Workbook

Sheet Resumo
A1: Despesas 2026 – almoxarifado (insumos, papel, uso e consumo, frete de compra) e frete de venda – VINCO
A2: R$, por mês de emissão. Custo líquido = valor bruto menos créditos de impostos recuperáveis (regras na aba Premissas). Só o efetivamente pago (NF-e com título a pagar + CT-e); sem remessa de compra, devolução, transferência, x.949, x.922 e aluguel de contêiner.
A4: Destino / Categoria | B4: 46023 | C4: 46054 | D4: 46082 | E4: 46113 | F4: 46143 | G4: 46174 | H4: 46204 | I4: 46235 | J4: 46266 | K4: Total 2026 | L4: Memo: antes de 2026
A5: Insumos e papel
A6: 2.01.03 Compra de Matéria Prima (Papel) | B6: =SUMIFS(Base!$N$2:$N$4835,Base!$B$2:$B$4835,"Insumos e papel",Base!$C$2:$C$4835,"2.01.03 Compra de Matéria Prima (Papel)",Base!$A$2:$A$4835,B$4) | C6: =SUMIFS(Base!$N$2:$N$4835,Base!$B$2:$B$4835,"Insumos e papel",Base!$C$2:$C$4835,"2.01.03 Compra de Matéria Prima (Papel)",Base!$A$2:$A$4835,C$4) | D6: =SUMIFS(Base!$N$2:$N$4835,Base!$B$2:$B$4835,"Insumos e papel",Base!$C$2:$C$4835,"2.01.03 Compra de Matéria Prima (Papel)",Base!$A$2:$A$4835,D$4) | E6: =SUMIFS(Base!$N$2:$N$4835,Base!$B$2:$B$4835,"Insumos e papel",Base!$C$2:$C$4835,"2.01.03 Compra de Matéria Prima (Papel)",Base!$A$2:$A$4835,E$4) | F6: =SUMIFS(Base!$N$2:$N$4835,Base!$B$2:$B$4835,"Insumos e papel",Base!$C$2:$C$4835,"2.01.03 Compra de Matéria Prima (Papel)",Base!$A$2:$A$4835,F$4) | G6: =SUMIFS(Base!$N$2:$N$4835,Base!$B$2:$B$4835,"Insumos e papel",Base!$C$2:$C$4835,"2.01.03 Compra de Matéria Prima (Papel)",Base!$A$2:$A$4835,G$4) | H6: =SUMIFS(Base!$N$2:$N$4835,Base!$B$2:$B$4835,"Insumos e papel",Base!$C$2:$C$4835,"2.01.03 Compra de Matéria Prima (Papel)",Base!$A$2:$A$4835,H$4) | I6: =SUMIFS(Base!$N$2:$N$4835,Base!$B$2:$B$4835,"Insumos e papel",Base!$C$2:$C$4835,"2.01.03 Compra de Matéria Prima (Papel)",Base!$A$2:$A$4835,I$4) | J6: =SUMIFS(Base!$N$2:$N$4835,Base!$B$2:$B$4835,"Insumos e papel",Base!$C$2:$C$4835,"2.01.03 Compra de Matéria Prima (Papel)",Base!$A$2:$A$4835,J$4) | K6: =SUM(B6:J6) | L6: =SUMIFS(Base!$N$2:$N$4835,Base!$B$2:$B$4835,"Insumos e papel",Base!$C$2:$C$4835,"2.01.03 Compra de Matéria Prima (Papel)",Base!$A$2:$A$4835,"Antes de 2026")
A7: 2.01.79 Compra de Gás | B7: =SUMIFS(Base!$N$2:$N$4835,Base!$B$2:$B$4835,"Insumos e papel",Base!$C$2:$C$4835,"2.01.79 Compra de Gás",Base!$A$2:$A$4835,B$4) | C7: =SUMIFS(Base!$N$2:$N$4835,Base!$B$2:$B$4835,"Insumos e papel",Base!$C$2:$C$4835,"2.01.79 Compra de Gás",Base!$A$2:$A$4835,C$4) | D7: =SUMIFS(Base!$N$2:$N$4835,Base!$B$2:$B$4835,"Insumos e papel",Base!$C$2:$C$4835,"2.01.79 Compra de Gás",Base!$A$2:$A$4835,D$4) | E7: =SUMIFS(Base!$N$2:$N$4835,Base!$B$2:$B$4835,"Insumos e papel",Base!$C$2:$C$4835,"2.01.79 Compra de Gás",Base!$A$2:$A$4835,E$4) | F7: =SUMIFS(Base!$N$2:$N$4835,Base!$B$2:$B$4835,"Insumos e papel",Base!$C$2:$C$4835,"2.01.79 Compra de Gás",Base!$A$2:$A$4835,F$4) | G7: =SUMIFS(Base!$N$2:$N$4835,Base!$B$2:$B$4835,"Insumos e papel",Base!$C$2:$C$4835,"2.01.79 Compra de Gás",Base!$A$2:$A$4835,G$4) | H7: =SUMIFS(Base!$N$2:$N$4835,Base!$B$2:$B$4835,"Insumos e papel",Base!$C$2:$C$4835,"2.01.79 Compra de Gás",Base!$A$2:$A$4835,H$4) | I7: =SUMIFS(Base!$N$2:$N$4835,Base!$B$2:$B$4835,"Insumos e papel",Base!$C$2:$C$4835,"2.01.79 Compra de Gás",Base!$A$2:$A$4835,I$4) | J7: =SUMIFS(Base!$N$2:$N$4835,Base!$B$2:$B$4835,"Insumos e papel",Base!$C$2:$C$4835,"2.01.79 Compra de Gás",Base!$A$2:$A$4835,J$4) | K7: =SUM(B7:J7) | L7: =SUMIFS(Base!$N$2:$N$4835,Base!$B$2:$B$4835,"Insumos e papel",Base!$C$2:$C$4835,"2.01.79 Compra de Gás",Base!$A$2:$A$4835,"Antes de 2026")
A8: 2.01.83 Compra de Etiqueta Personalizada | B8: =SUMIFS(Base!$N$2:$N$4835,Base!$B$2:$B$4835,"Insumos e papel",Base!$C$2:$C$4835,"2.01.83 Compra de Etiqueta Personalizada",Base!$A$2:$A$4835,B$4) | C8: =SUMIFS(Base!$N$2:$N$4835,Base!$B$2:$B$4835,"Insumos e papel",Base!$C$2:$C$4835,"2.01.83 Compra de Etiqueta Personalizada",Base!$A$2:$A$4835,C$4) | D8: =SUMIFS(Base!$N$2:$N$4835,Base!$B$2:$B$4835,"Insumos e papel",Base!$C$2:$C$4835,"2.01.83 Compra de Etiqueta Personalizada",Base!$A$2:$A$4835,D$4) | E8: =SUMIFS(Base!$N$2:$N$4835,Base!$B$2:$B$4835,"Insumos e papel",Base!$C$2:$C$4835,"2.01.83 Compra de Etiqueta Personalizada",Base!$A$2:$A$4835,E$4) | F8: =SUMIFS(Base!$N$2:$N$4835,Base!$B$2:$B$4835,"Insumos e papel",Base!$C$2:$C$4835,"2.01.83 Compra de Etiqueta Personalizada",Base!$A$2:$A$4835,F$4) | G8: =SUMIFS(Base!$N$2:$N$4835,Base!$B$2:$B$4835,"Insumos e papel",Base!$C$2:$C$4835,"2.01.83 Compra de Etiqueta Personalizada",Base!$A$2:$A$4835,G$4) | H8: =SUMIFS(Base!$N$2:$N$4835,Base!$B$2:$B$4835,"Insumos e papel",Base!$C$2:$C$4835,"2.01.83 Compra de Etiqueta Personalizada",Base!$A$2:$A$4835,H$4) | I8: =SUMIFS(Base!$N$2:$N$4835,Base!$B$2:$B$4835,"Insumos e papel",Base!$C$2:$C$4835,"2.01.83 Compra de Etiqueta Personalizada",Base!$A$2:$A$4835,I$4) | J8: =SUMIFS(Base!$N$2:$N$4835,Base!$B$2:$B$4835,"Insumos e papel",Base!$C$2:$C$4835,"2.01.83 Compra de Etiqueta Personalizada",Base!$A$2:$A$4835,J$4) | K8: =SUM(B8:J8) | L8: =SUMIFS(Base!$N$2:$N$4835,Base!$B$2:$B$4835,"Insumos e papel",Base!$C$2:$C$4835,"2.01.83 Compra de Etiqueta Personalizada",Base!$A$2:$A$4835,"Antes de 2026")
A9: 2.01.89 Compra de Pallet | B9: =SUMIFS(Base!$N$2:$N$4835,Base!$B$2:$B$4835,"Insumos e papel",Base!$C$2:$C$4835,"2.01.89 Compra de Pallet",Base!$A$2:$A$4835,B$4) | C9: =SUMIFS(Base!$N$2:$N$4835,Base!$B$2:$B$4835,"Insumos e papel",Base!$C$2:$C$4835,"2.01.89 Compra de Pallet",Base!$A$2:$A$4835,C$4) | D9: =SUMIFS(Base!$N$2:$N$4835,Base!$B$2:$B$4835,"Insumos e papel",Base!$C$2:$C$4835,"2.01.89 Compra de Pallet",Base!$A$2:$A$4835,D$4) | E9: =SUMIFS(Base!$N$2:$N$4835,Base!$B$2:$B$4835,"Insumos e papel",Base!$C$2:$C$4835,"2.01.89 Compra de Pallet",Base!$A$2:$A$4835,E$4) | F9: =SUMIFS(Base!$N$2:$N$4835,Base!$B$2:$B$4835,"Insumos e papel",Base!$C$2:$C$4835,"2.01.89 Compra de Pallet",Base!$A$2:$A$4835,F$4) | G9: =SUMIFS(Base!$N$2:$N$4835,Base!$B$2:$B$4835,"Insumos e papel",Base!$C$2:$C$4835,"2.01.89 Compra de Pallet",Base!$A$2:$A$4835,G$4) | H9: =SUMIFS(Base!$N$2:$N$4835,Base!$B$2:$B$4835,"Insumos e papel",Base!$C$2:$C$4835,"2.01.89 Compra de Pallet",Base!$A$2:$A$4835,H$4) | I9: =SUMIFS(Base!$N$2:$N$4835,Base!$B$2:$B$4835,"Insumos e papel",Base!$C$2:$C$4835,"2.01.89 Compra de Pallet",Base!$A$2:$A$4835,I$4) | J9: =SUMIFS(Base!$N$2:$N$4835,Base!$B$2:$B$4835,"Insumos e papel",Base!$C$2:$C$4835,"2.01.89 Compra de Pallet",Base!$A$2:$A$4835,J$4) | K9: =SUM(B9:J9) | L9: =SUMIFS(Base!$N$2:$N$4835,Base!$B$2:$B$4835,"Insumos e papel",Base!$C$2:$C$4835,"2.01.89 Compra de Pallet",Base!$A$2:$A$4835,"Antes de 2026")
A10: 2.01.91 Compra de Filme Strech | B10: =SUMIFS(Base!$N$2:$N$4835,Base!$B$2:$B$4835,"Insumos e papel",Base!$C$2:$C$4835,"2.01.91 Compra de Filme Strech",Base!$A$2:$A$4835,B$4) | C10: =SUMIFS(Base!$N$2:$N$4835,Base!$B$2:$B$4835,"Insumos e papel",Base!$C$2:$C$4835,"2.01.91 Compra de Filme Strech",Base!$A$2:$A$4835,C$4) | D10: =SUMIFS(Base!$N$2:$N$4835,Base!$B$2:$B$4835,"Insumos e papel",Base!$C$2:$C$4835,"2.01.91 Compra de Filme Strech",Base!$A$2:$A$4835,D$4) | E10: =SUMIFS(Base!$N$2:$N$4835,Base!$B$2:$B$4835,"Insumos e papel",Base!$C$2:$C$4835,"2.01.91 Compra de Filme Strech",Base!$A$2:$A$4835,E$4) | F10: =SUMIFS(Base!$N$2:$N$4835,Base!$B$2:$B$4835,"Insumos e papel",Base!$C$2:$C$4835,"2.01.91 Compra de Filme Strech",Base!$A$2:$A$4835,F$4) | G10: =SUMIFS(Base!$N$2:$N$4835,Base!$B$2:$B$4835,"Insumos e papel",Base!$C$2:$C$4835,"2.01.91 Compra de Filme Strech",Base!$A$2:$A$4835,G$4) | H10: =SUMIFS(Base!$N$2:$N$4835,Base!$B$2:$B$4835,"Insumos e papel",Base!$C$2:$C$4835,"2.01.91 Compra de Filme Strech",Base!$A$2:$A$4835,H$4) | I10: =SUMIFS(Base!$N$2:$N$4835,Base!$B$2:$B$4835,"Insumos e papel",Base!$C$2:$C$4835,"2.01.91 Compra de Filme Strech",Base!$A$2:$A$4835,I$4) | J10: =SUMIFS(Base!$N$2:$N$4835,Base!$B$2:$B$4835,"Insumos e papel",Base!$C$2:$C$4835,"2.01.91 Compra de Filme Strech",Base!$A$2:$A$4835,J$4) | K10: =SUM(B10:J10) | L10: =SUMIFS(Base!$N$2:$N$4835,Base!$B$2:$B$4835,"Insumos e papel",Base!$C$2:$C$4835,"2.01.91 Compra de Filme Strech",Base!$A$2:$A$4835,"Antes de 2026")
A11: 2.01.92 Compra de Tinta | B11: =SUMIFS(Base!$N$2:$N$4835,Base!$B$2:$B$4835,"Insumos e papel",Base!$C$2:$C$4835,"2.01.92 Compra de Tinta",Base!$A$2:$A$4835,B$4) | C11: =SUMIFS(Base!$N$2:$N$4835,Base!$B$2:$B$4835,"Insumos e papel",Base!$C$2:$C$4835,"2.01.92 Compra de Tinta",Base!$A$2:$A$4835,C$4) | D11: =SUMIFS(Base!$N$2:$N$4835,Base!$B$2:$B$4835,"Insumos e papel",Base!$C$2:$C$4835,"2.01.92 Compra de Tinta",Base!$A$2:$A$4835,D$4) | E11: =SUMIFS(Base!$N$2:$N$4835,Base!$B$2:$B$4835,"Insumos e papel",Base!$C$2:$C$4835,"2.01.92 Compra de Tinta",Base!$A$2:$A$4835,E$4) | F11: =SUMIFS(Base!$N$2:$N$4835,Base!$B$2:$B$4835,"Insumos e papel",Base!$C$2:$C$4835,"2.01.92 Compra de Tinta",Base!$A$2:$A$4835,F$4) | G11: =SUMIFS(Base!$N$2:$N$4835,Base!$B$2:$B$4835,"Insumos e papel",Base!$C$2:$C$4835,"2.01.92 Compra de Tinta",Base!$A$2:$A$4835,G$4) | H11: =SUMIFS(Base!$N$2:$N$4835,Base!$B$2:$B$4835,"Insumos e papel",Base!$C$2:$C$4835,"2.01.92 Compra de Tinta",Base!$A$2:$A$4835,H$4) | I11: =SUMIFS(Base!$N$2:$N$4835,Base!$B$2:$B$4835,"Insumos e papel",Base!$C$2:$C$4835,"2.01.92 Compra de Tinta",Base!$A$2:$A$4835,I$4) | J11: =SUMIFS(Base!$N$2:$N$4835,Base!$B$2:$B$4835,"Insumos e papel",Base!$C$2:$C$4835,"2.01.92 Compra de Tinta",Base!$A$2:$A$4835,J$4) | K11: =SUM(B11:J11) | L11: =SUMIFS(Base!$N$2:$N$4835,Base!$B$2:$B$4835,"Insumos e papel",Base!$C$2:$C$4835,"2.01.92 Compra de Tinta",Base!$A$2:$A$4835,"Antes de 2026")
A12: 2.01.93 Compra de Plástico Poliolefínico | B12: =SUMIFS(Base!$N$2:$N$4835,Base!$B$2:$B$4835,"Insumos e papel",Base!$C$2:$C$4835,"2.01.93 Compra de Plástico Poliolefínico",Base!$A$2:$A$4835,B$4) | C12: =SUMIFS(Base!$N$2:$N$4835,Base!$B$2:$B$4835,"Insumos e papel",Base!$C$2:$C$4835,"2.01.93 Compra de Plástico Poliolefínico",Base!$A$2:$A$4835,C$4) | D12: =SUMIFS(Base!$N$2:$N$4835,Base!$B$2:$B$4835,"Insumos e papel",Base!$C$2:$C$4835,"2.01.93 Compra de Plástico Poliolefínico",Base!$A$2:$A$4835,D$4) | E12: =SUMIFS(Base!$N$2:$N$4835,Base!$B$2:$B$4835,"Insumos e papel",Base!$C$2:$C$4835,"2.01.93 Compra de Plástico Poliolefínico",Base!$A$2:$A$4835,E$4) | F12: =SUMIFS(Base!$N$2:$N$4835,Base!$B$2:$B$4835,"Insumos e papel",Base!$C$2:$C$4835,"2.01.93 Compra de Plástico Poliolefínico",Base!$A$2:$A$4835,F$4) | G12: =SUMIFS(Base!$N$2:$N$4835,Base!$B$2:$B$4835,"Insumos e papel",Base!$C$2:$C$4835,"2.01.93 Compra de Plástico Poliolefínico",Base!$A$2:$A$4835,G$4) | H12: =SUMIFS(Base!$N$2:$N$4835,Base!$B$2:$B$4835,"Insumos e papel",Base!$C$2:$C$4835,"2.01.93 Compra de Plástico Poliolefínico",Base!$A$2:$A$4835,H$4) | I12: =SUMIFS(Base!$N$2:$N$4835,Base!$B$2:$B$4835,"Insumos e papel",Base!$C$2:$C$4835,"2.01.93 Compra de Plástico Poliolefínico",Base!$A$2:$A$4835,I$4) | J12: =SUMIFS(Base!$N$2:$N$4835,Base!$B$2:$B$4835,"Insumos e papel",Base!$C$2:$C$4835,"2.01.93 Compra de Plástico Poliolefínico",Base!$A$2:$A$4835,J$4) | K12: =SUM(B12:J12) | L12: =SUMIFS(Base!$N$2:$N$4835,Base!$B$2:$B$4835,"Insumos e papel",Base!$C$2:$C$4835,"2.01.93 Compra de Plástico Poliolefínico",Base!$A$2:$A$4835,"Antes de 2026")
A13: 2.01.94 Compra de Fita Adesiva | B13: =SUMIFS(Base!$N$2:$N$4835,Base!$B$2:$B$4835,"Insumos e papel",Base!$C$2:$C$4835,"2.01.94 Compra de Fita Adesiva",Base!$A$2:$A$4835,B$4) | C13: =SUMIFS(Base!$N$2:$N$4835,Base!$B$2:$B$4835,"Insumos e papel",Base!$C$2:$C$4835,"2.01.94 Compra de Fita Adesiva",Base!$A$2:$A$4835,C$4) | D13: =SUMIFS(Base!$N$2:$N$4835,Base!$B$2:$B$4835,"Insumos e papel",Base!$C$2:$C$4835,"2.01.94 Compra de Fita Adesiva",Base!$A$2:$A$4835,D$4) | E13: =SUMIFS(Base!$N$2:$N$4835,Base!$B$2:$B$4835,"Insumos e papel",Base!$C$2:$C$4835,"2.01.94 Compra de Fita Adesiva",Base!$A$2:$A$4835,E$4) | F13: =SUMIFS(Base!$N$2:$N$4835,Base!$B$2:$B$4835,"Insumos e papel",Base!$C$2:$C$4835,"2.01.94 Compra de Fita Adesiva",Base!$A$2:$A$4835,F$4) | G13: =SUMIFS(Base!$N$2:$N$4835,Base!$B$2:$B$4835,"Insumos e papel",Base!$C$2:$C$4835,"2.01.94 Compra de Fita Adesiva",Base!$A$2:$A$4835,G$4) | H13: =SUMIFS(Base!$N$2:$N$4835,Base!$B$2:$B$4835,"Insumos e papel",Base!$C$2:$C$4835,"2.01.94 Compra de Fita Adesiva",Base!$A$2:$A$4835,H$4) | I13: =SUMIFS(Base!$N$2:$N$4835,Base!$B$2:$B$4835,"Insumos e papel",Base!$C$2:$C$4835,"2.01.94 Compra de Fita Adesiva",Base!$A$2:$A$4835,I$4) | J13: =SUMIFS(Base!$N$2:$N$4835,Base!$B$2:$B$4835,"Insumos e papel",Base!$C$2:$C$4835,"2.01.94 Compra de Fita Adesiva",Base!$A$2:$A$4835,J$4) | K13: =SUM(B13:J13) | L13: =SUMIFS(Base!$N$2:$N$4835,Base!$B$2:$B$4835,"Insumos e papel",Base!$C$2:$C$4835,"2.01.94 Compra de Fita Adesiva",Base!$A$2:$A$4835,"Antes de 2026")
A14: 2.01.95 Compra de Etiqueta | B14: =SUMIFS(Base!$N$2:$N$4835,Base!$B$2:$B$4835,"Insumos e papel",Base!$C$2:$C$4835,"2.01.95 Compra de Etiqueta",Base!$A$2:$A$4835,B$4) | C14: =SUMIFS(Base!$N$2:$N$4835,Base!$B$2:$B$4835,"Insumos e papel",Base!$C$2:$C$4835,"2.01.95 Compra de Etiqueta",Base!$A$2:$A$4835,C$4) | D14: =SUMIFS(Base!$N$2:$N$4835,Base!$B$2:$B$4835,"Insumos e papel",Base!$C$2:$C$4835,"2.01.95 Compra de Etiqueta",Base!$A$2:$A$4835,D$4) | E14: =SUMIFS(Base!$N$2:$N$4835,Base!$B$2:$B$4835,"Insumos e papel",Base!$C$2:$C$4835,"2.01.95 Compra de Etiqueta",Base!$A$2:$A$4835,E$4) | F14: =SUMIFS(Base!$N$2:$N$4835,Base!$B$2:$B$4835,"Insumos e papel",Base!$C$2:$C$4835,"2.01.95 Compra de Etiqueta",Base!$A$2:$A$4835,F$4) | G14: =SUMIFS(Base!$N$2:$N$4835,Base!$B$2:$B$4835,"Insumos e papel",Base!$C$2:$C$4835,"2.01.95 Compra de Etiqueta",Base!$A$2:$A$4835,G$4) | H14: =SUMIFS(Base!$N$2:$N$4835,Base!$B$2:$B$4835,"Insumos e papel",Base!$C$2:$C$4835,"2.01.95 Compra de Etiqueta",Base!$A$2:$A$4835,H$4) | I14: =SUMIFS(Base!$N$2:$N$4835,Base!$B$2:$B$4835,"Insumos e papel",Base!$C$2:$C$4835,"2.01.95 Compra de Etiqueta",Base!$A$2:$A$4835,I$4) | J14: =SUMIFS(Base!$N$2:$N$4835,Base!$B$2:$B$4835,"Insumos e papel",Base!$C$2:$C$4835,"2.01.95 Compra de Etiqueta",Base!$A$2:$A$4835,J$4) | K14: =SUM(B14:J14) | L14: =SUMIFS(Base!$N$2:$N$4835,Base!$B$2:$B$4835,"Insumos e papel",Base!$C$2:$C$4835,"2.01.95 Compra de Etiqueta",Base!$A$2:$A$4835,"Antes de 2026")
A15: 2.01.96 Compra de Cola | B15: =SUMIFS(Base!$N$2:$N$4835,Base!$B$2:$B$4835,"Insumos e papel",Base!$C$2:$C$4835,"2.01.96 Compra de Cola",Base!$A$2:$A$4835,B$4) | C15: =SUMIFS(Base!$N$2:$N$4835,Base!$B$2:$B$4835,"Insumos e papel",Base!$C$2:$C$4835,"2.01.96 Compra de Cola",Base!$A$2:$A$4835,C$4) | D15: =SUMIFS(Base!$N$2:$N$4835,Base!$B$2:$B$4835,"Insumos e papel",Base!$C$2:$C$4835,"2.01.96 Compra de Cola",Base!$A$2:$A$4835,D$4) | E15: =SUMIFS(Base!$N$2:$N$4835,Base!$B$2:$B$4835,"Insumos e papel",Base!$C$2:$C$4835,"2.01.96 Compra de Cola",Base!$A$2:$A$4835,E$4) | F15: =SUMIFS(Base!$N$2:$N$4835,Base!$B$2:$B$4835,"Insumos e papel",Base!$C$2:$C$4835,"2.01.96 Compra de Cola",Base!$A$2:$A$4835,F$4) | G15: =SUMIFS(Base!$N$2:$N$4835,Base!$B$2:$B$4835,"Insumos e papel",Base!$C$2:$C$4835,"2.01.96 Compra de Cola",Base!$A$2:$A$4835,G$4) | H15: =SUMIFS(Base!$N$2:$N$4835,Base!$B$2:$B$4835,"Insumos e papel",Base!$C$2:$C$4835,"2.01.96 Compra de Cola",Base!$A$2:$A$4835,H$4) | I15: =SUMIFS(Base!$N$2:$N$4835,Base!$B$2:$B$4835,"Insumos e papel",Base!$C$2:$C$4835,"2.01.96 Compra de Cola",Base!$A$2:$A$4835,I$4) | J15: =SUMIFS(Base!$N$2:$N$4835,Base!$B$2:$B$4835,"Insumos e papel",Base!$C$2:$C$4835,"2.01.96 Compra de Cola",Base!$A$2:$A$4835,J$4) | K15: =SUM(B15:J15) | L15: =SUMIFS(Base!$N$2:$N$4835,Base!$B$2:$B$4835,"Insumos e papel",Base!$C$2:$C$4835,"2.01.96 Compra de Cola",Base!$A$2:$A$4835,"Antes de 2026")
A16: 2.01.97 Compra de Clichê | B16: =SUMIFS(Base!$N$2:$N$4835,Base!$B$2:$B$4835,"Insumos e papel",Base!$C$2:$C$4835,"2.01.97 Compra de Clichê",Base!$A$2:$A$4835,B$4) | C16: =SUMIFS(Base!$N$2:$N$4835,Base!$B$2:$B$4835,"Insumos e papel",Base!$C$2:$C$4835,"2.01.97 Compra de Clichê",Base!$A$2:$A$4835,C$4) | D16: =SUMIFS(Base!$N$2:$N$4835,Base!$B$2:$B$4835,"Insumos e papel",Base!$C$2:$C$4835,"2.01.97 Compra de Clichê",Base!$A$2:$A$4835,D$4) | E16: =SUMIFS(Base!$N$2:$N$4835,Base!$B$2:$B$4835,"Insumos e papel",Base!$C$2:$C$4835,"2.01.97 Compra de Clichê",Base!$A$2:$A$4835,E$4) | F16: =SUMIFS(Base!$N$2:$N$4835,Base!$B$2:$B$4835,"Insumos e papel",Base!$C$2:$C$4835,"2.01.97 Compra de Clichê",Base!$A$2:$A$4835,F$4) | G16: =SUMIFS(Base!$N$2:$N$4835,Base!$B$2:$B$4835,"Insumos e papel",Base!$C$2:$C$4835,"2.01.97 Compra de Clichê",Base!$A$2:$A$4835,G$4) | H16: =SUMIFS(Base!$N$2:$N$4835,Base!$B$2:$B$4835,"Insumos e papel",Base!$C$2:$C$4835,"2.01.97 Compra de Clichê",Base!$A$2:$A$4835,H$4) | I16: =SUMIFS(Base!$N$2:$N$4835,Base!$B$2:$B$4835,"Insumos e papel",Base!$C$2:$C$4835,"2.01.97 Compra de Clichê",Base!$A$2:$A$4835,I$4) | J16: =SUMIFS(Base!$N$2:$N$4835,Base!$B$2:$B$4835,"Insumos e papel",Base!$C$2:$C$4835,"2.01.97 Compra de Clichê",Base!$A$2:$A$4835,J$4) | K16: =SUM(B16:J16) | L16: =SUMIFS(Base!$N$2:$N$4835,Base!$B$2:$B$4835,"Insumos e papel",Base!$C$2:$C$4835,"2.01.97 Compra de Clichê",Base!$A$2:$A$4835,"Antes de 2026")
A17: 2.01.99 Compra de Caixas | B17: =SUMIFS(Base!$N$2:$N$4835,Base!$B$2:$B$4835,"Insumos e papel",Base!$C$2:$C$4835,"2.01.99 Compra de Caixas",Base!$A$2:$A$4835,B$4) | C17: =SUMIFS(Base!$N$2:$N$4835,Base!$B$2:$B$4835,"Insumos e papel",Base!$C$2:$C$4835,"2.01.99 Compra de Caixas",Base!$A$2:$A$4835,C$4) | D17: =SUMIFS(Base!$N$2:$N$4835,Base!$B$2:$B$4835,"Insumos e papel",Base!$C$2:$C$4835,"2.01.99 Compra de Caixas",Base!$A$2:$A$4835,D$4) | E17: =SUMIFS(Base!$N$2:$N$4835,Base!$B$2:$B$4835,"Insumos e papel",Base!$C$2:$C$4835,"2.01.99 Compra de Caixas",Base!$A$2:$A$4835,E$4) | F17: =SUMIFS(Base!$N$2:$N$4835,Base!$B$2:$B$4835,"Insumos e papel",Base!$C$2:$C$4835,"2.01.99 Compra de Caixas",Base!$A$2:$A$4835,F$4) | G17: =SUMIFS(Base!$N$2:$N$4835,Base!$B$2:$B$4835,"Insumos e papel",Base!$C$2:$C$4835,"2.01.99 Compra de Caixas",Base!$A$2:$A$4835,G$4) | H17: =SUMIFS(Base!$N$2:$N$4835,Base!$B$2:$B$4835,"Insumos e papel",Base!$C$2:$C$4835,"2.01.99 Compra de Caixas",Base!$A$2:$A$4835,H$4) | I17: =SUMIFS(Base!$N$2:$N$4835,Base!$B$2:$B$4835,"Insumos e papel",Base!$C$2:$C$4835,"2.01.99 Compra de Caixas",Base!$A$2:$A$4835,I$4) | J17: =SUMIFS(Base!$N$2:$N$4835,Base!$B$2:$B$4835,"Insumos e papel",Base!$C$2:$C$4835,"2.01.99 Compra de Caixas",Base!$A$2:$A$4835,J$4) | K17: =SUM(B17:J17) | L17: =SUMIFS(Base!$N$2:$N$4835,Base!$B$2:$B$4835,"Insumos e papel",Base!$C$2:$C$4835,"2.01.99 Compra de Caixas",Base!$A$2:$A$4835,"Antes de 2026")
A18: Total Insumos e papel | B18: =SUM(B6:B17) | C18: =SUM(C6:C17) | D18: =SUM(D6:D17) | E18: =SUM(E6:E17) | F18: =SUM(F6:F17) | G18: =SUM(G6:G17) | H18: =SUM(H6:H17) | I18: =SUM(I6:I17) | ... L18: =SUM(L6:L17)
A20: Uso e consumo
A21: 2.01.85 Compra de Uso e Consumo | B21: =SUMIFS(Base!$N$2:$N$4835,Base!$B$2:$B$4835,"Uso e consumo",Base!$C$2:$C$4835,"2.01.85 Compra de Uso e Consumo",Base!$A$2:$A$4835,B$4) | C21: =SUMIFS(Base!$N$2:$N$4835,Base!$B$2:$B$4835,"Uso e consumo",Base!$C$2:$C$4835,"2.01.85 Compra de Uso e Consumo",Base!$A$2:$A$4835,C$4) | D21: =SUMIFS(Base!$N$2:$N$4835,Base!$B$2:$B$4835,"Uso e consumo",Base!$C$2:$C$4835,"2.01.85 Compra de Uso e Consumo",Base!$A$2:$A$4835,D$4) | E21: =SUMIFS(Base!$N$2:$N$4835,Base!$B$2:$B$4835,"Uso e consumo",Base!$C$2:$C$4835,"2.01.85 Compra de Uso e Consumo",Base!$A$2:$A$4835,E$4) | F21: =SUMIFS(Base!$N$2:$N$4835,Base!$B$2:$B$4835,"Uso e consumo",Base!$C$2:$C$4835,"2.01.85 Compra de Uso e Consumo",Base!$A$2:$A$4835,F$4) | G21: =SUMIFS(Base!$N$2:$N$4835,Base!$B$2:$B$4835,"Uso e consumo",Base!$C$2:$C$4835,"2.01.85 Compra de Uso e Consumo",Base!$A$2:$A$4835,G$4) | H21: =SUMIFS(Base!$N$2:$N$4835,Base!$B$2:$B$4835,"Uso e consumo",Base!$C$2:$C$4835,"2.01.85 Compra de Uso e Consumo",Base!$A$2:$A$4835,H$4) | I21: =SUMIFS(Base!$N$2:$N$4835,Base!$B$2:$B$4835,"Uso e consumo",Base!$C$2:$C$4835,"2.01.85 Compra de Uso e Consumo",Base!$A$2:$A$4835,I$4) | J21: =SUMIFS(Base!$N$2:$N$4835,Base!$B$2:$B$4835,"Uso e consumo",Base!$C$2:$C$4835,"2.01.85 Compra de Uso e Consumo",Base!$A$2:$A$4835,J$4) | K21: =SUM(B21:J21) | L21: =SUMIFS(Base!$N$2:$N$4835,Base!$B$2:$B$4835,"Uso e consumo",Base!$C$2:$C$4835,"2.01.85 Compra de Uso e Consumo",Base!$A$2:$A$4835,"Antes de 2026")
A22: 2.01.87 Compra de Peças de Máquinas | B22: =SUMIFS(Base!$N$2:$N$4835,Base!$B$2:$B$4835,"Uso e consumo",Base!$C$2:$C$4835,"2.01.87 Compra de Peças de Máquinas",Base!$A$2:$A$4835,B$4) | C22: =SUMIFS(Base!$N$2:$N$4835,Base!$B$2:$B$4835,"Uso e consumo",Base!$C$2:$C$4835,"2.01.87 Compra de Peças de Máquinas",Base!$A$2:$A$4835,C$4) | D22: =SUMIFS(Base!$N$2:$N$4835,Base!$B$2:$B$4835,"Uso e consumo",Base!$C$2:$C$4835,"2.01.87 Compra de Peças de Máquinas",Base!$A$2:$A$4835,D$4) | E22: =SUMIFS(Base!$N$2:$N$4835,Base!$B$2:$B$4835,"Uso e consumo",Base!$C$2:$C$4835,"2.01.87 Compra de Peças de Máquinas",Base!$A$2:$A$4835,E$4) | F22: =SUMIFS(Base!$N$2:$N$4835,Base!$B$2:$B$4835,"Uso e consumo",Base!$C$2:$C$4835,"2.01.87 Compra de Peças de Máquinas",Base!$A$2:$A$4835,F$4) | G22: =SUMIFS(Base!$N$2:$N$4835,Base!$B$2:$B$4835,"Uso e consumo",Base!$C$2:$C$4835,"2.01.87 Compra de Peças de Máquinas",Base!$A$2:$A$4835,G$4) | H22: =SUMIFS(Base!$N$2:$N$4835,Base!$B$2:$B$4835,"Uso e consumo",Base!$C$2:$C$4835,"2.01.87 Compra de Peças de Máquinas",Base!$A$2:$A$4835,H$4) | I22: =SUMIFS(Base!$N$2:$N$4835,Base!$B$2:$B$4835,"Uso e consumo",Base!$C$2:$C$4835,"2.01.87 Compra de Peças de Máquinas",Base!$A$2:$A$4835,I$4) | J22: =SUMIFS(Base!$N$2:$N$4835,Base!$B$2:$B$4835,"Uso e consumo",Base!$C$2:$C$4835,"2.01.87 Compra de Peças de Máquinas",Base!$A$2:$A$4835,J$4) | K22: =SUM(B22:J22) | L22: =SUMIFS(Base!$N$2:$N$4835,Base!$B$2:$B$4835,"Uso e consumo",Base!$C$2:$C$4835,"2.01.87 Compra de Peças de Máquinas",Base!$A$2:$A$4835,"Antes de 2026")
A23: 2.03.88 Compra de Fardamento | B23: =SUMIFS(Base!$N$2:$N$4835,Base!$B$2:$B$4835,"Uso e consumo",Base!$C$2:$C$4835,"2.03.88 Compra de Fardamento",Base!$A$2:$A$4835,B$4) | C23: =SUMIFS(Base!$N$2:$N$4835,Base!$B$2:$B$4835,"Uso e consumo",Base!$C$2:$C$4835,"2.03.88 Compra de Fardamento",Base!$A$2:$A$4835,C$4) | D23: =SUMIFS(Base!$N$2:$N$4835,Base!$B$2:$B$4835,"Uso e consumo",Base!$C$2:$C$4835,"2.03.88 Compra de Fardamento",Base!$A$2:$A$4835,D$4) | E23: =SUMIFS(Base!$N$2:$N$4835,Base!$B$2:$B$4835,"Uso e consumo",Base!$C$2:$C$4835,"2.03.88 Compra de Fardamento",Base!$A$2:$A$4835,E$4) | F23: =SUMIFS(Base!$N$2:$N$4835,Base!$B$2:$B$4835,"Uso e consumo",Base!$C$2:$C$4835,"2.03.88 Compra de Fardamento",Base!$A$2:$A$4835,F$4) | G23: =SUMIFS(Base!$N$2:$N$4835,Base!$B$2:$B$4835,"Uso e consumo",Base!$C$2:$C$4835,"2.03.88 Compra de Fardamento",Base!$A$2:$A$4835,G$4) | H23: =SUMIFS(Base!$N$2:$N$4835,Base!$B$2:$B$4835,"Uso e consumo",Base!$C$2:$C$4835,"2.03.88 Compra de Fardamento",Base!$A$2:$A$4835,H$4) | I23: =SUMIFS(Base!$N$2:$N$4835,Base!$B$2:$B$4835,"Uso e consumo",Base!$C$2:$C$4835,"2.03.88 Compra de Fardamento",Base!$A$2:$A$4835,I$4) | J23: =SUMIFS(Base!$N$2:$N$4835,Base!$B$2:$B$4835,"Uso e consumo",Base!$C$2:$C$4835,"2.03.88 Compra de Fardamento",Base!$A$2:$A$4835,J$4) | K23: =SUM(B23:J23) | L23: =SUMIFS(Base!$N$2:$N$4835,Base!$B$2:$B$4835,"Uso e consumo",Base!$C$2:$C$4835,"2.03.88 Compra de Fardamento",Base!$A$2:$A$4835,"Antes de 2026")
A24: 2.03.90 Compra de EPI | B24: =SUMIFS(Base!$N$2:$N$4835,Base!$B$2:$B$4835,"Uso e consumo",Base!$C$2:$C$4835,"2.03.90 Compra de EPI",Base!$A$2:$A$4835,B$4) | C24: =SUMIFS(Base!$N$2:$N$4835,Base!$B$2:$B$4835,"Uso e consumo",Base!$C$2:$C$4835,"2.03.90 Compra de EPI",Base!$A$2:$A$4835,C$4) | D24: =SUMIFS(Base!$N$2:$N$4835,Base!$B$2:$B$4835,"Uso e consumo",Base!$C$2:$C$4835,"2.03.90 Compra de EPI",Base!$A$2:$A$4835,D$4) | E24: =SUMIFS(Base!$N$2:$N$4835,Base!$B$2:$B$4835,"Uso e consumo",Base!$C$2:$C$4835,"2.03.90 Compra de EPI",Base!$A$2:$A$4835,E$4) | F24: =SUMIFS(Base!$N$2:$N$4835,Base!$B$2:$B$4835,"Uso e consumo",Base!$C$2:$C$4835,"2.03.90 Compra de EPI",Base!$A$2:$A$4835,F$4) | G24: =SUMIFS(Base!$N$2:$N$4835,Base!$B$2:$B$4835,"Uso e consumo",Base!$C$2:$C$4835,"2.03.90 Compra de EPI",Base!$A$2:$A$4835,G$4) | H24: =SUMIFS(Base!$N$2:$N$4835,Base!$B$2:$B$4835,"Uso e consumo",Base!$C$2:$C$4835,"2.03.90 Compra de EPI",Base!$A$2:$A$4835,H$4) | I24: =SUMIFS(Base!$N$2:$N$4835,Base!$B$2:$B$4835,"Uso e consumo",Base!$C$2:$C$4835,"2.03.90 Compra de EPI",Base!$A$2:$A$4835,I$4) | J24: =SUMIFS(Base!$N$2:$N$4835,Base!$B$2:$B$4835,"Uso e consumo",Base!$C$2:$C$4835,"2.03.90 Compra de EPI",Base!$A$2:$A$4835,J$4) | K24: =SUM(B24:J24) | L24: =SUMIFS(Base!$N$2:$N$4835,Base!$B$2:$B$4835,"Uso e consumo",Base!$C$2:$C$4835,"2.03.90 Compra de EPI",Base!$A$2:$A$4835,"Antes de 2026")
A25: 2.04.06 Material de Escritório | B25: =SUMIFS(Base!$N$2:$N$4835,Base!$B$2:$B$4835,"Uso e consumo",Base!$C$2:$C$4835,"2.04.06 Material de Escritório",Base!$A$2:$A$4835,B$4) | C25: =SUMIFS(Base!$N$2:$N$4835,Base!$B$2:$B$4835,"Uso e consumo",Base!$C$2:$C$4835,"2.04.06 Material de Escritório",Base!$A$2:$A$4835,C$4) | D25: =SUMIFS(Base!$N$2:$N$4835,Base!$B$2:$B$4835,"Uso e consumo",Base!$C$2:$C$4835,"2.04.06 Material de Escritório",Base!$A$2:$A$4835,D$4) | E25: =SUMIFS(Base!$N$2:$N$4835,Base!$B$2:$B$4835,"Uso e consumo",Base!$C$2:$C$4835,"2.04.06 Material de Escritório",Base!$A$2:$A$4835,E$4) | F25: =SUMIFS(Base!$N$2:$N$4835,Base!$B$2:$B$4835,"Uso e consumo",Base!$C$2:$C$4835,"2.04.06 Material de Escritório",Base!$A$2:$A$4835,F$4) | G25: =SUMIFS(Base!$N$2:$N$4835,Base!$B$2:$B$4835,"Uso e consumo",Base!$C$2:$C$4835,"2.04.06 Material de Escritório",Base!$A$2:$A$4835,G$4) | H25: =SUMIFS(Base!$N$2:$N$4835,Base!$B$2:$B$4835,"Uso e consumo",Base!$C$2:$C$4835,"2.04.06 Material de Escritório",Base!$A$2:$A$4835,H$4) | I25: =SUMIFS(Base!$N$2:$N$4835,Base!$B$2:$B$4835,"Uso e consumo",Base!$C$2:$C$4835,"2.04.06 Material de Escritório",Base!$A$2:$A$4835,I$4) | J25: =SUMIFS(Base!$N$2:$N$4835,Base!$B$2:$B$4835,"Uso e consumo",Base!$C$2:$C$4835,"2.04.06 Material de Escritório",Base!$A$2:$A$4835,J$4) | K25: =SUM(B25:J25) | L25: =SUMIFS(Base!$N$2:$N$4835,Base!$B$2:$B$4835,"Uso e consumo",Base!$C$2:$C$4835,"2.04.06 Material de Escritório",Base!$A$2:$A$4835,"Antes de 2026")
A26: 2.04.91 Compra de Material de Limpeza | B26: =SUMIFS(Base!$N$2:$N$4835,Base!$B$2:$B$4835,"Uso e consumo",Base!$C$2:$C$4835,"2.04.91 Compra de Material de Limpeza",Base!$A$2:$A$4835,B$4) | C26: =SUMIFS(Base!$N$2:$N$4835,Base!$B$2:$B$4835,"Uso e consumo",Base!$C$2:$C$4835,"2.04.91 Compra de Material de Limpeza",Base!$A$2:$A$4835,C$4) | D26: =SUMIFS(Base!$N$2:$N$4835,Base!$B$2:$B$4835,"Uso e consumo",Base!$C$2:$C$4835,"2.04.91 Compra de Material de Limpeza",Base!$A$2:$A$4835,D$4) | E26: =SUMIFS(Base!$N$2:$N$4835,Base!$B$2:$B$4835,"Uso e consumo",Base!$C$2:$C$4835,"2.04.91 Compra de Material de Limpeza",Base!$A$2:$A$4835,E$4) | F26: =SUMIFS(Base!$N$2:$N$4835,Base!$B$2:$B$4835,"Uso e consumo",Base!$C$2:$C$4835,"2.04.91 Compra de Material de Limpeza",Base!$A$2:$A$4835,F$4) | G26: =SUMIFS(Base!$N$2:$N$4835,Base!$B$2:$B$4835,"Uso e consumo",Base!$C$2:$C$4835,"2.04.91 Compra de Material de Limpeza",Base!$A$2:$A$4835,G$4) | H26: =SUMIFS(Base!$N$2:$N$4835,Base!$B$2:$B$4835,"Uso e consumo",Base!$C$2:$C$4835,"2.04.91 Compra de Material de Limpeza",Base!$A$2:$A$4835,H$4) | I26: =SUMIFS(Base!$N$2:$N$4835,Base!$B$2:$B$4835,"Uso e consumo",Base!$C$2:$C$4835,"2.04.91 Compra de Material de Limpeza",Base!$A$2:$A$4835,I$4) | J26: =SUMIFS(Base!$N$2:$N$4835,Base!$B$2:$B$4835,"Uso e consumo",Base!$C$2:$C$4835,"2.04.91 Compra de Material de Limpeza",Base!$A$2:$A$4835,J$4) | K26: =SUM(B26:J26) | L26: =SUMIFS(Base!$N$2:$N$4835,Base!$B$2:$B$4835,"Uso e consumo",Base!$C$2:$C$4835,"2.04.91 Compra de Material de Limpeza",Base!$A$2:$A$4835,"Antes de 2026")
A27: 2.04.95 Copa e Cozinha | B27: =SUMIFS(Base!$N$2:$N$4835,Base!$B$2:$B$4835,"Uso e consumo",Base!$C$2:$C$4835,"2.04.95 Copa e Cozinha",Base!$A$2:$A$4835,B$4) | C27: =SUMIFS(Base!$N$2:$N$4835,Base!$B$2:$B$4835,"Uso e consumo",Base!$C$2:$C$4835,"2.04.95 Copa e Cozinha",Base!$A$2:$A$4835,C$4) | D27: =SUMIFS(Base!$N$2:$N$4835,Base!$B$2:$B$4835,"Uso e consumo",Base!$C$2:$C$4835,"2.04.95 Copa e Cozinha",Base!$A$2:$A$4835,D$4) | E27: =SUMIFS(Base!$N$2:$N$4835,Base!$B$2:$B$4835,"Uso e consumo",Base!$C$2:$C$4835,"2.04.95 Copa e Cozinha",Base!$A$2:$A$4835,E$4) | F27: =SUMIFS(Base!$N$2:$N$4835,Base!$B$2:$B$4835,"Uso e consumo",Base!$C$2:$C$4835,"2.04.95 Copa e Cozinha",Base!$A$2:$A$4835,F$4) | G27: =SUMIFS(Base!$N$2:$N$4835,Base!$B$2:$B$4835,"Uso e consumo",Base!$C$2:$C$4835,"2.04.95 Copa e Cozinha",Base!$A$2:$A$4835,G$4) | H27: =SUMIFS(Base!$N$2:$N$4835,Base!$B$2:$B$4835,"Uso e consumo",Base!$C$2:$C$4835,"2.04.95 Copa e Cozinha",Base!$A$2:$A$4835,H$4) | I27: =SUMIFS(Base!$N$2:$N$4835,Base!$B$2:$B$4835,"Uso e consumo",Base!$C$2:$C$4835,"2.04.95 Copa e Cozinha",Base!$A$2:$A$4835,I$4) | J27: =SUMIFS(Base!$N$2:$N$4835,Base!$B$2:$B$4835,"Uso e consumo",Base!$C$2:$C$4835,"2.04.95 Copa e Cozinha",Base!$A$2:$A$4835,J$4) | K27: =SUM(B27:J27) | L27: =SUMIFS(Base!$N$2:$N$4835,Base!$B$2:$B$4835,"Uso e consumo",Base!$C$2:$C$4835,"2.04.95 Copa e Cozinha",Base!$A$2:$A$4835,"Antes de 2026")
A28: 2.04.96 Bens de Pequeno Valor | B28: =SUMIFS(Base!$N$2:$N$4835,Base!$B$2:$B$4835,"Uso e consumo",Base!$C$2:$C$4835,"2.04.96 Bens de Pequeno Valor",Base!$A$2:$A$4835,B$4) | C28: =SUMIFS(Base!$N$2:$N$4835,Base!$B$2:$B$4835,"Uso e consumo",Base!$C$2:$C$4835,"2.04.96 Bens de Pequeno Valor",Base!$A$2:$A$4835,C$4) | D28: =SUMIFS(Base!$N$2:$N$4835,Base!$B$2:$B$4835,"Uso e consumo",Base!$C$2:$C$4835,"2.04.96 Bens de Pequeno Valor",Base!$A$2:$A$4835,D$4) | E28: =SUMIFS(Base!$N$2:$N$4835,Base!$B$2:$B$4835,"Uso e consumo",Base!$C$2:$C$4835,"2.04.96 Bens de Pequeno Valor",Base!$A$2:$A$4835,E$4) | F28: =SUMIFS(Base!$N$2:$N$4835,Base!$B$2:$B$4835,"Uso e consumo",Base!$C$2:$C$4835,"2.04.96 Bens de Pequeno Valor",Base!$A$2:$A$4835,F$4) | G28: =SUMIFS(Base!$N$2:$N$4835,Base!$B$2:$B$4835,"Uso e consumo",Base!$C$2:$C$4835,"2.04.96 Bens de Pequeno Valor",Base!$A$2:$A$4835,G$4) | H28: =SUMIFS(Base!$N$2:$N$4835,Base!$B$2:$B$4835,"Uso e consumo",Base!$C$2:$C$4835,"2.04.96 Bens de Pequeno Valor",Base!$A$2:$A$4835,H$4) | I28: =SUMIFS(Base!$N$2:$N$4835,Base!$B$2:$B$4835,"Uso e consumo",Base!$C$2:$C$4835,"2.04.96 Bens de Pequeno Valor",Base!$A$2:$A$4835,I$4) | J28: =SUMIFS(Base!$N$2:$N$4835,Base!$B$2:$B$4835,"Uso e consumo",Base!$C$2:$C$4835,"2.04.96 Bens de Pequeno Valor",Base!$A$2:$A$4835,J$4) | K28: =SUM(B28:J28) | L28: =SUMIFS(Base!$N$2:$N$4835,Base!$B$2:$B$4835,"Uso e consumo",Base!$C$2:$C$4835,"2.04.96 Bens de Pequeno Valor",Base!$A$2:$A$4835,"Antes de 2026")
A29: Total Uso e consumo | B29: =SUM(B21:B28) | C29: =SUM(C21:C28) | D29: =SUM(D21:D28) | E29: =SUM(E21:E28) | F29: =SUM(F21:F28) | G29: =SUM(G21:G28) | H29: =SUM(H21:H28) | I29: =SUM(I21:I28) | ... L29: =SUM(L21:L28)
A31: Frete de compra
A32: Frete de compra | B32: =SUMIFS(Base!$N$2:$N$4835,Base!$B$2:$B$4835,"Frete de compra",Base!$C$2:$C$4835,"Frete de compra",Base!$A$2:$A$4835,B$4) | C32: =SUMIFS(Base!$N$2:$N$4835,Base!$B$2:$B$4835,"Frete de compra",Base!$C$2:$C$4835,"Frete de compra",Base!$A$2:$A$4835,C$4) | D32: =SUMIFS(Base!$N$2:$N$4835,Base!$B$2:$B$4835,"Frete de compra",Base!$C$2:$C$4835,"Frete de compra",Base!$A$2:$A$4835,D$4) | E32: =SUMIFS(Base!$N$2:$N$4835,Base!$B$2:$B$4835,"Frete de compra",Base!$C$2:$C$4835,"Frete de compra",Base!$A$2:$A$4835,E$4) | F32: =SUMIFS(Base!$N$2:$N$4835,Base!$B$2:$B$4835,"Frete de compra",Base!$C$2:$C$4835,"Frete de compra",Base!$A$2:$A$4835,F$4) | G32: =SUMIFS(Base!$N$2:$N$4835,Base!$B$2:$B$4835,"Frete de compra",Base!$C$2:$C$4835,"Frete de compra",Base!$A$2:$A$4835,G$4) | H32: =SUMIFS(Base!$N$2:$N$4835,Base!$B$2:$B$4835,"Frete de compra",Base!$C$2:$C$4835,"Frete de compra",Base!$A$2:$A$4835,H$4) | I32: =SUMIFS(Base!$N$2:$N$4835,Base!$B$2:$B$4835,"Frete de compra",Base!$C$2:$C$4835,"Frete de compra",Base!$A$2:$A$4835,I$4) | J32: =SUMIFS(Base!$N$2:$N$4835,Base!$B$2:$B$4835,"Frete de compra",Base!$C$2:$C$4835,"Frete de compra",Base!$A$2:$A$4835,J$4) | K32: =SUM(B32:J32) | L32: =SUMIFS(Base!$N$2:$N$4835,Base!$B$2:$B$4835,"Frete de compra",Base!$C$2:$C$4835,"Frete de compra",Base!$A$2:$A$4835,"Antes de 2026")
A33: Total Frete de compra | B33: =SUM(B32:B32) | C33: =SUM(C32:C32) | D33: =SUM(D32:D32) | E33: =SUM(E32:E32) | F33: =SUM(F32:F32) | G33: =SUM(G32:G32) | H33: =SUM(H32:H32) | I33: =SUM(I32:I32) | ... L33: =SUM(L32:L32)
A35: Frete de venda
A36: Frete de venda (para clientes) | B36: =SUMIFS(Base!$N$2:$N$4835,Base!$B$2:$B$4835,"Frete de venda",Base!$C$2:$C$4835,"Frete de venda (para clientes)",Base!$A$2:$A$4835,B$4) | C36: =SUMIFS(Base!$N$2:$N$4835,Base!$B$2:$B$4835,"Frete de venda",Base!$C$2:$C$4835,"Frete de venda (para clientes)",Base!$A$2:$A$4835,C$4) | D36: =SUMIFS(Base!$N$2:$N$4835,Base!$B$2:$B$4835,"Frete de venda",Base!$C$2:$C$4835,"Frete de venda (para clientes)",Base!$A$2:$A$4835,D$4) | E36: =SUMIFS(Base!$N$2:$N$4835,Base!$B$2:$B$4835,"Frete de venda",Base!$C$2:$C$4835,"Frete de venda (para clientes)",Base!$A$2:$A$4835,E$4) | F36: =SUMIFS(Base!$N$2:$N$4835,Base!$B$2:$B$4835,"Frete de venda",Base!$C$2:$C$4835,"Frete de venda (para clientes)",Base!$A$2:$A$4835,F$4) | G36: =SUMIFS(Base!$N$2:$N$4835,Base!$B$2:$B$4835,"Frete de venda",Base!$C$2:$C$4835,"Frete de venda (para clientes)",Base!$A$2:$A$4835,G$4) | H36: =SUMIFS(Base!$N$2:$N$4835,Base!$B$2:$B$4835,"Frete de venda",Base!$C$2:$C$4835,"Frete de venda (para clientes)",Base!$A$2:$A$4835,H$4) | I36: =SUMIFS(Base!$N$2:$N$4835,Base!$B$2:$B$4835,"Frete de venda",Base!$C$2:$C$4835,"Frete de venda (para clientes)",Base!$A$2:$A$4835,I$4) | J36: =SUMIFS(Base!$N$2:$N$4835,Base!$B$2:$B$4835,"Frete de venda",Base!$C$2:$C$4835,"Frete de venda (para clientes)",Base!$A$2:$A$4835,J$4) | K36: =SUM(B36:J36) | L36: =SUMIFS(Base!$N$2:$N$4835,Base!$B$2:$B$4835,"Frete de venda",Base!$C$2:$C$4835,"Frete de venda (para clientes)",Base!$A$2:$A$4835,"Antes de 2026")
A37: Total Frete de venda | B37: =SUM(B36:B36) | C37: =SUM(C36:C36) | D37: =SUM(D36:D36) | E37: =SUM(E36:E36) | F37: =SUM(F36:F36) | G37: =SUM(G36:G36) | H37: =SUM(H36:H36) | I37: =SUM(I36:I36) | ... L37: =SUM(L36:L36)
A39: TOTAL DAS DESPESAS (líquido de créditos) | B39: =B18+B29+B33+B37 | C39: =C18+C29+C33+C37 | D39: =D18+D29+D33+D37 | E39: =E18+E29+E33+E37 | F39: =F18+F29+F33+F37 | G39: =G18+G29+G33+G37 | H39: =H18+H29+H33+H37 | I39: =I18+I29+I33+I37 | ... L39: =L18+L29+L33+L37
A41: Memo: valor bruto (com impostos) | B41: =SUMIFS(Base!$H$2:$H$4835,Base!$A$2:$A$4835,B$4) | C41: =SUMIFS(Base!$H$2:$H$4835,Base!$A$2:$A$4835,C$4) | D41: =SUMIFS(Base!$H$2:$H$4835,Base!$A$2:$A$4835,D$4) | E41: =SUMIFS(Base!$H$2:$H$4835,Base!$A$2:$A$4835,E$4) | F41: =SUMIFS(Base!$H$2:$H$4835,Base!$A$2:$A$4835,F$4) | G41: =SUMIFS(Base!$H$2:$H$4835,Base!$A$2:$A$4835,G$4) | H41: =SUMIFS(Base!$H$2:$H$4835,Base!$A$2:$A$4835,H$4) | I41: =SUMIFS(Base!$H$2:$H$4835,Base!$A$2:$A$4835,I$4) | J41: =SUMIFS(Base!$H$2:$H$4835,Base!$A$2:$A$4835,J$4) | K41: =SUM(B41:J41) | L41: =SUMIFS(Base!$H$2:$H$4835,Base!$A$2:$A$4835,"Antes de 2026")
A42: Memo: créditos de impostos abatidos | B42: =SUMIFS(Base!$M$2:$M$4835,Base!$A$2:$A$4835,B$4) | C42: =SUMIFS(Base!$M$2:$M$4835,Base!$A$2:$A$4835,C$4) | D42: =SUMIFS(Base!$M$2:$M$4835,Base!$A$2:$A$4835,D$4) | E42: =SUMIFS(Base!$M$2:$M$4835,Base!$A$2:$A$4835,E$4) | F42: =SUMIFS(Base!$M$2:$M$4835,Base!$A$2:$A$4835,F$4) | G42: =SUMIFS(Base!$M$2:$M$4835,Base!$A$2:$A$4835,G$4) | H42: =SUMIFS(Base!$M$2:$M$4835,Base!$A$2:$A$4835,H$4) | I42: =SUMIFS(Base!$M$2:$M$4835,Base!$A$2:$A$4835,I$4) | J42: =SUMIFS(Base!$M$2:$M$4835,Base!$A$2:$A$4835,J$4) | K42: =SUM(B42:J42) | L42: =SUMIFS(Base!$M$2:$M$4835,Base!$A$2:$A$4835,"Antes de 2026")
A43: Conferência: bruto − créditos − total (deve ser zero) | B43: =ROUND(B41-B42-B39,2) | C43: =ROUND(C41-C42-C39,2) | D43: =ROUND(D41-D42-D39,2) | E43: =ROUND(E41-E42-E39,2) | F43: =ROUND(F41-F42-F39,2) | G43: =ROUND(G41-G42-G39,2) | H43: =ROUND(H41-H42-H39,2) | I43: =ROUND(I41-I42-I39,2) | ... L43: =ROUND(L41-L42-L39,2)

Sheet Comparação mensal
A1: Comparação mensal – custo líquido de créditos (R$, positivo = gasto)
A2: Variação = mês contra o mês anterior. Vermelho: alta acima de 20%; verde: queda acima de 20%. Pico = mês de maior gasto.
A4: Por destino | B4: 46023 | C4: 46054 | D4: 46082 | E4: 46113 | F4: 46143 | G4: 46174 | H4: 46204 | I4: 46235 | J4: 46266 | K4: Total 2026 | L4: Média mensal | M4: Maior mês | N4: Mês do pico
A5: Insumos e papel | B5: =SUMIFS(Base!$N$2:$N$4835,Base!$B$2:$B$4835,"Insumos e papel",Base!$A$2:$A$4835,B$4) | C5: =SUMIFS(Base!$N$2:$N$4835,Base!$B$2:$B$4835,"Insumos e papel",Base!$A$2:$A$4835,C$4) | D5: =SUMIFS(Base!$N$2:$N$4835,Base!$B$2:$B$4835,"Insumos e papel",Base!$A$2:$A$4835,D$4) | E5: =SUMIFS(Base!$N$2:$N$4835,Base!$B$2:$B$4835,"Insumos e papel",Base!$A$2:$A$4835,E$4) | F5: =SUMIFS(Base!$N$2:$N$4835,Base!$B$2:$B$4835,"Insumos e papel",Base!$A$2:$A$4835,F$4) | G5: =SUMIFS(Base!$N$2:$N$4835,Base!$B$2:$B$4835,"Insumos e papel",Base!$A$2:$A$4835,G$4) | H5: =SUMIFS(Base!$N$2:$N$4835,Base!$B$2:$B$4835,"Insumos e papel",Base!$A$2:$A$4835,H$4) | I5: =SUMIFS(Base!$N$2:$N$4835,Base!$B$2:$B$4835,"Insumos e papel",Base!$A$2:$A$4835,I$4) | J5: =SUMIFS(Base!$N$2:$N$4835,Base!$B$2:$B$4835,"Insumos e papel",Base!$A$2:$A$4835,J$4) | K5: =SUM(B5:J5) | L5: =AVERAGE(B5:J5) | M5: =MAX(B5:J5) | N5: =IF(M5=0,"",INDEX($B$4:$J$4,MATCH(M5,B5:J5,0)))
A6: Uso e consumo | B6: =SUMIFS(Base!$N$2:$N$4835,Base!$B$2:$B$4835,"Uso e consumo",Base!$A$2:$A$4835,B$4) | C6: =SUMIFS(Base!$N$2:$N$4835,Base!$B$2:$B$4835,"Uso e consumo",Base!$A$2:$A$4835,C$4) | D6: =SUMIFS(Base!$N$2:$N$4835,Base!$B$2:$B$4835,"Uso e consumo",Base!$A$2:$A$4835,D$4) | E6: =SUMIFS(Base!$N$2:$N$4835,Base!$B$2:$B$4835,"Uso e consumo",Base!$A$2:$A$4835,E$4) | F6: =SUMIFS(Base!$N$2:$N$4835,Base!$B$2:$B$4835,"Uso e consumo",Base!$A$2:$A$4835,F$4) | G6: =SUMIFS(Base!$N$2:$N$4835,Base!$B$2:$B$4835,"Uso e consumo",Base!$A$2:$A$4835,G$4) | H6: =SUMIFS(Base!$N$2:$N$4835,Base!$B$2:$B$4835,"Uso e consumo",Base!$A$2:$A$4835,H$4) | I6: =SUMIFS(Base!$N$2:$N$4835,Base!$B$2:$B$4835,"Uso e consumo",Base!$A$2:$A$4835,I$4) | J6: =SUMIFS(Base!$N$2:$N$4835,Base!$B$2:$B$4835,"Uso e consumo",Base!$A$2:$A$4835,J$4) | K6: =SUM(B6:J6) | L6: =AVERAGE(B6:J6) | M6: =MAX(B6:J6) | N6: =IF(M6=0,"",INDEX($B$4:$J$4,MATCH(M6,B6:J6,0)))
A7: Frete de compra | B7: =SUMIFS(Base!$N$2:$N$4835,Base!$B$2:$B$4835,"Frete de compra",Base!$A$2:$A$4835,B$4) | C7: =SUMIFS(Base!$N$2:$N$4835,Base!$B$2:$B$4835,"Frete de compra",Base!$A$2:$A$4835,C$4) | D7: =SUMIFS(Base!$N$2:$N$4835,Base!$B$2:$B$4835,"Frete de compra",Base!$A$2:$A$4835,D$4) | E7: =SUMIFS(Base!$N$2:$N$4835,Base!$B$2:$B$4835,"Frete de compra",Base!$A$2:$A$4835,E$4) | F7: =SUMIFS(Base!$N$2:$N$4835,Base!$B$2:$B$4835,"Frete de compra",Base!$A$2:$A$4835,F$4) | G7: =SUMIFS(Base!$N$2:$N$4835,Base!$B$2:$B$4835,"Frete de compra",Base!$A$2:$A$4835,G$4) | H7: =SUMIFS(Base!$N$2:$N$4835,Base!$B$2:$B$4835,"Frete de compra",Base!$A$2:$A$4835,H$4) | I7: =SUMIFS(Base!$N$2:$N$4835,Base!$B$2:$B$4835,"Frete de compra",Base!$A$2:$A$4835,I$4) | J7: =SUMIFS(Base!$N$2:$N$4835,Base!$B$2:$B$4835,"Frete de compra",Base!$A$2:$A$4835,J$4) | K7: =SUM(B7:J7) | L7: =AVERAGE(B7:J7) | M7: =MAX(B7:J7) | N7: =IF(M7=0,"",INDEX($B$4:$J$4,MATCH(M7,B7:J7,0)))
A8: Frete de venda | B8: =SUMIFS(Base!$N$2:$N$4835,Base!$B$2:$B$4835,"Frete de venda",Base!$A$2:$A$4835,B$4) | C8: =SUMIFS(Base!$N$2:$N$4835,Base!$B$2:$B$4835,"Frete de venda",Base!$A$2:$A$4835,C$4) | D8: =SUMIFS(Base!$N$2:$N$4835,Base!$B$2:$B$4835,"Frete de venda",Base!$A$2:$A$4835,D$4) | E8: =SUMIFS(Base!$N$2:$N$4835,Base!$B$2:$B$4835,"Frete de venda",Base!$A$2:$A$4835,E$4) | F8: =SUMIFS(Base!$N$2:$N$4835,Base!$B$2:$B$4835,"Frete de venda",Base!$A$2:$A$4835,F$4) | G8: =SUMIFS(Base!$N$2:$N$4835,Base!$B$2:$B$4835,"Frete de venda",Base!$A$2:$A$4835,G$4) | H8: =SUMIFS(Base!$N$2:$N$4835,Base!$B$2:$B$4835,"Frete de venda",Base!$A$2:$A$4835,H$4) | I8: =SUMIFS(Base!$N$2:$N$4835,Base!$B$2:$B$4835,"Frete de venda",Base!$A$2:$A$4835,I$4) | J8: =SUMIFS(Base!$N$2:$N$4835,Base!$B$2:$B$4835,"Frete de venda",Base!$A$2:$A$4835,J$4) | K8: =SUM(B8:J8) | L8: =AVERAGE(B8:J8) | M8: =MAX(B8:J8) | N8: =IF(M8=0,"",INDEX($B$4:$J$4,MATCH(M8,B8:J8,0)))
A9: TOTAL | B9: =SUM(B5:B8) | C9: =SUM(C5:C8) | D9: =SUM(D5:D8) | E9: =SUM(E5:E8) | F9: =SUM(F5:F8) | G9: =SUM(G5:G8) | H9: =SUM(H5:H8) | I9: =SUM(I5:I8) | ... K9: =SUM(K5:K8) | L9: =AVERAGE(B9:J9) | M9: =MAX(B9:J9) | N9: =INDEX($B$4:$J$4,MATCH(M9,B9:J9,0))
A11: Variação % vs mês anterior – destino | B11: 46023 | C11: 46054 | D11: 46082 | E11: 46113 | F11: 46143 | G11: 46174 | H11: 46204 | I11: 46235 | J11: 46266 | K11: Total 2026 | L11: Média mensal | M11: Maior mês | N11: Mês do pico
A12: =A5 | C12: =IF(B5=0,"",C5/B5-1) | D12: =IF(C5=0,"",D5/C5-1) | E12: =IF(D5=0,"",E5/D5-1) | F12: =IF(E5=0,"",F5/E5-1) | G12: =IF(F5=0,"",G5/F5-1) | H12: =IF(G5=0,"",H5/G5-1) | I12: =IF(H5=0,"",I5/H5-1) | J12: =IF(I5=0,"",J5/I5-1)
A13: =A6 | C13: =IF(B6=0,"",C6/B6-1) | D13: =IF(C6=0,"",D6/C6-1) | E13: =IF(D6=0,"",E6/D6-1) | F13: =IF(E6=0,"",F6/E6-1) | G13: =IF(F6=0,"",G6/F6-1) | H13: =IF(G6=0,"",H6/G6-1) | I13: =IF(H6=0,"",I6/H6-1) | J13: =IF(I6=0,"",J6/I6-1)
A14: =A7 | C14: =IF(B7=0,"",C7/B7-1) | D14: =IF(C7=0,"",D7/C7-1) | E14: =IF(D7=0,"",E7/D7-1) | F14: =IF(E7=0,"",F7/E7-1) | G14: =IF(F7=0,"",G7/F7-1) | H14: =IF(G7=0,"",H7/G7-1) | I14: =IF(H7=0,"",I7/H7-1) | J14: =IF(I7=0,"",J7/I7-1)
A15: =A8 | C15: =IF(B8=0,"",C8/B8-1) | D15: =IF(C8=0,"",D8/C8-1) | E15: =IF(D8=0,"",E8/D8-1) | F15: =IF(E8=0,"",F8/E8-1) | G15: =IF(F8=0,"",G8/F8-1) | H15: =IF(G8=0,"",H8/G8-1) | I15: =IF(H8=0,"",I8/H8-1) | J15: =IF(I8=0,"",J8/I8-1)
A16: =A9 | C16: =IF(B9=0,"",C9/B9-1) | D16: =IF(C9=0,"",D9/C9-1) | E16: =IF(D9=0,"",E9/D9-1) | F16: =IF(E9=0,"",F9/E9-1) | G16: =IF(F9=0,"",G9/F9-1) | H16: =IF(G9=0,"",H9/G9-1) | I16: =IF(H9=0,"",I9/H9-1) | J16: =IF(I9=0,"",J9/I9-1)
A18: Participação no total do mês | B18: 46023 | C18: 46054 | D18: 46082 | E18: 46113 | F18: 46143 | G18: 46174 | H18: 46204 | I18: 46235 | J18: 46266 | K18: Total 2026 | L18: Média mensal | M18: Maior mês | N18: Mês do pico
A19: =A5 | B19: =IFERROR(B5/B$9,"") | C19: =IFERROR(C5/C$9,"") | D19: =IFERROR(D5/D$9,"") | E19: =IFERROR(E5/E$9,"") | F19: =IFERROR(F5/F$9,"") | G19: =IFERROR(G5/G$9,"") | H19: =IFERROR(H5/H$9,"") | I19: =IFERROR(I5/I$9,"") | ... K19: =IFERROR(K5/K$9,"")
A20: =A6 | B20: =IFERROR(B6/B$9,"") | C20: =IFERROR(C6/C$9,"") | D20: =IFERROR(D6/D$9,"") | E20: =IFERROR(E6/E$9,"") | F20: =IFERROR(F6/F$9,"") | G20: =IFERROR(G6/G$9,"") | H20: =IFERROR(H6/H$9,"") | I20: =IFERROR(I6/I$9,"") | ... K20: =IFERROR(K6/K$9,"")
A21: =A7 | B21: =IFERROR(B7/B$9,"") | C21: =IFERROR(C7/C$9,"") | D21: =IFERROR(D7/D$9,"") | E21: =IFERROR(E7/E$9,"") | F21: =IFERROR(F7/F$9,"") | G21: =IFERROR(G7/G$9,"") | H21: =IFERROR(H7/H$9,"") | I21: =IFERROR(I7/I$9,"") | ... K21: =IFERROR(K7/K$9,"")
A22: =A8 | B22: =IFERROR(B8/B$9,"") | C22: =IFERROR(C8/C$9,"") | D22: =IFERROR(D8/D$9,"") | E22: =IFERROR(E8/E$9,"") | F22: =IFERROR(F8/F$9,"") | G22: =IFERROR(G8/G$9,"") | H22: =IFERROR(H8/H$9,"") | I22: =IFERROR(I8/I$9,"") | ... K22: =IFERROR(K8/K$9,"")
A24: Por categoria do Omie | B24: 46023 | C24: 46054 | D24: 46082 | E24: 46113 | F24: 46143 | G24: 46174 | H24: 46204 | I24: 46235 | J24: 46266 | K24: Total 2026 | L24: Média mensal | M24: Maior mês | N24: Mês do pico
A25: Insumos e papel
A26: 2.01.03 Compra de Matéria Prima (Papel) | B26: =SUMIFS(Base!$N$2:$N$4835,Base!$B$2:$B$4835,"Insumos e papel",Base!$C$2:$C$4835,"2.01.03 Compra de Matéria Prima (Papel)",Base!$A$2:$A$4835,B$4) | C26: =SUMIFS(Base!$N$2:$N$4835,Base!$B$2:$B$4835,"Insumos e papel",Base!$C$2:$C$4835,"2.01.03 Compra de Matéria Prima (Papel)",Base!$A$2:$A$4835,C$4) | D26: =SUMIFS(Base!$N$2:$N$4835,Base!$B$2:$B$4835,"Insumos e papel",Base!$C$2:$C$4835,"2.01.03 Compra de Matéria Prima (Papel)",Base!$A$2:$A$4835,D$4) | E26: =SUMIFS(Base!$N$2:$N$4835,Base!$B$2:$B$4835,"Insumos e papel",Base!$C$2:$C$4835,"2.01.03 Compra de Matéria Prima (Papel)",Base!$A$2:$A$4835,E$4) | F26: =SUMIFS(Base!$N$2:$N$4835,Base!$B$2:$B$4835,"Insumos e papel",Base!$C$2:$C$4835,"2.01.03 Compra de Matéria Prima (Papel)",Base!$A$2:$A$4835,F$4) | G26: =SUMIFS(Base!$N$2:$N$4835,Base!$B$2:$B$4835,"Insumos e papel",Base!$C$2:$C$4835,"2.01.03 Compra de Matéria Prima (Papel)",Base!$A$2:$A$4835,G$4) | H26: =SUMIFS(Base!$N$2:$N$4835,Base!$B$2:$B$4835,"Insumos e papel",Base!$C$2:$C$4835,"2.01.03 Compra de Matéria Prima (Papel)",Base!$A$2:$A$4835,H$4) | I26: =SUMIFS(Base!$N$2:$N$4835,Base!$B$2:$B$4835,"Insumos e papel",Base!$C$2:$C$4835,"2.01.03 Compra de Matéria Prima (Papel)",Base!$A$2:$A$4835,I$4) | J26: =SUMIFS(Base!$N$2:$N$4835,Base!$B$2:$B$4835,"Insumos e papel",Base!$C$2:$C$4835,"2.01.03 Compra de Matéria Prima (Papel)",Base!$A$2:$A$4835,J$4) | K26: =SUM(B26:J26) | L26: =AVERAGE(B26:J26) | M26: =MAX(B26:J26) | N26: =IF(M26=0,"",INDEX($B$4:$J$4,MATCH(M26,B26:J26,0)))
A27: 2.01.79 Compra de Gás | B27: =SUMIFS(Base!$N$2:$N$4835,Base!$B$2:$B$4835,"Insumos e papel",Base!$C$2:$C$4835,"2.01.79 Compra de Gás",Base!$A$2:$A$4835,B$4) | C27: =SUMIFS(Base!$N$2:$N$4835,Base!$B$2:$B$4835,"Insumos e papel",Base!$C$2:$C$4835,"2.01.79 Compra de Gás",Base!$A$2:$A$4835,C$4) | D27: =SUMIFS(Base!$N$2:$N$4835,Base!$B$2:$B$4835,"Insumos e papel",Base!$C$2:$C$4835,"2.01.79 Compra de Gás",Base!$A$2:$A$4835,D$4) | E27: =SUMIFS(Base!$N$2:$N$4835,Base!$B$2:$B$4835,"Insumos e papel",Base!$C$2:$C$4835,"2.01.79 Compra de Gás",Base!$A$2:$A$4835,E$4) | F27: =SUMIFS(Base!$N$2:$N$4835,Base!$B$2:$B$4835,"Insumos e papel",Base!$C$2:$C$4835,"2.01.79 Compra de Gás",Base!$A$2:$A$4835,F$4) | G27: =SUMIFS(Base!$N$2:$N$4835,Base!$B$2:$B$4835,"Insumos e papel",Base!$C$2:$C$4835,"2.01.79 Compra de Gás",Base!$A$2:$A$4835,G$4) | H27: =SUMIFS(Base!$N$2:$N$4835,Base!$B$2:$B$4835,"Insumos e papel",Base!$C$2:$C$4835,"2.01.79 Compra de Gás",Base!$A$2:$A$4835,H$4) | I27: =SUMIFS(Base!$N$2:$N$4835,Base!$B$2:$B$4835,"Insumos e papel",Base!$C$2:$C$4835,"2.01.79 Compra de Gás",Base!$A$2:$A$4835,I$4) | J27: =SUMIFS(Base!$N$2:$N$4835,Base!$B$2:$B$4835,"Insumos e papel",Base!$C$2:$C$4835,"2.01.79 Compra de Gás",Base!$A$2:$A$4835,J$4) | K27: =SUM(B27:J27) | L27: =AVERAGE(B27:J27) | M27: =MAX(B27:J27) | N27: =IF(M27=0,"",INDEX($B$4:$J$4,MATCH(M27,B27:J27,0)))
A28: 2.01.83 Compra de Etiqueta Personalizada | B28: =SUMIFS(Base!$N$2:$N$4835,Base!$B$2:$B$4835,"Insumos e papel",Base!$C$2:$C$4835,"2.01.83 Compra de Etiqueta Personalizada",Base!$A$2:$A$4835,B$4) | C28: =SUMIFS(Base!$N$2:$N$4835,Base!$B$2:$B$4835,"Insumos e papel",Base!$C$2:$C$4835,"2.01.83 Compra de Etiqueta Personalizada",Base!$A$2:$A$4835,C$4) | D28: =SUMIFS(Base!$N$2:$N$4835,Base!$B$2:$B$4835,"Insumos e papel",Base!$C$2:$C$4835,"2.01.83 Compra de Etiqueta Personalizada",Base!$A$2:$A$4835,D$4) | E28: =SUMIFS(Base!$N$2:$N$4835,Base!$B$2:$B$4835,"Insumos e papel",Base!$C$2:$C$4835,"2.01.83 Compra de Etiqueta Personalizada",Base!$A$2:$A$4835,E$4) | F28: =SUMIFS(Base!$N$2:$N$4835,Base!$B$2:$B$4835,"Insumos e papel",Base!$C$2:$C$4835,"2.01.83 Compra de Etiqueta Personalizada",Base!$A$2:$A$4835,F$4) | G28: =SUMIFS(Base!$N$2:$N$4835,Base!$B$2:$B$4835,"Insumos e papel",Base!$C$2:$C$4835,"2.01.83 Compra de Etiqueta Personalizada",Base!$A$2:$A$4835,G$4) | H28: =SUMIFS(Base!$N$2:$N$4835,Base!$B$2:$B$4835,"Insumos e papel",Base!$C$2:$C$4835,"2.01.83 Compra de Etiqueta Personalizada",Base!$A$2:$A$4835,H$4) | I28: =SUMIFS(Base!$N$2:$N$4835,Base!$B$2:$B$4835,"Insumos e papel",Base!$C$2:$C$4835,"2.01.83 Compra de Etiqueta Personalizada",Base!$A$2:$A$4835,I$4) | J28: =SUMIFS(Base!$N$2:$N$4835,Base!$B$2:$B$4835,"Insumos e papel",Base!$C$2:$C$4835,"2.01.83 Compra de Etiqueta Personalizada",Base!$A$2:$A$4835,J$4) | K28: =SUM(B28:J28) | L28: =AVERAGE(B28:J28) | M28: =MAX(B28:J28) | N28: =IF(M28=0,"",INDEX($B$4:$J$4,MATCH(M28,B28:J28,0)))
A29: 2.01.89 Compra de Pallet | B29: =SUMIFS(Base!$N$2:$N$4835,Base!$B$2:$B$4835,"Insumos e papel",Base!$C$2:$C$4835,"2.01.89 Compra de Pallet",Base!$A$2:$A$4835,B$4) | C29: =SUMIFS(Base!$N$2:$N$4835,Base!$B$2:$B$4835,"Insumos e papel",Base!$C$2:$C$4835,"2.01.89 Compra de Pallet",Base!$A$2:$A$4835,C$4) | D29: =SUMIFS(Base!$N$2:$N$4835,Base!$B$2:$B$4835,"Insumos e papel",Base!$C$2:$C$4835,"2.01.89 Compra de Pallet",Base!$A$2:$A$4835,D$4) | E29: =SUMIFS(Base!$N$2:$N$4835,Base!$B$2:$B$4835,"Insumos e papel",Base!$C$2:$C$4835,"2.01.89 Compra de Pallet",Base!$A$2:$A$4835,E$4) | F29: =SUMIFS(Base!$N$2:$N$4835,Base!$B$2:$B$4835,"Insumos e papel",Base!$C$2:$C$4835,"2.01.89 Compra de Pallet",Base!$A$2:$A$4835,F$4) | G29: =SUMIFS(Base!$N$2:$N$4835,Base!$B$2:$B$4835,"Insumos e papel",Base!$C$2:$C$4835,"2.01.89 Compra de Pallet",Base!$A$2:$A$4835,G$4) | H29: =SUMIFS(Base!$N$2:$N$4835,Base!$B$2:$B$4835,"Insumos e papel",Base!$C$2:$C$4835,"2.01.89 Compra de Pallet",Base!$A$2:$A$4835,H$4) | I29: =SUMIFS(Base!$N$2:$N$4835,Base!$B$2:$B$4835,"Insumos e papel",Base!$C$2:$C$4835,"2.01.89 Compra de Pallet",Base!$A$2:$A$4835,I$4) | J29: =SUMIFS(Base!$N$2:$N$4835,Base!$B$2:$B$4835,"Insumos e papel",Base!$C$2:$C$4835,"2.01.89 Compra de Pallet",Base!$A$2:$A$4835,J$4) | K29: =SUM(B29:J29) | L29: =AVERAGE(B29:J29) | M29: =MAX(B29:J29) | N29: =IF(M29=0,"",INDEX($B$4:$J$4,MATCH(M29,B29:J29,0)))
A30: 2.01.91 Compra de Filme Strech | B30: =SUMIFS(Base!$N$2:$N$4835,Base!$B$2:$B$4835,"Insumos e papel",Base!$C$2:$C$4835,"2.01.91 Compra de Filme Strech",Base!$A$2:$A$4835,B$4) | C30: =SUMIFS(Base!$N$2:$N$4835,Base!$B$2:$B$4835,"Insumos e papel",Base!$C$2:$C$4835,"2.01.91 Compra de Filme Strech",Base!$A$2:$A$4835,C$4) | D30: =SUMIFS(Base!$N$2:$N$4835,Base!$B$2:$B$4835,"Insumos e papel",Base!$C$2:$C$4835,"2.01.91 Compra de Filme Strech",Base!$A$2:$A$4835,D$4) | E30: =SUMIFS(Base!$N$2:$N$4835,Base!$B$2:$B$4835,"Insumos e papel",Base!$C$2:$C$4835,"2.01.91 Compra de Filme Strech",Base!$A$2:$A$4835,E$4) | F30: =SUMIFS(Base!$N$2:$N$4835,Base!$B$2:$B$4835,"Insumos e papel",Base!$C$2:$C$4835,"2.01.91 Compra de Filme Strech",Base!$A$2:$A$4835,F$4) | G30: =SUMIFS(Base!$N$2:$N$4835,Base!$B$2:$B$4835,"Insumos e papel",Base!$C$2:$C$4835,"2.01.91 Compra de Filme Strech",Base!$A$2:$A$4835,G$4) | H30: =SUMIFS(Base!$N$2:$N$4835,Base!$B$2:$B$4835,"Insumos e papel",Base!$C$2:$C$4835,"2.01.91 Compra de Filme Strech",Base!$A$2:$A$4835,H$4) | I30: =SUMIFS(Base!$N$2:$N$4835,Base!$B$2:$B$4835,"Insumos e papel",Base!$C$2:$C$4835,"2.01.91 Compra de Filme Strech",Base!$A$2:$A$4835,I$4) | J30: =SUMIFS(Base!$N$2:$N$4835,Base!$B$2:$B$4835,"Insumos e papel",Base!$C$2:$C$4835,"2.01.91 Compra de Filme Strech",Base!$A$2:$A$4835,J$4) | K30: =SUM(B30:J30) | L30: =AVERAGE(B30:J30) | M30: =MAX(B30:J30) | N30: =IF(M30=0,"",INDEX($B$4:$J$4,MATCH(M30,B30:J30,0)))
A31: 2.01.92 Compra de Tinta | B31: =SUMIFS(Base!$N$2:$N$4835,Base!$B$2:$B$4835,"Insumos e papel",Base!$C$2:$C$4835,"2.01.92 Compra de Tinta",Base!$A$2:$A$4835,B$4) | C31: =SUMIFS(Base!$N$2:$N$4835,Base!$B$2:$B$4835,"Insumos e papel",Base!$C$2:$C$4835,"2.01.92 Compra de Tinta",Base!$A$2:$A$4835,C$4) | D31: =SUMIFS(Base!$N$2:$N$4835,Base!$B$2:$B$4835,"Insumos e papel",Base!$C$2:$C$4835,"2.01.92 Compra de Tinta",Base!$A$2:$A$4835,D$4) | E31: =SUMIFS(Base!$N$2:$N$4835,Base!$B$2:$B$4835,"Insumos e papel",Base!$C$2:$C$4835,"2.01.92 Compra de Tinta",Base!$A$2:$A$4835,E$4) | F31: =SUMIFS(Base!$N$2:$N$4835,Base!$B$2:$B$4835,"Insumos e papel",Base!$C$2:$C$4835,"2.01.92 Compra de Tinta",Base!$A$2:$A$4835,F$4) | G31: =SUMIFS(Base!$N$2:$N$4835,Base!$B$2:$B$4835,"Insumos e papel",Base!$C$2:$C$4835,"2.01.92 Compra de Tinta",Base!$A$2:$A$4835,G$4) | H31: =SUMIFS(Base!$N$2:$N$4835,Base!$B$2:$B$4835,"Insumos e papel",Base!$C$2:$C$4835,"2.01.92 Compra de Tinta",Base!$A$2:$A$4835,H$4) | I31: =SUMIFS(Base!$N$2:$N$4835,Base!$B$2:$B$4835,"Insumos e papel",Base!$C$2:$C$4835,"2.01.92 Compra de Tinta",Base!$A$2:$A$4835,I$4) | J31: =SUMIFS(Base!$N$2:$N$4835,Base!$B$2:$B$4835,"Insumos e papel",Base!$C$2:$C$4835,"2.01.92 Compra de Tinta",Base!$A$2:$A$4835,J$4) | K31: =SUM(B31:J31) | L31: =AVERAGE(B31:J31) | M31: =MAX(B31:J31) | N31: =IF(M31=0,"",INDEX($B$4:$J$4,MATCH(M31,B31:J31,0)))
A32: 2.01.93 Compra de Plástico Poliolefínico | B32: =SUMIFS(Base!$N$2:$N$4835,Base!$B$2:$B$4835,"Insumos e papel",Base!$C$2:$C$4835,"2.01.93 Compra de Plástico Poliolefínico",Base!$A$2:$A$4835,B$4) | C32: =SUMIFS(Base!$N$2:$N$4835,Base!$B$2:$B$4835,"Insumos e papel",Base!$C$2:$C$4835,"2.01.93 Compra de Plástico Poliolefínico",Base!$A$2:$A$4835,C$4) | D32: =SUMIFS(Base!$N$2:$N$4835,Base!$B$2:$B$4835,"Insumos e papel",Base!$C$2:$C$4835,"2.01.93 Compra de Plástico Poliolefínico",Base!$A$2:$A$4835,D$4) | E32: =SUMIFS(Base!$N$2:$N$4835,Base!$B$2:$B$4835,"Insumos e papel",Base!$C$2:$C$4835,"2.01.93 Compra de Plástico Poliolefínico",Base!$A$2:$A$4835,E$4) | F32: =SUMIFS(Base!$N$2:$N$4835,Base!$B$2:$B$4835,"Insumos e papel",Base!$C$2:$C$4835,"2.01.93 Compra de Plástico Poliolefínico",Base!$A$2:$A$4835,F$4) | G32: =SUMIFS(Base!$N$2:$N$4835,Base!$B$2:$B$4835,"Insumos e papel",Base!$C$2:$C$4835,"2.01.93 Compra de Plástico Poliolefínico",Base!$A$2:$A$4835,G$4) | H32: =SUMIFS(Base!$N$2:$N$4835,Base!$B$2:$B$4835,"Insumos e papel",Base!$C$2:$C$4835,"2.01.93 Compra de Plástico Poliolefínico",Base!$A$2:$A$4835,H$4) | I32: =SUMIFS(Base!$N$2:$N$4835,Base!$B$2:$B$4835,"Insumos e papel",Base!$C$2:$C$4835,"2.01.93 Compra de Plástico Poliolefínico",Base!$A$2:$A$4835,I$4) | J32: =SUMIFS(Base!$N$2:$N$4835,Base!$B$2:$B$4835,"Insumos e papel",Base!$C$2:$C$4835,"2.01.93 Compra de Plástico Poliolefínico",Base!$A$2:$A$4835,J$4) | K32: =SUM(B32:J32) | L32: =AVERAGE(B32:J32) | M32: =MAX(B32:J32) | N32: =IF(M32=0,"",INDEX($B$4:$J$4,MATCH(M32,B32:J32,0)))
A33: 2.01.94 Compra de Fita Adesiva | B33: =SUMIFS(Base!$N$2:$N$4835,Base!$B$2:$B$4835,"Insumos e papel",Base!$C$2:$C$4835,"2.01.94 Compra de Fita Adesiva",Base!$A$2:$A$4835,B$4) | C33: =SUMIFS(Base!$N$2:$N$4835,Base!$B$2:$B$4835,"Insumos e papel",Base!$C$2:$C$4835,"2.01.94 Compra de Fita Adesiva",Base!$A$2:$A$4835,C$4) | D33: =SUMIFS(Base!$N$2:$N$4835,Base!$B$2:$B$4835,"Insumos e papel",Base!$C$2:$C$4835,"2.01.94 Compra de Fita Adesiva",Base!$A$2:$A$4835,D$4) | E33: =SUMIFS(Base!$N$2:$N$4835,Base!$B$2:$B$4835,"Insumos e papel",Base!$C$2:$C$4835,"2.01.94 Compra de Fita Adesiva",Base!$A$2:$A$4835,E$4) | F33: =SUMIFS(Base!$N$2:$N$4835,Base!$B$2:$B$4835,"Insumos e papel",Base!$C$2:$C$4835,"2.01.94 Compra de Fita Adesiva",Base!$A$2:$A$4835,F$4) | G33: =SUMIFS(Base!$N$2:$N$4835,Base!$B$2:$B$4835,"Insumos e papel",Base!$C$2:$C$4835,"2.01.94 Compra de Fita Adesiva",Base!$A$2:$A$4835,G$4) | H33: =SUMIFS(Base!$N$2:$N$4835,Base!$B$2:$B$4835,"Insumos e papel",Base!$C$2:$C$4835,"2.01.94 Compra de Fita Adesiva",Base!$A$2:$A$4835,H$4) | I33: =SUMIFS(Base!$N$2:$N$4835,Base!$B$2:$B$4835,"Insumos e papel",Base!$C$2:$C$4835,"2.01.94 Compra de Fita Adesiva",Base!$A$2:$A$4835,I$4) | J33: =SUMIFS(Base!$N$2:$N$4835,Base!$B$2:$B$4835,"Insumos e papel",Base!$C$2:$C$4835,"2.01.94 Compra de Fita Adesiva",Base!$A$2:$A$4835,J$4) | K33: =SUM(B33:J33) | L33: =AVERAGE(B33:J33) | M33: =MAX(B33:J33) | N33: =IF(M33=0,"",INDEX($B$4:$J$4,MATCH(M33,B33:J33,0)))
A34: 2.01.95 Compra de Etiqueta | B34: =SUMIFS(Base!$N$2:$N$4835,Base!$B$2:$B$4835,"Insumos e papel",Base!$C$2:$C$4835,"2.01.95 Compra de Etiqueta",Base!$A$2:$A$4835,B$4) | C34: =SUMIFS(Base!$N$2:$N$4835,Base!$B$2:$B$4835,"Insumos e papel",Base!$C$2:$C$4835,"2.01.95 Compra de Etiqueta",Base!$A$2:$A$4835,C$4) | D34: =SUMIFS(Base!$N$2:$N$4835,Base!$B$2:$B$4835,"Insumos e papel",Base!$C$2:$C$4835,"2.01.95 Compra de Etiqueta",Base!$A$2:$A$4835,D$4) | E34: =SUMIFS(Base!$N$2:$N$4835,Base!$B$2:$B$4835,"Insumos e papel",Base!$C$2:$C$4835,"2.01.95 Compra de Etiqueta",Base!$A$2:$A$4835,E$4) | F34: =SUMIFS(Base!$N$2:$N$4835,Base!$B$2:$B$4835,"Insumos e papel",Base!$C$2:$C$4835,"2.01.95 Compra de Etiqueta",Base!$A$2:$A$4835,F$4) | G34: =SUMIFS(Base!$N$2:$N$4835,Base!$B$2:$B$4835,"Insumos e papel",Base!$C$2:$C$4835,"2.01.95 Compra de Etiqueta",Base!$A$2:$A$4835,G$4) | H34: =SUMIFS(Base!$N$2:$N$4835,Base!$B$2:$B$4835,"Insumos e papel",Base!$C$2:$C$4835,"2.01.95 Compra de Etiqueta",Base!$A$2:$A$4835,H$4) | I34: =SUMIFS(Base!$N$2:$N$4835,Base!$B$2:$B$4835,"Insumos e papel",Base!$C$2:$C$4835,"2.01.95 Compra de Etiqueta",Base!$A$2:$A$4835,I$4) | J34: =SUMIFS(Base!$N$2:$N$4835,Base!$B$2:$B$4835,"Insumos e papel",Base!$C$2:$C$4835,"2.01.95 Compra de Etiqueta",Base!$A$2:$A$4835,J$4) | K34: =SUM(B34:J34) | L34: =AVERAGE(B34:J34) | M34: =MAX(B34:J34) | N34: =IF(M34=0,"",INDEX($B$4:$J$4,MATCH(M34,B34:J34,0)))
A35: 2.01.96 Compra de Cola | B35: =SUMIFS(Base!$N$2:$N$4835,Base!$B$2:$B$4835,"Insumos e papel",Base!$C$2:$C$4835,"2.01.96 Compra de Cola",Base!$A$2:$A$4835,B$4) | C35: =SUMIFS(Base!$N$2:$N$4835,Base!$B$2:$B$4835,"Insumos e papel",Base!$C$2:$C$4835,"2.01.96 Compra de Cola",Base!$A$2:$A$4835,C$4) | D35: =SUMIFS(Base!$N$2:$N$4835,Base!$B$2:$B$4835,"Insumos e papel",Base!$C$2:$C$4835,"2.01.96 Compra de Cola",Base!$A$2:$A$4835,D$4) | E35: =SUMIFS(Base!$N$2:$N$4835,Base!$B$2:$B$4835,"Insumos e papel",Base!$C$2:$C$4835,"2.01.96 Compra de Cola",Base!$A$2:$A$4835,E$4) | F35: =SUMIFS(Base!$N$2:$N$4835,Base!$B$2:$B$4835,"Insumos e papel",Base!$C$2:$C$4835,"2.01.96 Compra de Cola",Base!$A$2:$A$4835,F$4) | G35: =SUMIFS(Base!$N$2:$N$4835,Base!$B$2:$B$4835,"Insumos e papel",Base!$C$2:$C$4835,"2.01.96 Compra de Cola",Base!$A$2:$A$4835,G$4) | H35: =SUMIFS(Base!$N$2:$N$4835,Base!$B$2:$B$4835,"Insumos e papel",Base!$C$2:$C$4835,"2.01.96 Compra de Cola",Base!$A$2:$A$4835,H$4) | I35: =SUMIFS(Base!$N$2:$N$4835,Base!$B$2:$B$4835,"Insumos e papel",Base!$C$2:$C$4835,"2.01.96 Compra de Cola",Base!$A$2:$A$4835,I$4) | J35: =SUMIFS(Base!$N$2:$N$4835,Base!$B$2:$B$4835,"Insumos e papel",Base!$C$2:$C$4835,"2.01.96 Compra de Cola",Base!$A$2:$A$4835,J$4) | K35: =SUM(B35:J35) | L35: =AVERAGE(B35:J35) | M35: =MAX(B35:J35) | N35: =IF(M35=0,"",INDEX($B$4:$J$4,MATCH(M35,B35:J35,0)))
A36: 2.01.97 Compra de Clichê | B36: =SUMIFS(Base!$N$2:$N$4835,Base!$B$2:$B$4835,"Insumos e papel",Base!$C$2:$C$4835,"2.01.97 Compra de Clichê",Base!$A$2:$A$4835,B$4) | C36: =SUMIFS(Base!$N$2:$N$4835,Base!$B$2:$B$4835,"Insumos e papel",Base!$C$2:$C$4835,"2.01.97 Compra de Clichê",Base!$A$2:$A$4835,C$4) | D36: =SUMIFS(Base!$N$2:$N$4835,Base!$B$2:$B$4835,"Insumos e papel",Base!$C$2:$C$4835,"2.01.97 Compra de Clichê",Base!$A$2:$A$4835,D$4) | E36: =SUMIFS(Base!$N$2:$N$4835,Base!$B$2:$B$4835,"Insumos e papel",Base!$C$2:$C$4835,"2.01.97 Compra de Clichê",Base!$A$2:$A$4835,E$4) | F36: =SUMIFS(Base!$N$2:$N$4835,Base!$B$2:$B$4835,"Insumos e papel",Base!$C$2:$C$4835,"2.01.97 Compra de Clichê",Base!$A$2:$A$4835,F$4) | G36: =SUMIFS(Base!$N$2:$N$4835,Base!$B$2:$B$4835,"Insumos e papel",Base!$C$2:$C$4835,"2.01.97 Compra de Clichê",Base!$A$2:$A$4835,G$4) | H36: =SUMIFS(Base!$N$2:$N$4835,Base!$B$2:$B$4835,"Insumos e papel",Base!$C$2:$C$4835,"2.01.97 Compra de Clichê",Base!$A$2:$A$4835,H$4) | I36: =SUMIFS(Base!$N$2:$N$4835,Base!$B$2:$B$4835,"Insumos e papel",Base!$C$2:$C$4835,"2.01.97 Compra de Clichê",Base!$A$2:$A$4835,I$4) | J36: =SUMIFS(Base!$N$2:$N$4835,Base!$B$2:$B$4835,"Insumos e papel",Base!$C$2:$C$4835,"2.01.97 Compra de Clichê",Base!$A$2:$A$4835,J$4) | K36: =SUM(B36:J36) | L36: =AVERAGE(B36:J36) | M36: =MAX(B36:J36) | N36: =IF(M36=0,"",INDEX($B$4:$J$4,MATCH(M36,B36:J36,0)))
