Workbook

Sheet LEIAME
A1: Despesas pagas 2026 – VINCO (planilha completa)
A2: Fonte: aba Notas de entradas_conferidas_2026_ajustado_v3.xlsx (Omie). R$; competência = mês de emissão; "Antes de 2026" = documentos emitidos antes de 2026 e conferidos em 2026 (memo, fora do total 2026).
A4: 1) Abas
A5: Aba | B5: Conteúdo
A6: Resumo geral | B6: Categoria e subcategoria × mês (Jan–Set/2026), total, % do total, memo antes de 2026, total por categoria de nível 1 e conferências (zero).
A7: Insumos e papel | B7: Subcategoria × mês e fornecedores com total e %.
A8: Uso e consumo | B8: Idem (material de consumo, peças, fardamento, EPI, limpeza, escritório).
A9: Frete de compra | B9: Idem (Aliança, Stancanelli, Gol, Planeta Azul).
A10: Frete de venda | B10: Idem (demais transportadoras).
A11: Outras despesas pagas | B11: Imobilizado, manutenção, sede, brindes, combustível e aluguel de contêiner (cada um uma subcategoria).
A12: Lançamentos | B12: Base: uma linha por documento pago (categoria, subcategoria, mês, data, tipo, número, fornecedor, CNPJ, bruto, crédito, líquido, CFOP, observação, impostos, chave). Todas as abas de resumo são SUMIFS sobre ela.
A13: Excluídos | B13: Documentos que não são pagamento ou são duplicidade (remessa, devolução, transferência, x.949, x.922, NF-e sem título), com o motivo.
A14: Premissas | B14: Tabela editável de créditos (IPI/ICMS/PIS/COFINS) por categoria e subcategoria, com a justificativa fiscal.
A16: 2) Regras aplicadas
A17: • Só o efetivamente pago: NF-e entra se "Gerou título a pagar" = Sim; CT-e (frete) entram todos.
A18: • Fora (aba Excluídos): remessa (categoria 2.01.84, exceto frete 2.01.84 "por conta do remetente", que entra como frete); devoluções (2.09); remessa sem venda x.949; transferências 0.01; simples faturamento x.922 (duplica x.116/x.117); NF-e sem título.
A19: • Aluguel de contêiner (UNIAO MULTIMODAL OTM LTDA) não é frete: fica em Outras despesas pagas.
A20: • Insumos e papel: 2.01.03, 79, 83, 89, 91, 92, 93, 94, 95, 96, 97, 99. Uso e consumo: 2.01.85, 2.01.87 (peças de máquinas), 2.03.88 fardamento, 2.03.90 EPI, 2.04.91, 2.04.06, 2.04.95, 2.04.96.
A21: • Frete de compra = somente ALIANCA NAVEGACAO E LOGISTICA (com/sem ponto final, unificadas), STANCANELLI, GOL LINHAS AEREAS e TRANSPORTES DE MAQUINAS PLANETA AZUL. Frete de venda = todas as demais transportadoras (inclui Cazan e RF BRA).
A22: • Créditos (Lucro Real): insumos = IPI+ICMS+PIS+COFINS; uso e consumo = só PIS/COFINS; frete de compra = só ICMS; frete de venda = nenhum; sem crédito de ICMS/IPI em CFOP x.556; ICMS-ST nunca é abatido. Detalhe por categoria na aba Premissas (editável).
A23: • Todas as demais categorias pagas (imobilizado 2.07 e 2.01.78, manutenção, sede 2.16, brindes/premiações/marketing, combustível) ficam em Outras despesas pagas, sem crédito modelado.
A25: 3) Correções fiscais desta revisão (comparação com a versão anterior despesas_2026.xlsx)
A26: Ajuste | B26: Motivo fiscal / o que mudou | G26: Efeito no líquido 2026 (R$)
A27: Impostos de documentos rateados (14 NF-e, 28 linhas) | B27: IPI/ICMS/PIS/COFINS constavam só na 1ª linha do rateio e eram creditados integralmente na categoria dessa linha (em 5 documentos o ICMS destacado chegava a superar o valor da categoria). Agora são redistribuídos proporcionalmente ao valor de cada categoria, pois o imposto do trecho de imobilizado/outra categoria não pertence ao insumo. Insumos: R$ 1.121,90; Uso e consumo: R$ 17,75. | G27: 1139.65
A28: PIS/COFINS de fardamento, material de escritório, copa e cozinha e bens de pequeno valor zerados | B28: Não são insumo da produção: o crédito de fardamento (Lei 10.833, art. 3º, X) é restrito a prestadoras de limpeza/conservação e material administrativo não gera crédito (PN Cosit 5/2018). EPI (2.03.90), peças (2.01.87), limpeza (2.04.91) e uso e consumo (2.01.85) mantêm PIS/COFINS. Editável na aba Premissas. | G28: 290.46
A29: Frete de compra classificado pelo nome da transportadora e Aliança unificada | B29: As grafias "ALIANCA ... LTDA" e "ALIANCA ... LTDA." viram um só fornecedor; o enquadramento em frete de compra/venda passa a seguir a lista de transportadoras da regra, não o grupo do Omie. Sem efeito nos totais. | G29: 0
A30: Aluguel de contêiner (UNIAO MULTIMODAL) em Outras despesas pagas | B30: CT-e da UNIAO MULTIMODAL OTM (R$ 293.060,00 bruto, sem ICMS) é locação/estadia de contêiner, não transporte; já estava fora do frete e agora aparece como subcategoria própria. | G30: 0
A31: Créditos calculados por fórmula em Lançamentos, por categoria | B31: A versão anterior definia créditos por destino; agora cada categoria tem seus flags (aba Premissas) e a coluna Crédito é fórmula, então qualquer ajuste recalcula tudo. | G31: 0
A32: Revisados e mantidos sem alteração | B32: ICMS-ST: nenhum valor relevante no escopo (R$ 250 em CT-e), nunca abatido, permanece no custo. PIS/COFINS de CT-e: não destacados nos CT-e (zero). CFOP x.556 sem ICMS/IPI: regra mantida. Frete de venda sem crédito: regra do usuário mantida (ver pendências). EPI: crédito de PIS/COFINS mantido (PN Cosit 5/2018). Estadia/cabotagem da Aliança (2.01.82): mantida com o ICMS destacado. | G32: 0
A34: 4) Totais por categoria (2026, fórmulas sobre Lançamentos)
A35: Categoria | B35: Nº docs 2026 | C35: Valor bruto 2026 | D35: Créditos 2026 | E35: Líquido 2026 | F35: % do líquido | G35: Bruto antes de 2026 | H35: Líquido antes de 2026
A36: Insumos e papel | B36: =COUNTIFS('Lançamentos'!$A$2:$A$5010,$A36,'Lançamentos'!$D$2:$D$5010,"Em 2026") | C36: =SUMIFS('Lançamentos'!$J$2:$J$5010,'Lançamentos'!$A$2:$A$5010,$A36,'Lançamentos'!$D$2:$D$5010,"Em 2026") | D36: =SUMIFS('Lançamentos'!$K$2:$K$5010,'Lançamentos'!$A$2:$A$5010,$A36,'Lançamentos'!$D$2:$D$5010,"Em 2026") | E36: =C36-D36 | F36: =E36/E$41 | G36: =SUMIFS('Lançamentos'!$J$2:$J$5010,'Lançamentos'!$A$2:$A$5010,$A36,'Lançamentos'!$D$2:$D$5010,"Antes de 2026") | H36: =G36-SUMIFS('Lançamentos'!$K$2:$K$5010,'Lançamentos'!$A$2:$A$5010,$A36,'Lançamentos'!$D$2:$D$5010,"Antes de 2026")
A37: Uso e consumo | B37: =COUNTIFS('Lançamentos'!$A$2:$A$5010,$A37,'Lançamentos'!$D$2:$D$5010,"Em 2026") | C37: =SUMIFS('Lançamentos'!$J$2:$J$5010,'Lançamentos'!$A$2:$A$5010,$A37,'Lançamentos'!$D$2:$D$5010,"Em 2026") | D37: =SUMIFS('Lançamentos'!$K$2:$K$5010,'Lançamentos'!$A$2:$A$5010,$A37,'Lançamentos'!$D$2:$D$5010,"Em 2026") | E37: =C37-D37 | F37: =E37/E$41 | G37: =SUMIFS('Lançamentos'!$J$2:$J$5010,'Lançamentos'!$A$2:$A$5010,$A37,'Lançamentos'!$D$2:$D$5010,"Antes de 2026") | H37: =G37-SUMIFS('Lançamentos'!$K$2:$K$5010,'Lançamentos'!$A$2:$A$5010,$A37,'Lançamentos'!$D$2:$D$5010,"Antes de 2026")
A38: Frete de compra | B38: =COUNTIFS('Lançamentos'!$A$2:$A$5010,$A38,'Lançamentos'!$D$2:$D$5010,"Em 2026") | C38: =SUMIFS('Lançamentos'!$J$2:$J$5010,'Lançamentos'!$A$2:$A$5010,$A38,'Lançamentos'!$D$2:$D$5010,"Em 2026") | D38: =SUMIFS('Lançamentos'!$K$2:$K$5010,'Lançamentos'!$A$2:$A$5010,$A38,'Lançamentos'!$D$2:$D$5010,"Em 2026") | E38: =C38-D38 | F38: =E38/E$41 | G38: =SUMIFS('Lançamentos'!$J$2:$J$5010,'Lançamentos'!$A$2:$A$5010,$A38,'Lançamentos'!$D$2:$D$5010,"Antes de 2026") | H38: =G38-SUMIFS('Lançamentos'!$K$2:$K$5010,'Lançamentos'!$A$2:$A$5010,$A38,'Lançamentos'!$D$2:$D$5010,"Antes de 2026")
A39: Frete de venda | B39: =COUNTIFS('Lançamentos'!$A$2:$A$5010,$A39,'Lançamentos'!$D$2:$D$5010,"Em 2026") | C39: =SUMIFS('Lançamentos'!$J$2:$J$5010,'Lançamentos'!$A$2:$A$5010,$A39,'Lançamentos'!$D$2:$D$5010,"Em 2026") | D39: =SUMIFS('Lançamentos'!$K$2:$K$5010,'Lançamentos'!$A$2:$A$5010,$A39,'Lançamentos'!$D$2:$D$5010,"Em 2026") | E39: =C39-D39 | F39: =E39/E$41 | G39: =SUMIFS('Lançamentos'!$J$2:$J$5010,'Lançamentos'!$A$2:$A$5010,$A39,'Lançamentos'!$D$2:$D$5010,"Antes de 2026") | H39: =G39-SUMIFS('Lançamentos'!$K$2:$K$5010,'Lançamentos'!$A$2:$A$5010,$A39,'Lançamentos'!$D$2:$D$5010,"Antes de 2026")
A40: Outras despesas pagas | B40: =COUNTIFS('Lançamentos'!$A$2:$A$5010,$A40,'Lançamentos'!$D$2:$D$5010,"Em 2026") | C40: =SUMIFS('Lançamentos'!$J$2:$J$5010,'Lançamentos'!$A$2:$A$5010,$A40,'Lançamentos'!$D$2:$D$5010,"Em 2026") | D40: =SUMIFS('Lançamentos'!$K$2:$K$5010,'Lançamentos'!$A$2:$A$5010,$A40,'Lançamentos'!$D$2:$D$5010,"Em 2026") | E40: =C40-D40 | F40: =E40/E$41 | G40: =SUMIFS('Lançamentos'!$J$2:$J$5010,'Lançamentos'!$A$2:$A$5010,$A40,'Lançamentos'!$D$2:$D$5010,"Antes de 2026") | H40: =G40-SUMIFS('Lançamentos'!$K$2:$K$5010,'Lançamentos'!$A$2:$A$5010,$A40,'Lançamentos'!$D$2:$D$5010,"Antes de 2026")
A41: TOTAL | B41: =SUM(B36:B40) | C41: =SUM(C36:C40) | D41: =SUM(D36:D40) | E41: =SUM(E36:E40) | F41: =E41/E41 | G41: =SUM(G36:G40) | H41: =SUM(H36:H40)
A43: 5) Reconciliação com a aba Notas (valor bruto, todas as linhas)
A44: Item | B44: Em 2026 | C44: Antes de 2026 | D44: Total | E44: Nº linhas
A45: Pago – Insumos e papel | B45: =SUMIFS('Lançamentos'!$J$2:$J$5010,'Lançamentos'!$A$2:$A$5010,"Insumos e papel",'Lançamentos'!$D$2:$D$5010,"Em 2026") | C45: =SUMIFS('Lançamentos'!$J$2:$J$5010,'Lançamentos'!$A$2:$A$5010,"Insumos e papel",'Lançamentos'!$D$2:$D$5010,"Antes de 2026") | D45: =B45+C45 | E45: =COUNTIFS('Lançamentos'!$A$2:$A$5010,"Insumos e papel")
...

Sheet Resumo geral
A1: Despesas pagas 2026 – resumo geral (VINCO)
A2: R$ por mês de emissão, custo líquido de créditos (aba Premissas). Só o efetivamente pago (NF-e com título a pagar + CT-e); sem remessa, devolução, transferência, x.949, x.922 e NF-e sem título (aba Excluídos). Todos os valores são SUMIFS sobre a aba Lançamentos.
A4: Categoria / Subcategoria | B4: 46023 | C4: 46054 | D4: 46082 | E4: 46113 | F4: 46143 | G4: 46174 | H4: 46204 | I4: 46235 | J4: 46266 | K4: Total 2026 | L4: % do total | M4: Memo: antes de 2026
A5: Insumos e papel | B5: =SUM(B6:B17) | C5: =SUM(C6:C17) | D5: =SUM(D6:D17) | E5: =SUM(E6:E17) | F5: =SUM(F6:F17) | G5: =SUM(G6:G17) | H5: =SUM(H6:H17) | I5: =SUM(I6:I17) | ... K5: =SUM(K6:K17) | L5: =K5/K$51 | M5: =SUM(M6:M17)
A6: 2.01.03 Compra de Matéria Prima (Papel) | B6: =SUMIFS('Lançamentos'!$L$2:$L$5010,'Lançamentos'!$A$2:$A$5010,"Insumos e papel",'Lançamentos'!$B$2:$B$5010,$A6,'Lançamentos'!$C$2:$C$5010,B$4) | C6: =SUMIFS('Lançamentos'!$L$2:$L$5010,'Lançamentos'!$A$2:$A$5010,"Insumos e papel",'Lançamentos'!$B$2:$B$5010,$A6,'Lançamentos'!$C$2:$C$5010,C$4) | D6: =SUMIFS('Lançamentos'!$L$2:$L$5010,'Lançamentos'!$A$2:$A$5010,"Insumos e papel",'Lançamentos'!$B$2:$B$5010,$A6,'Lançamentos'!$C$2:$C$5010,D$4) | E6: =SUMIFS('Lançamentos'!$L$2:$L$5010,'Lançamentos'!$A$2:$A$5010,"Insumos e papel",'Lançamentos'!$B$2:$B$5010,$A6,'Lançamentos'!$C$2:$C$5010,E$4) | F6: =SUMIFS('Lançamentos'!$L$2:$L$5010,'Lançamentos'!$A$2:$A$5010,"Insumos e papel",'Lançamentos'!$B$2:$B$5010,$A6,'Lançamentos'!$C$2:$C$5010,F$4) | G6: =SUMIFS('Lançamentos'!$L$2:$L$5010,'Lançamentos'!$A$2:$A$5010,"Insumos e papel",'Lançamentos'!$B$2:$B$5010,$A6,'Lançamentos'!$C$2:$C$5010,G$4) | H6: =SUMIFS('Lançamentos'!$L$2:$L$5010,'Lançamentos'!$A$2:$A$5010,"Insumos e papel",'Lançamentos'!$B$2:$B$5010,$A6,'Lançamentos'!$C$2:$C$5010,H$4) | I6: =SUMIFS('Lançamentos'!$L$2:$L$5010,'Lançamentos'!$A$2:$A$5010,"Insumos e papel",'Lançamentos'!$B$2:$B$5010,$A6,'Lançamentos'!$C$2:$C$5010,I$4) | J6: =SUMIFS('Lançamentos'!$L$2:$L$5010,'Lançamentos'!$A$2:$A$5010,"Insumos e papel",'Lançamentos'!$B$2:$B$5010,$A6,'Lançamentos'!$C$2:$C$5010,J$4) | K6: =SUM(B6:J6) | L6: =K6/K$51 | M6: =SUMIFS('Lançamentos'!$L$2:$L$5010,'Lançamentos'!$A$2:$A$5010,"Insumos e papel",'Lançamentos'!$B$2:$B$5010,$A6,'Lançamentos'!$C$2:$C$5010,"Antes de 2026")
A7: 2.01.79 Compra de Gás | B7: =SUMIFS('Lançamentos'!$L$2:$L$5010,'Lançamentos'!$A$2:$A$5010,"Insumos e papel",'Lançamentos'!$B$2:$B$5010,$A7,'Lançamentos'!$C$2:$C$5010,B$4) | C7: =SUMIFS('Lançamentos'!$L$2:$L$5010,'Lançamentos'!$A$2:$A$5010,"Insumos e papel",'Lançamentos'!$B$2:$B$5010,$A7,'Lançamentos'!$C$2:$C$5010,C$4) | D7: =SUMIFS('Lançamentos'!$L$2:$L$5010,'Lançamentos'!$A$2:$A$5010,"Insumos e papel",'Lançamentos'!$B$2:$B$5010,$A7,'Lançamentos'!$C$2:$C$5010,D$4) | E7: =SUMIFS('Lançamentos'!$L$2:$L$5010,'Lançamentos'!$A$2:$A$5010,"Insumos e papel",'Lançamentos'!$B$2:$B$5010,$A7,'Lançamentos'!$C$2:$C$5010,E$4) | F7: =SUMIFS('Lançamentos'!$L$2:$L$5010,'Lançamentos'!$A$2:$A$5010,"Insumos e papel",'Lançamentos'!$B$2:$B$5010,$A7,'Lançamentos'!$C$2:$C$5010,F$4) | G7: =SUMIFS('Lançamentos'!$L$2:$L$5010,'Lançamentos'!$A$2:$A$5010,"Insumos e papel",'Lançamentos'!$B$2:$B$5010,$A7,'Lançamentos'!$C$2:$C$5010,G$4) | H7: =SUMIFS('Lançamentos'!$L$2:$L$5010,'Lançamentos'!$A$2:$A$5010,"Insumos e papel",'Lançamentos'!$B$2:$B$5010,$A7,'Lançamentos'!$C$2:$C$5010,H$4) | I7: =SUMIFS('Lançamentos'!$L$2:$L$5010,'Lançamentos'!$A$2:$A$5010,"Insumos e papel",'Lançamentos'!$B$2:$B$5010,$A7,'Lançamentos'!$C$2:$C$5010,I$4) | J7: =SUMIFS('Lançamentos'!$L$2:$L$5010,'Lançamentos'!$A$2:$A$5010,"Insumos e papel",'Lançamentos'!$B$2:$B$5010,$A7,'Lançamentos'!$C$2:$C$5010,J$4) | K7: =SUM(B7:J7) | L7: =K7/K$51 | M7: =SUMIFS('Lançamentos'!$L$2:$L$5010,'Lançamentos'!$A$2:$A$5010,"Insumos e papel",'Lançamentos'!$B$2:$B$5010,$A7,'Lançamentos'!$C$2:$C$5010,"Antes de 2026")
A8: 2.01.83 Compra de Etiqueta Personalizada | B8: =SUMIFS('Lançamentos'!$L$2:$L$5010,'Lançamentos'!$A$2:$A$5010,"Insumos e papel",'Lançamentos'!$B$2:$B$5010,$A8,'Lançamentos'!$C$2:$C$5010,B$4) | C8: =SUMIFS('Lançamentos'!$L$2:$L$5010,'Lançamentos'!$A$2:$A$5010,"Insumos e papel",'Lançamentos'!$B$2:$B$5010,$A8,'Lançamentos'!$C$2:$C$5010,C$4) | D8: =SUMIFS('Lançamentos'!$L$2:$L$5010,'Lançamentos'!$A$2:$A$5010,"Insumos e papel",'Lançamentos'!$B$2:$B$5010,$A8,'Lançamentos'!$C$2:$C$5010,D$4) | E8: =SUMIFS('Lançamentos'!$L$2:$L$5010,'Lançamentos'!$A$2:$A$5010,"Insumos e papel",'Lançamentos'!$B$2:$B$5010,$A8,'Lançamentos'!$C$2:$C$5010,E$4) | F8: =SUMIFS('Lançamentos'!$L$2:$L$5010,'Lançamentos'!$A$2:$A$5010,"Insumos e papel",'Lançamentos'!$B$2:$B$5010,$A8,'Lançamentos'!$C$2:$C$5010,F$4) | G8: =SUMIFS('Lançamentos'!$L$2:$L$5010,'Lançamentos'!$A$2:$A$5010,"Insumos e papel",'Lançamentos'!$B$2:$B$5010,$A8,'Lançamentos'!$C$2:$C$5010,G$4) | H8: =SUMIFS('Lançamentos'!$L$2:$L$5010,'Lançamentos'!$A$2:$A$5010,"Insumos e papel",'Lançamentos'!$B$2:$B$5010,$A8,'Lançamentos'!$C$2:$C$5010,H$4) | I8: =SUMIFS('Lançamentos'!$L$2:$L$5010,'Lançamentos'!$A$2:$A$5010,"Insumos e papel",'Lançamentos'!$B$2:$B$5010,$A8,'Lançamentos'!$C$2:$C$5010,I$4) | J8: =SUMIFS('Lançamentos'!$L$2:$L$5010,'Lançamentos'!$A$2:$A$5010,"Insumos e papel",'Lançamentos'!$B$2:$B$5010,$A8,'Lançamentos'!$C$2:$C$5010,J$4) | K8: =SUM(B8:J8) | L8: =K8/K$51 | M8: =SUMIFS('Lançamentos'!$L$2:$L$5010,'Lançamentos'!$A$2:$A$5010,"Insumos e papel",'Lançamentos'!$B$2:$B$5010,$A8,'Lançamentos'!$C$2:$C$5010,"Antes de 2026")
A9: 2.01.89 Compra de Pallet | B9: =SUMIFS('Lançamentos'!$L$2:$L$5010,'Lançamentos'!$A$2:$A$5010,"Insumos e papel",'Lançamentos'!$B$2:$B$5010,$A9,'Lançamentos'!$C$2:$C$5010,B$4) | C9: =SUMIFS('Lançamentos'!$L$2:$L$5010,'Lançamentos'!$A$2:$A$5010,"Insumos e papel",'Lançamentos'!$B$2:$B$5010,$A9,'Lançamentos'!$C$2:$C$5010,C$4) | D9: =SUMIFS('Lançamentos'!$L$2:$L$5010,'Lançamentos'!$A$2:$A$5010,"Insumos e papel",'Lançamentos'!$B$2:$B$5010,$A9,'Lançamentos'!$C$2:$C$5010,D$4) | E9: =SUMIFS('Lançamentos'!$L$2:$L$5010,'Lançamentos'!$A$2:$A$5010,"Insumos e papel",'Lançamentos'!$B$2:$B$5010,$A9,'Lançamentos'!$C$2:$C$5010,E$4) | F9: =SUMIFS('Lançamentos'!$L$2:$L$5010,'Lançamentos'!$A$2:$A$5010,"Insumos e papel",'Lançamentos'!$B$2:$B$5010,$A9,'Lançamentos'!$C$2:$C$5010,F$4) | G9: =SUMIFS('Lançamentos'!$L$2:$L$5010,'Lançamentos'!$A$2:$A$5010,"Insumos e papel",'Lançamentos'!$B$2:$B$5010,$A9,'Lançamentos'!$C$2:$C$5010,G$4) | H9: =SUMIFS('Lançamentos'!$L$2:$L$5010,'Lançamentos'!$A$2:$A$5010,"Insumos e papel",'Lançamentos'!$B$2:$B$5010,$A9,'Lançamentos'!$C$2:$C$5010,H$4) | I9: =SUMIFS('Lançamentos'!$L$2:$L$5010,'Lançamentos'!$A$2:$A$5010,"Insumos e papel",'Lançamentos'!$B$2:$B$5010,$A9,'Lançamentos'!$C$2:$C$5010,I$4) | J9: =SUMIFS('Lançamentos'!$L$2:$L$5010,'Lançamentos'!$A$2:$A$5010,"Insumos e papel",'Lançamentos'!$B$2:$B$5010,$A9,'Lançamentos'!$C$2:$C$5010,J$4) | K9: =SUM(B9:J9) | L9: =K9/K$51 | M9: =SUMIFS('Lançamentos'!$L$2:$L$5010,'Lançamentos'!$A$2:$A$5010,"Insumos e papel",'Lançamentos'!$B$2:$B$5010,$A9,'Lançamentos'!$C$2:$C$5010,"Antes de 2026")
A10: 2.01.91 Compra de Filme Strech | B10: =SUMIFS('Lançamentos'!$L$2:$L$5010,'Lançamentos'!$A$2:$A$5010,"Insumos e papel",'Lançamentos'!$B$2:$B$5010,$A10,'Lançamentos'!$C$2:$C$5010,B$4) | C10: =SUMIFS('Lançamentos'!$L$2:$L$5010,'Lançamentos'!$A$2:$A$5010,"Insumos e papel",'Lançamentos'!$B$2:$B$5010,$A10,'Lançamentos'!$C$2:$C$5010,C$4) | D10: =SUMIFS('Lançamentos'!$L$2:$L$5010,'Lançamentos'!$A$2:$A$5010,"Insumos e papel",'Lançamentos'!$B$2:$B$5010,$A10,'Lançamentos'!$C$2:$C$5010,D$4) | E10: =SUMIFS('Lançamentos'!$L$2:$L$5010,'Lançamentos'!$A$2:$A$5010,"Insumos e papel",'Lançamentos'!$B$2:$B$5010,$A10,'Lançamentos'!$C$2:$C$5010,E$4) | F10: =SUMIFS('Lançamentos'!$L$2:$L$5010,'Lançamentos'!$A$2:$A$5010,"Insumos e papel",'Lançamentos'!$B$2:$B$5010,$A10,'Lançamentos'!$C$2:$C$5010,F$4) | G10: =SUMIFS('Lançamentos'!$L$2:$L$5010,'Lançamentos'!$A$2:$A$5010,"Insumos e papel",'Lançamentos'!$B$2:$B$5010,$A10,'Lançamentos'!$C$2:$C$5010,G$4) | H10: =SUMIFS('Lançamentos'!$L$2:$L$5010,'Lançamentos'!$A$2:$A$5010,"Insumos e papel",'Lançamentos'!$B$2:$B$5010,$A10,'Lançamentos'!$C$2:$C$5010,H$4) | I10: =SUMIFS('Lançamentos'!$L$2:$L$5010,'Lançamentos'!$A$2:$A$5010,"Insumos e papel",'Lançamentos'!$B$2:$B$5010,$A10,'Lançamentos'!$C$2:$C$5010,I$4) | J10: =SUMIFS('Lançamentos'!$L$2:$L$5010,'Lançamentos'!$A$2:$A$5010,"Insumos e papel",'Lançamentos'!$B$2:$B$5010,$A10,'Lançamentos'!$C$2:$C$5010,J$4) | K10: =SUM(B10:J10) | L10: =K10/K$51 | M10: =SUMIFS('Lançamentos'!$L$2:$L$5010,'Lançamentos'!$A$2:$A$5010,"Insumos e papel",'Lançamentos'!$B$2:$B$5010,$A10,'Lançamentos'!$C$2:$C$5010,"Antes de 2026")
A11: 2.01.92 Compra de Tinta | B11: =SUMIFS('Lançamentos'!$L$2:$L$5010,'Lançamentos'!$A$2:$A$5010,"Insumos e papel",'Lançamentos'!$B$2:$B$5010,$A11,'Lançamentos'!$C$2:$C$5010,B$4) | C11: =SUMIFS('Lançamentos'!$L$2:$L$5010,'Lançamentos'!$A$2:$A$5010,"Insumos e papel",'Lançamentos'!$B$2:$B$5010,$A11,'Lançamentos'!$C$2:$C$5010,C$4) | D11: =SUMIFS('Lançamentos'!$L$2:$L$5010,'Lançamentos'!$A$2:$A$5010,"Insumos e papel",'Lançamentos'!$B$2:$B$5010,$A11,'Lançamentos'!$C$2:$C$5010,D$4) | E11: =SUMIFS('Lançamentos'!$L$2:$L$5010,'Lançamentos'!$A$2:$A$5010,"Insumos e papel",'Lançamentos'!$B$2:$B$5010,$A11,'Lançamentos'!$C$2:$C$5010,E$4) | F11: =SUMIFS('Lançamentos'!$L$2:$L$5010,'Lançamentos'!$A$2:$A$5010,"Insumos e papel",'Lançamentos'!$B$2:$B$5010,$A11,'Lançamentos'!$C$2:$C$5010,F$4) | G11: =SUMIFS('Lançamentos'!$L$2:$L$5010,'Lançamentos'!$A$2:$A$5010,"Insumos e papel",'Lançamentos'!$B$2:$B$5010,$A11,'Lançamentos'!$C$2:$C$5010,G$4) | H11: =SUMIFS('Lançamentos'!$L$2:$L$5010,'Lançamentos'!$A$2:$A$5010,"Insumos e papel",'Lançamentos'!$B$2:$B$5010,$A11,'Lançamentos'!$C$2:$C$5010,H$4) | I11: =SUMIFS('Lançamentos'!$L$2:$L$5010,'Lançamentos'!$A$2:$A$5010,"Insumos e papel",'Lançamentos'!$B$2:$B$5010,$A11,'Lançamentos'!$C$2:$C$5010,I$4) | J11: =SUMIFS('Lançamentos'!$L$2:$L$5010,'Lançamentos'!$A$2:$A$5010,"Insumos e papel",'Lançamentos'!$B$2:$B$5010,$A11,'Lançamentos'!$C$2:$C$5010,J$4) | K11: =SUM(B11:J11) | L11: =K11/K$51 | M11: =SUMIFS('Lançamentos'!$L$2:$L$5010,'Lançamentos'!$A$2:$A$5010,"Insumos e papel",'Lançamentos'!$B$2:$B$5010,$A11,'Lançamentos'!$C$2:$C$5010,"Antes de 2026")
A12: 2.01.93 Compra de Plástico Poliolefínico | B12: =SUMIFS('Lançamentos'!$L$2:$L$5010,'Lançamentos'!$A$2:$A$5010,"Insumos e papel",'Lançamentos'!$B$2:$B$5010,$A12,'Lançamentos'!$C$2:$C$5010,B$4) | C12: =SUMIFS('Lançamentos'!$L$2:$L$5010,'Lançamentos'!$A$2:$A$5010,"Insumos e papel",'Lançamentos'!$B$2:$B$5010,$A12,'Lançamentos'!$C$2:$C$5010,C$4) | D12: =SUMIFS('Lançamentos'!$L$2:$L$5010,'Lançamentos'!$A$2:$A$5010,"Insumos e papel",'Lançamentos'!$B$2:$B$5010,$A12,'Lançamentos'!$C$2:$C$5010,D$4) | E12: =SUMIFS('Lançamentos'!$L$2:$L$5010,'Lançamentos'!$A$2:$A$5010,"Insumos e papel",'Lançamentos'!$B$2:$B$5010,$A12,'Lançamentos'!$C$2:$C$5010,E$4) | F12: =SUMIFS('Lançamentos'!$L$2:$L$5010,'Lançamentos'!$A$2:$A$5010,"Insumos e papel",'Lançamentos'!$B$2:$B$5010,$A12,'Lançamentos'!$C$2:$C$5010,F$4) | G12: =SUMIFS('Lançamentos'!$L$2:$L$5010,'Lançamentos'!$A$2:$A$5010,"Insumos e papel",'Lançamentos'!$B$2:$B$5010,$A12,'Lançamentos'!$C$2:$C$5010,G$4) | H12: =SUMIFS('Lançamentos'!$L$2:$L$5010,'Lançamentos'!$A$2:$A$5010,"Insumos e papel",'Lançamentos'!$B$2:$B$5010,$A12,'Lançamentos'!$C$2:$C$5010,H$4) | I12: =SUMIFS('Lançamentos'!$L$2:$L$5010,'Lançamentos'!$A$2:$A$5010,"Insumos e papel",'Lançamentos'!$B$2:$B$5010,$A12,'Lançamentos'!$C$2:$C$5010,I$4) | J12: =SUMIFS('Lançamentos'!$L$2:$L$5010,'Lançamentos'!$A$2:$A$5010,"Insumos e papel",'Lançamentos'!$B$2:$B$5010,$A12,'Lançamentos'!$C$2:$C$5010,J$4) | K12: =SUM(B12:J12) | L12: =K12/K$51 | M12: =SUMIFS('Lançamentos'!$L$2:$L$5010,'Lançamentos'!$A$2:$A$5010,"Insumos e papel",'Lançamentos'!$B$2:$B$5010,$A12,'Lançamentos'!$C$2:$C$5010,"Antes de 2026")
A13: 2.01.94 Compra de Fita Adesiva | B13: =SUMIFS('Lançamentos'!$L$2:$L$5010,'Lançamentos'!$A$2:$A$5010,"Insumos e papel",'Lançamentos'!$B$2:$B$5010,$A13,'Lançamentos'!$C$2:$C$5010,B$4) | C13: =SUMIFS('Lançamentos'!$L$2:$L$5010,'Lançamentos'!$A$2:$A$5010,"Insumos e papel",'Lançamentos'!$B$2:$B$5010,$A13,'Lançamentos'!$C$2:$C$5010,C$4) | D13: =SUMIFS('Lançamentos'!$L$2:$L$5010,'Lançamentos'!$A$2:$A$5010,"Insumos e papel",'Lançamentos'!$B$2:$B$5010,$A13,'Lançamentos'!$C$2:$C$5010,D$4) | E13: =SUMIFS('Lançamentos'!$L$2:$L$5010,'Lançamentos'!$A$2:$A$5010,"Insumos e papel",'Lançamentos'!$B$2:$B$5010,$A13,'Lançamentos'!$C$2:$C$5010,E$4) | F13: =SUMIFS('Lançamentos'!$L$2:$L$5010,'Lançamentos'!$A$2:$A$5010,"Insumos e papel",'Lançamentos'!$B$2:$B$5010,$A13,'Lançamentos'!$C$2:$C$5010,F$4) | G13: =SUMIFS('Lançamentos'!$L$2:$L$5010,'Lançamentos'!$A$2:$A$5010,"Insumos e papel",'Lançamentos'!$B$2:$B$5010,$A13,'Lançamentos'!$C$2:$C$5010,G$4) | H13: =SUMIFS('Lançamentos'!$L$2:$L$5010,'Lançamentos'!$A$2:$A$5010,"Insumos e papel",'Lançamentos'!$B$2:$B$5010,$A13,'Lançamentos'!$C$2:$C$5010,H$4) | I13: =SUMIFS('Lançamentos'!$L$2:$L$5010,'Lançamentos'!$A$2:$A$5010,"Insumos e papel",'Lançamentos'!$B$2:$B$5010,$A13,'Lançamentos'!$C$2:$C$5010,I$4) | J13: =SUMIFS('Lançamentos'!$L$2:$L$5010,'Lançamentos'!$A$2:$A$5010,"Insumos e papel",'Lançamentos'!$B$2:$B$5010,$A13,'Lançamentos'!$C$2:$C$5010,J$4) | K13: =SUM(B13:J13) | L13: =K13/K$51 | M13: =SUMIFS('Lançamentos'!$L$2:$L$5010,'Lançamentos'!$A$2:$A$5010,"Insumos e papel",'Lançamentos'!$B$2:$B$5010,$A13,'Lançamentos'!$C$2:$C$5010,"Antes de 2026")
A14: 2.01.95 Compra de Etiqueta | B14: =SUMIFS('Lançamentos'!$L$2:$L$5010,'Lançamentos'!$A$2:$A$5010,"Insumos e papel",'Lançamentos'!$B$2:$B$5010,$A14,'Lançamentos'!$C$2:$C$5010,B$4) | C14: =SUMIFS('Lançamentos'!$L$2:$L$5010,'Lançamentos'!$A$2:$A$5010,"Insumos e papel",'Lançamentos'!$B$2:$B$5010,$A14,'Lançamentos'!$C$2:$C$5010,C$4) | D14: =SUMIFS('Lançamentos'!$L$2:$L$5010,'Lançamentos'!$A$2:$A$5010,"Insumos e papel",'Lançamentos'!$B$2:$B$5010,$A14,'Lançamentos'!$C$2:$C$5010,D$4) | E14: =SUMIFS('Lançamentos'!$L$2:$L$5010,'Lançamentos'!$A$2:$A$5010,"Insumos e papel",'Lançamentos'!$B$2:$B$5010,$A14,'Lançamentos'!$C$2:$C$5010,E$4) | F14: =SUMIFS('Lançamentos'!$L$2:$L$5010,'Lançamentos'!$A$2:$A$5010,"Insumos e papel",'Lançamentos'!$B$2:$B$5010,$A14,'Lançamentos'!$C$2:$C$5010,F$4) | G14: =SUMIFS('Lançamentos'!$L$2:$L$5010,'Lançamentos'!$A$2:$A$5010,"Insumos e papel",'Lançamentos'!$B$2:$B$5010,$A14,'Lançamentos'!$C$2:$C$5010,G$4) | H14: =SUMIFS('Lançamentos'!$L$2:$L$5010,'Lançamentos'!$A$2:$A$5010,"Insumos e papel",'Lançamentos'!$B$2:$B$5010,$A14,'Lançamentos'!$C$2:$C$5010,H$4) | I14: =SUMIFS('Lançamentos'!$L$2:$L$5010,'Lançamentos'!$A$2:$A$5010,"Insumos e papel",'Lançamentos'!$B$2:$B$5010,$A14,'Lançamentos'!$C$2:$C$5010,I$4) | J14: =SUMIFS('Lançamentos'!$L$2:$L$5010,'Lançamentos'!$A$2:$A$5010,"Insumos e papel",'Lançamentos'!$B$2:$B$5010,$A14,'Lançamentos'!$C$2:$C$5010,J$4) | K14: =SUM(B14:J14) | L14: =K14/K$51 | M14: =SUMIFS('Lançamentos'!$L$2:$L$5010,'Lançamentos'!$A$2:$A$5010,"Insumos e papel",'Lançamentos'!$B$2:$B$5010,$A14,'Lançamentos'!$C$2:$C$5010,"Antes de 2026")
A15: 2.01.96 Compra de Cola | B15: =SUMIFS('Lançamentos'!$L$2:$L$5010,'Lançamentos'!$A$2:$A$5010,"Insumos e papel",'Lançamentos'!$B$2:$B$5010,$A15,'Lançamentos'!$C$2:$C$5010,B$4) | C15: =SUMIFS('Lançamentos'!$L$2:$L$5010,'Lançamentos'!$A$2:$A$5010,"Insumos e papel",'Lançamentos'!$B$2:$B$5010,$A15,'Lançamentos'!$C$2:$C$5010,C$4) | D15: =SUMIFS('Lançamentos'!$L$2:$L$5010,'Lançamentos'!$A$2:$A$5010,"Insumos e papel",'Lançamentos'!$B$2:$B$5010,$A15,'Lançamentos'!$C$2:$C$5010,D$4) | E15: =SUMIFS('Lançamentos'!$L$2:$L$5010,'Lançamentos'!$A$2:$A$5010,"Insumos e papel",'Lançamentos'!$B$2:$B$5010,$A15,'Lançamentos'!$C$2:$C$5010,E$4) | F15: =SUMIFS('Lançamentos'!$L$2:$L$5010,'Lançamentos'!$A$2:$A$5010,"Insumos e papel",'Lançamentos'!$B$2:$B$5010,$A15,'Lançamentos'!$C$2:$C$5010,F$4) | G15: =SUMIFS('Lançamentos'!$L$2:$L$5010,'Lançamentos'!$A$2:$A$5010,"Insumos e papel",'Lançamentos'!$B$2:$B$5010,$A15,'Lançamentos'!$C$2:$C$5010,G$4) | H15: =SUMIFS('Lançamentos'!$L$2:$L$5010,'Lançamentos'!$A$2:$A$5010,"Insumos e papel",'Lançamentos'!$B$2:$B$5010,$A15,'Lançamentos'!$C$2:$C$5010,H$4) | I15: =SUMIFS('Lançamentos'!$L$2:$L$5010,'Lançamentos'!$A$2:$A$5010,"Insumos e papel",'Lançamentos'!$B$2:$B$5010,$A15,'Lançamentos'!$C$2:$C$5010,I$4) | J15: =SUMIFS('Lançamentos'!$L$2:$L$5010,'Lançamentos'!$A$2:$A$5010,"Insumos e papel",'Lançamentos'!$B$2:$B$5010,$A15,'Lançamentos'!$C$2:$C$5010,J$4) | K15: =SUM(B15:J15) | L15: =K15/K$51 | M15: =SUMIFS('Lançamentos'!$L$2:$L$5010,'Lançamentos'!$A$2:$A$5010,"Insumos e papel",'Lançamentos'!$B$2:$B$5010,$A15,'Lançamentos'!$C$2:$C$5010,"Antes de 2026")
A16: 2.01.97 Compra de Clichê | B16: =SUMIFS('Lançamentos'!$L$2:$L$5010,'Lançamentos'!$A$2:$A$5010,"Insumos e papel",'Lançamentos'!$B$2:$B$5010,$A16,'Lançamentos'!$C$2:$C$5010,B$4) | C16: =SUMIFS('Lançamentos'!$L$2:$L$5010,'Lançamentos'!$A$2:$A$5010,"Insumos e papel",'Lançamentos'!$B$2:$B$5010,$A16,'Lançamentos'!$C$2:$C$5010,C$4) | D16: =SUMIFS('Lançamentos'!$L$2:$L$5010,'Lançamentos'!$A$2:$A$5010,"Insumos e papel",'Lançamentos'!$B$2:$B$5010,$A16,'Lançamentos'!$C$2:$C$5010,D$4) | E16: =SUMIFS('Lançamentos'!$L$2:$L$5010,'Lançamentos'!$A$2:$A$5010,"Insumos e papel",'Lançamentos'!$B$2:$B$5010,$A16,'Lançamentos'!$C$2:$C$5010,E$4) | F16: =SUMIFS('Lançamentos'!$L$2:$L$5010,'Lançamentos'!$A$2:$A$5010,"Insumos e papel",'Lançamentos'!$B$2:$B$5010,$A16,'Lançamentos'!$C$2:$C$5010,F$4) | G16: =SUMIFS('Lançamentos'!$L$2:$L$5010,'Lançamentos'!$A$2:$A$5010,"Insumos e papel",'Lançamentos'!$B$2:$B$5010,$A16,'Lançamentos'!$C$2:$C$5010,G$4) | H16: =SUMIFS('Lançamentos'!$L$2:$L$5010,'Lançamentos'!$A$2:$A$5010,"Insumos e papel",'Lançamentos'!$B$2:$B$5010,$A16,'Lançamentos'!$C$2:$C$5010,H$4) | I16: =SUMIFS('Lançamentos'!$L$2:$L$5010,'Lançamentos'!$A$2:$A$5010,"Insumos e papel",'Lançamentos'!$B$2:$B$5010,$A16,'Lançamentos'!$C$2:$C$5010,I$4) | J16: =SUMIFS('Lançamentos'!$L$2:$L$5010,'Lançamentos'!$A$2:$A$5010,"Insumos e papel",'Lançamentos'!$B$2:$B$5010,$A16,'Lançamentos'!$C$2:$C$5010,J$4) | K16: =SUM(B16:J16) | L16: =K16/K$51 | M16: =SUMIFS('Lançamentos'!$L$2:$L$5010,'Lançamentos'!$A$2:$A$5010,"Insumos e papel",'Lançamentos'!$B$2:$B$5010,$A16,'Lançamentos'!$C$2:$C$5010,"Antes de 2026")
A17: 2.01.99 Compra de Caixas | B17: =SUMIFS('Lançamentos'!$L$2:$L$5010,'Lançamentos'!$A$2:$A$5010,"Insumos e papel",'Lançamentos'!$B$2:$B$5010,$A17,'Lançamentos'!$C$2:$C$5010,B$4) | C17: =SUMIFS('Lançamentos'!$L$2:$L$5010,'Lançamentos'!$A$2:$A$5010,"Insumos e papel",'Lançamentos'!$B$2:$B$5010,$A17,'Lançamentos'!$C$2:$C$5010,C$4) | D17: =SUMIFS('Lançamentos'!$L$2:$L$5010,'Lançamentos'!$A$2:$A$5010,"Insumos e papel",'Lançamentos'!$B$2:$B$5010,$A17,'Lançamentos'!$C$2:$C$5010,D$4) | E17: =SUMIFS('Lançamentos'!$L$2:$L$5010,'Lançamentos'!$A$2:$A$5010,"Insumos e papel",'Lançamentos'!$B$2:$B$5010,$A17,'Lançamentos'!$C$2:$C$5010,E$4) | F17: =SUMIFS('Lançamentos'!$L$2:$L$5010,'Lançamentos'!$A$2:$A$5010,"Insumos e papel",'Lançamentos'!$B$2:$B$5010,$A17,'Lançamentos'!$C$2:$C$5010,F$4) | G17: =SUMIFS('Lançamentos'!$L$2:$L$5010,'Lançamentos'!$A$2:$A$5010,"Insumos e papel",'Lançamentos'!$B$2:$B$5010,$A17,'Lançamentos'!$C$2:$C$5010,G$4) | H17: =SUMIFS('Lançamentos'!$L$2:$L$5010,'Lançamentos'!$A$2:$A$5010,"Insumos e papel",'Lançamentos'!$B$2:$B$5010,$A17,'Lançamentos'!$C$2:$C$5010,H$4) | I17: =SUMIFS('Lançamentos'!$L$2:$L$5010,'Lançamentos'!$A$2:$A$5010,"Insumos e papel",'Lançamentos'!$B$2:$B$5010,$A17,'Lançamentos'!$C$2:$C$5010,I$4) | J17: =SUMIFS('Lançamentos'!$L$2:$L$5010,'Lançamentos'!$A$2:$A$5010,"Insumos e papel",'Lançamentos'!$B$2:$B$5010,$A17,'Lançamentos'!$C$2:$C$5010,J$4) | K17: =SUM(B17:J17) | L17: =K17/K$51 | M17: =SUMIFS('Lançamentos'!$L$2:$L$5010,'Lançamentos'!$A$2:$A$5010,"Insumos e papel",'Lançamentos'!$B$2:$B$5010,$A17,'Lançamentos'!$C$2:$C$5010,"Antes de 2026")
A18: Uso e consumo | B18: =SUM(B19:B26) | C18: =SUM(C19:C26) | D18: =SUM(D19:D26) | E18: =SUM(E19:E26) | F18: =SUM(F19:F26) | G18: =SUM(G19:G26) | H18: =SUM(H19:H26) | I18: =SUM(I19:I26) | ... K18: =SUM(K19:K26) | L18: =K18/K$51 | M18: =SUM(M19:M26)
A19: 2.01.85 Compra de Uso e Consumo | B19: =SUMIFS('Lançamentos'!$L$2:$L$5010,'Lançamentos'!$A$2:$A$5010,"Uso e consumo",'Lançamentos'!$B$2:$B$5010,$A19,'Lançamentos'!$C$2:$C$5010,B$4) | C19: =SUMIFS('Lançamentos'!$L$2:$L$5010,'Lançamentos'!$A$2:$A$5010,"Uso e consumo",'Lançamentos'!$B$2:$B$5010,$A19,'Lançamentos'!$C$2:$C$5010,C$4) | D19: =SUMIFS('Lançamentos'!$L$2:$L$5010,'Lançamentos'!$A$2:$A$5010,"Uso e consumo",'Lançamentos'!$B$2:$B$5010,$A19,'Lançamentos'!$C$2:$C$5010,D$4) | E19: =SUMIFS('Lançamentos'!$L$2:$L$5010,'Lançamentos'!$A$2:$A$5010,"Uso e consumo",'Lançamentos'!$B$2:$B$5010,$A19,'Lançamentos'!$C$2:$C$5010,E$4) | F19: =SUMIFS('Lançamentos'!$L$2:$L$5010,'Lançamentos'!$A$2:$A$5010,"Uso e consumo",'Lançamentos'!$B$2:$B$5010,$A19,'Lançamentos'!$C$2:$C$5010,F$4) | G19: =SUMIFS('Lançamentos'!$L$2:$L$5010,'Lançamentos'!$A$2:$A$5010,"Uso e consumo",'Lançamentos'!$B$2:$B$5010,$A19,'Lançamentos'!$C$2:$C$5010,G$4) | H19: =SUMIFS('Lançamentos'!$L$2:$L$5010,'Lançamentos'!$A$2:$A$5010,"Uso e consumo",'Lançamentos'!$B$2:$B$5010,$A19,'Lançamentos'!$C$2:$C$5010,H$4) | I19: =SUMIFS('Lançamentos'!$L$2:$L$5010,'Lançamentos'!$A$2:$A$5010,"Uso e consumo",'Lançamentos'!$B$2:$B$5010,$A19,'Lançamentos'!$C$2:$C$5010,I$4) | J19: =SUMIFS('Lançamentos'!$L$2:$L$5010,'Lançamentos'!$A$2:$A$5010,"Uso e consumo",'Lançamentos'!$B$2:$B$5010,$A19,'Lançamentos'!$C$2:$C$5010,J$4) | K19: =SUM(B19:J19) | L19: =K19/K$51 | M19: =SUMIFS('Lançamentos'!$L$2:$L$5010,'Lançamentos'!$A$2:$A$5010,"Uso e consumo",'Lançamentos'!$B$2:$B$5010,$A19,'Lançamentos'!$C$2:$C$5010,"Antes de 2026")
A20: 2.01.87 Compra de Peças de Máquinas | B20: =SUMIFS('Lançamentos'!$L$2:$L$5010,'Lançamentos'!$A$2:$A$5010,"Uso e consumo",'Lançamentos'!$B$2:$B$5010,$A20,'Lançamentos'!$C$2:$C$5010,B$4) | C20: =SUMIFS('Lançamentos'!$L$2:$L$5010,'Lançamentos'!$A$2:$A$5010,"Uso e consumo",'Lançamentos'!$B$2:$B$5010,$A20,'Lançamentos'!$C$2:$C$5010,C$4) | D20: =SUMIFS('Lançamentos'!$L$2:$L$5010,'Lançamentos'!$A$2:$A$5010,"Uso e consumo",'Lançamentos'!$B$2:$B$5010,$A20,'Lançamentos'!$C$2:$C$5010,D$4) | E20: =SUMIFS('Lançamentos'!$L$2:$L$5010,'Lançamentos'!$A$2:$A$5010,"Uso e consumo",'Lançamentos'!$B$2:$B$5010,$A20,'Lançamentos'!$C$2:$C$5010,E$4) | F20: =SUMIFS('Lançamentos'!$L$2:$L$5010,'Lançamentos'!$A$2:$A$5010,"Uso e consumo",'Lançamentos'!$B$2:$B$5010,$A20,'Lançamentos'!$C$2:$C$5010,F$4) | G20: =SUMIFS('Lançamentos'!$L$2:$L$5010,'Lançamentos'!$A$2:$A$5010,"Uso e consumo",'Lançamentos'!$B$2:$B$5010,$A20,'Lançamentos'!$C$2:$C$5010,G$4) | H20: =SUMIFS('Lançamentos'!$L$2:$L$5010,'Lançamentos'!$A$2:$A$5010,"Uso e consumo",'Lançamentos'!$B$2:$B$5010,$A20,'Lançamentos'!$C$2:$C$5010,H$4) | I20: =SUMIFS('Lançamentos'!$L$2:$L$5010,'Lançamentos'!$A$2:$A$5010,"Uso e consumo",'Lançamentos'!$B$2:$B$5010,$A20,'Lançamentos'!$C$2:$C$5010,I$4) | J20: =SUMIFS('Lançamentos'!$L$2:$L$5010,'Lançamentos'!$A$2:$A$5010,"Uso e consumo",'Lançamentos'!$B$2:$B$5010,$A20,'Lançamentos'!$C$2:$C$5010,J$4) | K20: =SUM(B20:J20) | L20: =K20/K$51 | M20: =SUMIFS('Lançamentos'!$L$2:$L$5010,'Lançamentos'!$A$2:$A$5010,"Uso e consumo",'Lançamentos'!$B$2:$B$5010,$A20,'Lançamentos'!$C$2:$C$5010,"Antes de 2026")
A21: 2.03.88 Compra de Fardamento | B21: =SUMIFS('Lançamentos'!$L$2:$L$5010,'Lançamentos'!$A$2:$A$5010,"Uso e consumo",'Lançamentos'!$B$2:$B$5010,$A21,'Lançamentos'!$C$2:$C$5010,B$4) | C21: =SUMIFS('Lançamentos'!$L$2:$L$5010,'Lançamentos'!$A$2:$A$5010,"Uso e consumo",'Lançamentos'!$B$2:$B$5010,$A21,'Lançamentos'!$C$2:$C$5010,C$4) | D21: =SUMIFS('Lançamentos'!$L$2:$L$5010,'Lançamentos'!$A$2:$A$5010,"Uso e consumo",'Lançamentos'!$B$2:$B$5010,$A21,'Lançamentos'!$C$2:$C$5010,D$4) | E21: =SUMIFS('Lançamentos'!$L$2:$L$5010,'Lançamentos'!$A$2:$A$5010,"Uso e consumo",'Lançamentos'!$B$2:$B$5010,$A21,'Lançamentos'!$C$2:$C$5010,E$4) | F21: =SUMIFS('Lançamentos'!$L$2:$L$5010,'Lançamentos'!$A$2:$A$5010,"Uso e consumo",'Lançamentos'!$B$2:$B$5010,$A21,'Lançamentos'!$C$2:$C$5010,F$4) | G21: =SUMIFS('Lançamentos'!$L$2:$L$5010,'Lançamentos'!$A$2:$A$5010,"Uso e consumo",'Lançamentos'!$B$2:$B$5010,$A21,'Lançamentos'!$C$2:$C$5010,G$4) | H21: =SUMIFS('Lançamentos'!$L$2:$L$5010,'Lançamentos'!$A$2:$A$5010,"Uso e consumo",'Lançamentos'!$B$2:$B$5010,$A21,'Lançamentos'!$C$2:$C$5010,H$4) | I21: =SUMIFS('Lançamentos'!$L$2:$L$5010,'Lançamentos'!$A$2:$A$5010,"Uso e consumo",'Lançamentos'!$B$2:$B$5010,$A21,'Lançamentos'!$C$2:$C$5010,I$4) | J21: =SUMIFS('Lançamentos'!$L$2:$L$5010,'Lançamentos'!$A$2:$A$5010,"Uso e consumo",'Lançamentos'!$B$2:$B$5010,$A21,'Lançamentos'!$C$2:$C$5010,J$4) | K21: =SUM(B21:J21) | L21: =K21/K$51 | M21: =SUMIFS('Lançamentos'!$L$2:$L$5010,'Lançamentos'!$A$2:$A$5010,"Uso e consumo",'Lançamentos'!$B$2:$B$5010,$A21,'Lançamentos'!$C$2:$C$5010,"Antes de 2026")
A22: 2.03.90 Compra de EPI | B22: =SUMIFS('Lançamentos'!$L$2:$L$5010,'Lançamentos'!$A$2:$A$5010,"Uso e consumo",'Lançamentos'!$B$2:$B$5010,$A22,'Lançamentos'!$C$2:$C$5010,B$4) | C22: =SUMIFS('Lançamentos'!$L$2:$L$5010,'Lançamentos'!$A$2:$A$5010,"Uso e consumo",'Lançamentos'!$B$2:$B$5010,$A22,'Lançamentos'!$C$2:$C$5010,C$4) | D22: =SUMIFS('Lançamentos'!$L$2:$L$5010,'Lançamentos'!$A$2:$A$5010,"Uso e consumo",'Lançamentos'!$B$2:$B$5010,$A22,'Lançamentos'!$C$2:$C$5010,D$4) | E22: =SUMIFS('Lançamentos'!$L$2:$L$5010,'Lançamentos'!$A$2:$A$5010,"Uso e consumo",'Lançamentos'!$B$2:$B$5010,$A22,'Lançamentos'!$C$2:$C$5010,E$4) | F22: =SUMIFS('Lançamentos'!$L$2:$L$5010,'Lançamentos'!$A$2:$A$5010,"Uso e consumo",'Lançamentos'!$B$2:$B$5010,$A22,'Lançamentos'!$C$2:$C$5010,F$4) | G22: =SUMIFS('Lançamentos'!$L$2:$L$5010,'Lançamentos'!$A$2:$A$5010,"Uso e consumo",'Lançamentos'!$B$2:$B$5010,$A22,'Lançamentos'!$C$2:$C$5010,G$4) | H22: =SUMIFS('Lançamentos'!$L$2:$L$5010,'Lançamentos'!$A$2:$A$5010,"Uso e consumo",'Lançamentos'!$B$2:$B$5010,$A22,'Lançamentos'!$C$2:$C$5010,H$4) | I22: =SUMIFS('Lançamentos'!$L$2:$L$5010,'Lançamentos'!$A$2:$A$5010,"Uso e consumo",'Lançamentos'!$B$2:$B$5010,$A22,'Lançamentos'!$C$2:$C$5010,I$4) | J22: =SUMIFS('Lançamentos'!$L$2:$L$5010,'Lançamentos'!$A$2:$A$5010,"Uso e consumo",'Lançamentos'!$B$2:$B$5010,$A22,'Lançamentos'!$C$2:$C$5010,J$4) | K22: =SUM(B22:J22) | L22: =K22/K$51 | M22: =SUMIFS('Lançamentos'!$L$2:$L$5010,'Lançamentos'!$A$2:$A$5010,"Uso e consumo",'Lançamentos'!$B$2:$B$5010,$A22,'Lançamentos'!$C$2:$C$5010,"Antes de 2026")
A23: 2.04.06 Material de Escritório | B23: =SUMIFS('Lançamentos'!$L$2:$L$5010,'Lançamentos'!$A$2:$A$5010,"Uso e consumo",'Lançamentos'!$B$2:$B$5010,$A23,'Lançamentos'!$C$2:$C$5010,B$4) | C23: =SUMIFS('Lançamentos'!$L$2:$L$5010,'Lançamentos'!$A$2:$A$5010,"Uso e consumo",'Lançamentos'!$B$2:$B$5010,$A23,'Lançamentos'!$C$2:$C$5010,C$4) | D23: =SUMIFS('Lançamentos'!$L$2:$L$5010,'Lançamentos'!$A$2:$A$5010,"Uso e consumo",'Lançamentos'!$B$2:$B$5010,$A23,'Lançamentos'!$C$2:$C$5010,D$4) | E23: =SUMIFS('Lançamentos'!$L$2:$L$5010,'Lançamentos'!$A$2:$A$5010,"Uso e consumo",'Lançamentos'!$B$2:$B$5010,$A23,'Lançamentos'!$C$2:$C$5010,E$4) | F23: =SUMIFS('Lançamentos'!$L$2:$L$5010,'Lançamentos'!$A$2:$A$5010,"Uso e consumo",'Lançamentos'!$B$2:$B$5010,$A23,'Lançamentos'!$C$2:$C$5010,F$4) | G23: =SUMIFS('Lançamentos'!$L$2:$L$5010,'Lançamentos'!$A$2:$A$5010,"Uso e consumo",'Lançamentos'!$B$2:$B$5010,$A23,'Lançamentos'!$C$2:$C$5010,G$4) | H23: =SUMIFS('Lançamentos'!$L$2:$L$5010,'Lançamentos'!$A$2:$A$5010,"Uso e consumo",'Lançamentos'!$B$2:$B$5010,$A23,'Lançamentos'!$C$2:$C$5010,H$4) | I23: =SUMIFS('Lançamentos'!$L$2:$L$5010,'Lançamentos'!$A$2:$A$5010,"Uso e consumo",'Lançamentos'!$B$2:$B$5010,$A23,'Lançamentos'!$C$2:$C$5010,I$4) | J23: =SUMIFS('Lançamentos'!$L$2:$L$5010,'Lançamentos'!$A$2:$A$5010,"Uso e consumo",'Lançamentos'!$B$2:$B$5010,$A23,'Lançamentos'!$C$2:$C$5010,J$4) | K23: =SUM(B23:J23) | L23: =K23/K$51 | M23: =SUMIFS('Lançamentos'!$L$2:$L$5010,'Lançamentos'!$A$2:$A$5010,"Uso e consumo",'Lançamentos'!$B$2:$B$5010,$A23,'Lançamentos'!$C$2:$C$5010,"Antes de 2026")
A24: 2.04.91 Compra de Material de Limpeza | B24: =SUMIFS('Lançamentos'!$L$2:$L$5010,'Lançamentos'!$A$2:$A$5010,"Uso e consumo",'Lançamentos'!$B$2:$B$5010,$A24,'Lançamentos'!$C$2:$C$5010,B$4) | C24: =SUMIFS('Lançamentos'!$L$2:$L$5010,'Lançamentos'!$A$2:$A$5010,"Uso e consumo",'Lançamentos'!$B$2:$B$5010,$A24,'Lançamentos'!$C$2:$C$5010,C$4) | D24: =SUMIFS('Lançamentos'!$L$2:$L$5010,'Lançamentos'!$A$2:$A$5010,"Uso e consumo",'Lançamentos'!$B$2:$B$5010,$A24,'Lançamentos'!$C$2:$C$5010,D$4) | E24: =SUMIFS('Lançamentos'!$L$2:$L$5010,'Lançamentos'!$A$2:$A$5010,"Uso e consumo",'Lançamentos'!$B$2:$B$5010,$A24,'Lançamentos'!$C$2:$C$5010,E$4) | F24: =SUMIFS('Lançamentos'!$L$2:$L$5010,'Lançamentos'!$A$2:$A$5010,"Uso e consumo",'Lançamentos'!$B$2:$B$5010,$A24,'Lançamentos'!$C$2:$C$5010,F$4) | G24: =SUMIFS('Lançamentos'!$L$2:$L$5010,'Lançamentos'!$A$2:$A$5010,"Uso e consumo",'Lançamentos'!$B$2:$B$5010,$A24,'Lançamentos'!$C$2:$C$5010,G$4) | H24: =SUMIFS('Lançamentos'!$L$2:$L$5010,'Lançamentos'!$A$2:$A$5010,"Uso e consumo",'Lançamentos'!$B$2:$B$5010,$A24,'Lançamentos'!$C$2:$C$5010,H$4) | I24: =SUMIFS('Lançamentos'!$L$2:$L$5010,'Lançamentos'!$A$2:$A$5010,"Uso e consumo",'Lançamentos'!$B$2:$B$5010,$A24,'Lançamentos'!$C$2:$C$5010,I$4) | J24: =SUMIFS('Lançamentos'!$L$2:$L$5010,'Lançamentos'!$A$2:$A$5010,"Uso e consumo",'Lançamentos'!$B$2:$B$5010,$A24,'Lançamentos'!$C$2:$C$5010,J$4) | K24: =SUM(B24:J24) | L24: =K24/K$51 | M24: =SUMIFS('Lançamentos'!$L$2:$L$5010,'Lançamentos'!$A$2:$A$5010,"Uso e consumo",'Lançamentos'!$B$2:$B$5010,$A24,'Lançamentos'!$C$2:$C$5010,"Antes de 2026")
A25: 2.04.95 Copa e Cozinha | B25: =SUMIFS('Lançamentos'!$L$2:$L$5010,'Lançamentos'!$A$2:$A$5010,"Uso e consumo",'Lançamentos'!$B$2:$B$5010,$A25,'Lançamentos'!$C$2:$C$5010,B$4) | C25: =SUMIFS('Lançamentos'!$L$2:$L$5010,'Lançamentos'!$A$2:$A$5010,"Uso e consumo",'Lançamentos'!$B$2:$B$5010,$A25,'Lançamentos'!$C$2:$C$5010,C$4) | D25: =SUMIFS('Lançamentos'!$L$2:$L$5010,'Lançamentos'!$A$2:$A$5010,"Uso e consumo",'Lançamentos'!$B$2:$B$5010,$A25,'Lançamentos'!$C$2:$C$5010,D$4) | E25: =SUMIFS('Lançamentos'!$L$2:$L$5010,'Lançamentos'!$A$2:$A$5010,"Uso e consumo",'Lançamentos'!$B$2:$B$5010,$A25,'Lançamentos'!$C$2:$C$5010,E$4) | F25: =SUMIFS('Lançamentos'!$L$2:$L$5010,'Lançamentos'!$A$2:$A$5010,"Uso e consumo",'Lançamentos'!$B$2:$B$5010,$A25,'Lançamentos'!$C$2:$C$5010,F$4) | G25: =SUMIFS('Lançamentos'!$L$2:$L$5010,'Lançamentos'!$A$2:$A$5010,"Uso e consumo",'Lançamentos'!$B$2:$B$5010,$A25,'Lançamentos'!$C$2:$C$5010,G$4) | H25: =SUMIFS('Lançamentos'!$L$2:$L$5010,'Lançamentos'!$A$2:$A$5010,"Uso e consumo",'Lançamentos'!$B$2:$B$5010,$A25,'Lançamentos'!$C$2:$C$5010,H$4) | I25: =SUMIFS('Lançamentos'!$L$2:$L$5010,'Lançamentos'!$A$2:$A$5010,"Uso e consumo",'Lançamentos'!$B$2:$B$5010,$A25,'Lançamentos'!$C$2:$C$5010,I$4) | J25: =SUMIFS('Lançamentos'!$L$2:$L$5010,'Lançamentos'!$A$2:$A$5010,"Uso e consumo",'Lançamentos'!$B$2:$B$5010,$A25,'Lançamentos'!$C$2:$C$5010,J$4) | K25: =SUM(B25:J25) | L25: =K25/K$51 | M25: =SUMIFS('Lançamentos'!$L$2:$L$5010,'Lançamentos'!$A$2:$A$5010,"Uso e consumo",'Lançamentos'!$B$2:$B$5010,$A25,'Lançamentos'!$C$2:$C$5010,"Antes de 2026")
A26: 2.04.96 Bens de Pequeno Valor | B26: =SUMIFS('Lançamentos'!$L$2:$L$5010,'Lançamentos'!$A$2:$A$5010,"Uso e consumo",'Lançamentos'!$B$2:$B$5010,$A26,'Lançamentos'!$C$2:$C$5010,B$4) | C26: =SUMIFS('Lançamentos'!$L$2:$L$5010,'Lançamentos'!$A$2:$A$5010,"Uso e consumo",'Lançamentos'!$B$2:$B$5010,$A26,'Lançamentos'!$C$2:$C$5010,C$4) | D26: =SUMIFS('Lançamentos'!$L$2:$L$5010,'Lançamentos'!$A$2:$A$5010,"Uso e consumo",'Lançamentos'!$B$2:$B$5010,$A26,'Lançamentos'!$C$2:$C$5010,D$4) | E26: =SUMIFS('Lançamentos'!$L$2:$L$5010,'Lançamentos'!$A$2:$A$5010,"Uso e consumo",'Lançamentos'!$B$2:$B$5010,$A26,'Lançamentos'!$C$2:$C$5010,E$4) | F26: =SUMIFS('Lançamentos'!$L$2:$L$5010,'Lançamentos'!$A$2:$A$5010,"Uso e consumo",'Lançamentos'!$B$2:$B$5010,$A26,'Lançamentos'!$C$2:$C$5010,F$4) | G26: =SUMIFS('Lançamentos'!$L$2:$L$5010,'Lançamentos'!$A$2:$A$5010,"Uso e consumo",'Lançamentos'!$B$2:$B$5010,$A26,'Lançamentos'!$C$2:$C$5010,G$4) | H26: =SUMIFS('Lançamentos'!$L$2:$L$5010,'Lançamentos'!$A$2:$A$5010,"Uso e consumo",'Lançamentos'!$B$2:$B$5010,$A26,'Lançamentos'!$C$2:$C$5010,H$4) | I26: =SUMIFS('Lançamentos'!$L$2:$L$5010,'Lançamentos'!$A$2:$A$5010,"Uso e consumo",'Lançamentos'!$B$2:$B$5010,$A26,'Lançamentos'!$C$2:$C$5010,I$4) | J26: =SUMIFS('Lançamentos'!$L$2:$L$5010,'Lançamentos'!$A$2:$A$5010,"Uso e consumo",'Lançamentos'!$B$2:$B$5010,$A26,'Lançamentos'!$C$2:$C$5010,J$4) | K26: =SUM(B26:J26) | L26: =K26/K$51 | M26: =SUMIFS('Lançamentos'!$L$2:$L$5010,'Lançamentos'!$A$2:$A$5010,"Uso e consumo",'Lançamentos'!$B$2:$B$5010,$A26,'Lançamentos'!$C$2:$C$5010,"Antes de 2026")
A27: Frete de compra | B27: =SUM(B28:B34) | C27: =SUM(C28:C34) | D27: =SUM(D28:D34) | E27: =SUM(E28:E34) | F27: =SUM(F28:F34) | G27: =SUM(G28:G34) | H27: =SUM(H28:H34) | I27: =SUM(I28:I34) | ... K27: =SUM(K28:K34) | L27: =K27/K$51 | M27: =SUM(M28:M34)
A28: 1.01.01 Venda de Mercadoria Fabricadas | B28: =SUMIFS('Lançamentos'!$L$2:$L$5010,'Lançamentos'!$A$2:$A$5010,"Frete de compra",'Lançamentos'!$B$2:$B$5010,$A28,'Lançamentos'!$C$2:$C$5010,B$4) | C28: =SUMIFS('Lançamentos'!$L$2:$L$5010,'Lançamentos'!$A$2:$A$5010,"Frete de compra",'Lançamentos'!$B$2:$B$5010,$A28,'Lançamentos'!$C$2:$C$5010,C$4) | D28: =SUMIFS('Lançamentos'!$L$2:$L$5010,'Lançamentos'!$A$2:$A$5010,"Frete de compra",'Lançamentos'!$B$2:$B$5010,$A28,'Lançamentos'!$C$2:$C$5010,D$4) | E28: =SUMIFS('Lançamentos'!$L$2:$L$5010,'Lançamentos'!$A$2:$A$5010,"Frete de compra",'Lançamentos'!$B$2:$B$5010,$A28,'Lançamentos'!$C$2:$C$5010,E$4) | F28: =SUMIFS('Lançamentos'!$L$2:$L$5010,'Lançamentos'!$A$2:$A$5010,"Frete de compra",'Lançamentos'!$B$2:$B$5010,$A28,'Lançamentos'!$C$2:$C$5010,F$4) | G28: =SUMIFS('Lançamentos'!$L$2:$L$5010,'Lançamentos'!$A$2:$A$5010,"Frete de compra",'Lançamentos'!$B$2:$B$5010,$A28,'Lançamentos'!$C$2:$C$5010,G$4) | H28: =SUMIFS('Lançamentos'!$L$2:$L$5010,'Lançamentos'!$A$2:$A$5010,"Frete de compra",'Lançamentos'!$B$2:$B$5010,$A28,'Lançamentos'!$C$2:$C$5010,H$4) | I28: =SUMIFS('Lançamentos'!$L$2:$L$5010,'Lançamentos'!$A$2:$A$5010,"Frete de compra",'Lançamentos'!$B$2:$B$5010,$A28,'Lançamentos'!$C$2:$C$5010,I$4) | J28: =SUMIFS('Lançamentos'!$L$2:$L$5010,'Lançamentos'!$A$2:$A$5010,"Frete de compra",'Lançamentos'!$B$2:$B$5010,$A28,'Lançamentos'!$C$2:$C$5010,J$4) | K28: =SUM(B28:J28) | L28: =K28/K$51 | M28: =SUMIFS('Lançamentos'!$L$2:$L$5010,'Lançamentos'!$A$2:$A$5010,"Frete de compra",'Lançamentos'!$B$2:$B$5010,$A28,'Lançamentos'!$C$2:$C$5010,"Antes de 2026")
A29: 2.01.01 Frete Galpão Produto Acabado | B29: =SUMIFS('Lançamentos'!$L$2:$L$5010,'Lançamentos'!$A$2:$A$5010,"Frete de compra",'Lançamentos'!$B$2:$B$5010,$A29,'Lançamentos'!$C$2:$C$5010,B$4) | C29: =SUMIFS('Lançamentos'!$L$2:$L$5010,'Lançamentos'!$A$2:$A$5010,"Frete de compra",'Lançamentos'!$B$2:$B$5010,$A29,'Lançamentos'!$C$2:$C$5010,C$4) | D29: =SUMIFS('Lançamentos'!$L$2:$L$5010,'Lançamentos'!$A$2:$A$5010,"Frete de compra",'Lançamentos'!$B$2:$B$5010,$A29,'Lançamentos'!$C$2:$C$5010,D$4) | E29: =SUMIFS('Lançamentos'!$L$2:$L$5010,'Lançamentos'!$A$2:$A$5010,"Frete de compra",'Lançamentos'!$B$2:$B$5010,$A29,'Lançamentos'!$C$2:$C$5010,E$4) | F29: =SUMIFS('Lançamentos'!$L$2:$L$5010,'Lançamentos'!$A$2:$A$5010,"Frete de compra",'Lançamentos'!$B$2:$B$5010,$A29,'Lançamentos'!$C$2:$C$5010,F$4) | G29: =SUMIFS('Lançamentos'!$L$2:$L$5010,'Lançamentos'!$A$2:$A$5010,"Frete de compra",'Lançamentos'!$B$2:$B$5010,$A29,'Lançamentos'!$C$2:$C$5010,G$4) | H29: =SUMIFS('Lançamentos'!$L$2:$L$5010,'Lançamentos'!$A$2:$A$5010,"Frete de compra",'Lançamentos'!$B$2:$B$5010,$A29,'Lançamentos'!$C$2:$C$5010,H$4) | I29: =SUMIFS('Lançamentos'!$L$2:$L$5010,'Lançamentos'!$A$2:$A$5010,"Frete de compra",'Lançamentos'!$B$2:$B$5010,$A29,'Lançamentos'!$C$2:$C$5010,I$4) | J29: =SUMIFS('Lançamentos'!$L$2:$L$5010,'Lançamentos'!$A$2:$A$5010,"Frete de compra",'Lançamentos'!$B$2:$B$5010,$A29,'Lançamentos'!$C$2:$C$5010,J$4) | K29: =SUM(B29:J29) | L29: =K29/K$51 | M29: =SUMIFS('Lançamentos'!$L$2:$L$5010,'Lançamentos'!$A$2:$A$5010,"Frete de compra",'Lançamentos'!$B$2:$B$5010,$A29,'Lançamentos'!$C$2:$C$5010,"Antes de 2026")
A30: 2.01.02 Frete sobre Vendas | B30: =SUMIFS('Lançamentos'!$L$2:$L$5010,'Lançamentos'!$A$2:$A$5010,"Frete de compra",'Lançamentos'!$B$2:$B$5010,$A30,'Lançamentos'!$C$2:$C$5010,B$4) | C30: =SUMIFS('Lançamentos'!$L$2:$L$5010,'Lançamentos'!$A$2:$A$5010,"Frete de compra",'Lançamentos'!$B$2:$B$5010,$A30,'Lançamentos'!$C$2:$C$5010,C$4) | D30: =SUMIFS('Lançamentos'!$L$2:$L$5010,'Lançamentos'!$A$2:$A$5010,"Frete de compra",'Lançamentos'!$B$2:$B$5010,$A30,'Lançamentos'!$C$2:$C$5010,D$4) | E30: =SUMIFS('Lançamentos'!$L$2:$L$5010,'Lançamentos'!$A$2:$A$5010,"Frete de compra",'Lançamentos'!$B$2:$B$5010,$A30,'Lançamentos'!$C$2:$C$5010,E$4) | F30: =SUMIFS('Lançamentos'!$L$2:$L$5010,'Lançamentos'!$A$2:$A$5010,"Frete de compra",'Lançamentos'!$B$2:$B$5010,$A30,'Lançamentos'!$C$2:$C$5010,F$4) | G30: =SUMIFS('Lançamentos'!$L$2:$L$5010,'Lançamentos'!$A$2:$A$5010,"Frete de compra",'Lançamentos'!$B$2:$B$5010,$A30,'Lançamentos'!$C$2:$C$5010,G$4) | H30: =SUMIFS('Lançamentos'!$L$2:$L$5010,'Lançamentos'!$A$2:$A$5010,"Frete de compra",'Lançamentos'!$B$2:$B$5010,$A30,'Lançamentos'!$C$2:$C$5010,H$4) | I30: =SUMIFS('Lançamentos'!$L$2:$L$5010,'Lançamentos'!$A$2:$A$5010,"Frete de compra",'Lançamentos'!$B$2:$B$5010,$A30,'Lançamentos'!$C$2:$C$5010,I$4) | J30: =SUMIFS('Lançamentos'!$L$2:$L$5010,'Lançamentos'!$A$2:$A$5010,"Frete de compra",'Lançamentos'!$B$2:$B$5010,$A30,'Lançamentos'!$C$2:$C$5010,J$4) | K30: =SUM(B30:J30) | L30: =K30/K$51 | M30: =SUMIFS('Lançamentos'!$L$2:$L$5010,'Lançamentos'!$A$2:$A$5010,"Frete de compra",'Lançamentos'!$B$2:$B$5010,$A30,'Lançamentos'!$C$2:$C$5010,"Antes de 2026")
A31: 2.01.82 Estadia - Cabotagem | B31: =SUMIFS('Lançamentos'!$L$2:$L$5010,'Lançamentos'!$A$2:$A$5010,"Frete de compra",'Lançamentos'!$B$2:$B$5010,$A31,'Lançamentos'!$C$2:$C$5010,B$4) | C31: =SUMIFS('Lançamentos'!$L$2:$L$5010,'Lançamentos'!$A$2:$A$5010,"Frete de compra",'Lançamentos'!$B$2:$B$5010,$A31,'Lançamentos'!$C$2:$C$5010,C$4) | D31: =SUMIFS('Lançamentos'!$L$2:$L$5010,'Lançamentos'!$A$2:$A$5010,"Frete de compra",'Lançamentos'!$B$2:$B$5010,$A31,'Lançamentos'!$C$2:$C$5010,D$4) | E31: =SUMIFS('Lançamentos'!$L$2:$L$5010,'Lançamentos'!$A$2:$A$5010,"Frete de compra",'Lançamentos'!$B$2:$B$5010,$A31,'Lançamentos'!$C$2:$C$5010,E$4) | F31: =SUMIFS('Lançamentos'!$L$2:$L$5010,'Lançamentos'!$A$2:$A$5010,"Frete de compra",'Lançamentos'!$B$2:$B$5010,$A31,'Lançamentos'!$C$2:$C$5010,F$4) | G31: =SUMIFS('Lançamentos'!$L$2:$L$5010,'Lançamentos'!$A$2:$A$5010,"Frete de compra",'Lançamentos'!$B$2:$B$5010,$A31,'Lançamentos'!$C$2:$C$5010,G$4) | H31: =SUMIFS('Lançamentos'!$L$2:$L$5010,'Lançamentos'!$A$2:$A$5010,"Frete de compra",'Lançamentos'!$B$2:$B$5010,$A31,'Lançamentos'!$C$2:$C$5010,H$4) | I31: =SUMIFS('Lançamentos'!$L$2:$L$5010,'Lançamentos'!$A$2:$A$5010,"Frete de compra",'Lançamentos'!$B$2:$B$5010,$A31,'Lançamentos'!$C$2:$C$5010,I$4) | J31: =SUMIFS('Lançamentos'!$L$2:$L$5010,'Lançamentos'!$A$2:$A$5010,"Frete de compra",'Lançamentos'!$B$2:$B$5010,$A31,'Lançamentos'!$C$2:$C$5010,J$4) | K31: =SUM(B31:J31) | L31: =K31/K$51 | M31: =SUMIFS('Lançamentos'!$L$2:$L$5010,'Lançamentos'!$A$2:$A$5010,"Frete de compra",'Lançamentos'!$B$2:$B$5010,$A31,'Lançamentos'!$C$2:$C$5010,"Antes de 2026")
A32: 2.01.98 Frete Descarregamento | B32: =SUMIFS('Lançamentos'!$L$2:$L$5010,'Lançamentos'!$A$2:$A$5010,"Frete de compra",'Lançamentos'!$B$2:$B$5010,$A32,'Lançamentos'!$C$2:$C$5010,B$4) | C32: =SUMIFS('Lançamentos'!$L$2:$L$5010,'Lançamentos'!$A$2:$A$5010,"Frete de compra",'Lançamentos'!$B$2:$B$5010,$A32,'Lançamentos'!$C$2:$C$5010,C$4) | D32: =SUMIFS('Lançamentos'!$L$2:$L$5010,'Lançamentos'!$A$2:$A$5010,"Frete de compra",'Lançamentos'!$B$2:$B$5010,$A32,'Lançamentos'!$C$2:$C$5010,D$4) | E32: =SUMIFS('Lançamentos'!$L$2:$L$5010,'Lançamentos'!$A$2:$A$5010,"Frete de compra",'Lançamentos'!$B$2:$B$5010,$A32,'Lançamentos'!$C$2:$C$5010,E$4) | F32: =SUMIFS('Lançamentos'!$L$2:$L$5010,'Lançamentos'!$A$2:$A$5010,"Frete de compra",'Lançamentos'!$B$2:$B$5010,$A32,'Lançamentos'!$C$2:$C$5010,F$4) | G32: =SUMIFS('Lançamentos'!$L$2:$L$5010,'Lançamentos'!$A$2:$A$5010,"Frete de compra",'Lançamentos'!$B$2:$B$5010,$A32,'Lançamentos'!$C$2:$C$5010,G$4) | H32: =SUMIFS('Lançamentos'!$L$2:$L$5010,'Lançamentos'!$A$2:$A$5010,"Frete de compra",'Lançamentos'!$B$2:$B$5010,$A32,'Lançamentos'!$C$2:$C$5010,H$4) | I32: =SUMIFS('Lançamentos'!$L$2:$L$5010,'Lançamentos'!$A$2:$A$5010,"Frete de compra",'Lançamentos'!$B$2:$B$5010,$A32,'Lançamentos'!$C$2:$C$5010,I$4) | J32: =SUMIFS('Lançamentos'!$L$2:$L$5010,'Lançamentos'!$A$2:$A$5010,"Frete de compra",'Lançamentos'!$B$2:$B$5010,$A32,'Lançamentos'!$C$2:$C$5010,J$4) | K32: =SUM(B32:J32) | L32: =K32/K$51 | M32: =SUMIFS('Lançamentos'!$L$2:$L$5010,'Lançamentos'!$A$2:$A$5010,"Frete de compra",'Lançamentos'!$B$2:$B$5010,$A32,'Lançamentos'!$C$2:$C$5010,"Antes de 2026")
A33: 2.02.93 Frete Amostras/Brindes | B33: =SUMIFS('Lançamentos'!$L$2:$L$5010,'Lançamentos'!$A$2:$A$5010,"Frete de compra",'Lançamentos'!$B$2:$B$5010,$A33,'Lançamentos'!$C$2:$C$5010,B$4) | C33: =SUMIFS('Lançamentos'!$L$2:$L$5010,'Lançamentos'!$A$2:$A$5010,"Frete de compra",'Lançamentos'!$B$2:$B$5010,$A33,'Lançamentos'!$C$2:$C$5010,C$4) | D33: =SUMIFS('Lançamentos'!$L$2:$L$5010,'Lançamentos'!$A$2:$A$5010,"Frete de compra",'Lançamentos'!$B$2:$B$5010,$A33,'Lançamentos'!$C$2:$C$5010,D$4) | E33: =SUMIFS('Lançamentos'!$L$2:$L$5010,'Lançamentos'!$A$2:$A$5010,"Frete de compra",'Lançamentos'!$B$2:$B$5010,$A33,'Lançamentos'!$C$2:$C$5010,E$4) | F33: =SUMIFS('Lançamentos'!$L$2:$L$5010,'Lançamentos'!$A$2:$A$5010,"Frete de compra",'Lançamentos'!$B$2:$B$5010,$A33,'Lançamentos'!$C$2:$C$5010,F$4) | G33: =SUMIFS('Lançamentos'!$L$2:$L$5010,'Lançamentos'!$A$2:$A$5010,"Frete de compra",'Lançamentos'!$B$2:$B$5010,$A33,'Lançamentos'!$C$2:$C$5010,G$4) | H33: =SUMIFS('Lançamentos'!$L$2:$L$5010,'Lançamentos'!$A$2:$A$5010,"Frete de compra",'Lançamentos'!$B$2:$B$5010,$A33,'Lançamentos'!$C$2:$C$5010,H$4) | I33: =SUMIFS('Lançamentos'!$L$2:$L$5010,'Lançamentos'!$A$2:$A$5010,"Frete de compra",'Lançamentos'!$B$2:$B$5010,$A33,'Lançamentos'!$C$2:$C$5010,I$4) | J33: =SUMIFS('Lançamentos'!$L$2:$L$5010,'Lançamentos'!$A$2:$A$5010,"Frete de compra",'Lançamentos'!$B$2:$B$5010,$A33,'Lançamentos'!$C$2:$C$5010,J$4) | K33: =SUM(B33:J33) | L33: =K33/K$51 | M33: =SUMIFS('Lançamentos'!$L$2:$L$5010,'Lançamentos'!$A$2:$A$5010,"Frete de compra",'Lançamentos'!$B$2:$B$5010,$A33,'Lançamentos'!$C$2:$C$5010,"Antes de 2026")
A34: 2.04.87 Frete sobre Compra | B34: =SUMIFS('Lançamentos'!$L$2:$L$5010,'Lançamentos'!$A$2:$A$5010,"Frete de compra",'Lançamentos'!$B$2:$B$5010,$A34,'Lançamentos'!$C$2:$C$5010,B$4) | C34: =SUMIFS('Lançamentos'!$L$2:$L$5010,'Lançamentos'!$A$2:$A$5010,"Frete de compra",'Lançamentos'!$B$2:$B$5010,$A34,'Lançamentos'!$C$2:$C$5010,C$4) | D34: =SUMIFS('Lançamentos'!$L$2:$L$5010,'Lançamentos'!$A$2:$A$5010,"Frete de compra",'Lançamentos'!$B$2:$B$5010,$A34,'Lançamentos'!$C$2:$C$5010,D$4) | E34: =SUMIFS('Lançamentos'!$L$2:$L$5010,'Lançamentos'!$A$2:$A$5010,"Frete de compra",'Lançamentos'!$B$2:$B$5010,$A34,'Lançamentos'!$C$2:$C$5010,E$4) | F34: =SUMIFS('Lançamentos'!$L$2:$L$5010,'Lançamentos'!$A$2:$A$5010,"Frete de compra",'Lançamentos'!$B$2:$B$5010,$A34,'Lançamentos'!$C$2:$C$5010,F$4) | G34: =SUMIFS('Lançamentos'!$L$2:$L$5010,'Lançamentos'!$A$2:$A$5010,"Frete de compra",'Lançamentos'!$B$2:$B$5010,$A34,'Lançamentos'!$C$2:$C$5010,G$4) | H34: =SUMIFS('Lançamentos'!$L$2:$L$5010,'Lançamentos'!$A$2:$A$5010,"Frete de compra",'Lançamentos'!$B$2:$B$5010,$A34,'Lançamentos'!$C$2:$C$5010,H$4) | I34: =SUMIFS('Lançamentos'!$L$2:$L$5010,'Lançamentos'!$A$2:$A$5010,"Frete de compra",'Lançamentos'!$B$2:$B$5010,$A34,'Lançamentos'!$C$2:$C$5010,I$4) | J34: =SUMIFS('Lançamentos'!$L$2:$L$5010,'Lançamentos'!$A$2:$A$5010,"Frete de compra",'Lançamentos'!$B$2:$B$5010,$A34,'Lançamentos'!$C$2:$C$5010,J$4) | K34: =SUM(B34:J34) | L34: =K34/K$51 | M34: =SUMIFS('Lançamentos'!$L$2:$L$5010,'Lançamentos'!$A$2:$A$5010,"Frete de compra",'Lançamentos'!$B$2:$B$5010,$A34,'Lançamentos'!$C$2:$C$5010,"Antes de 2026")
A35: Frete de venda | B35: =SUM(B36:B41) | C35: =SUM(C36:C41) | D35: =SUM(D36:D41) | E35: =SUM(E36:E41) | F35: =SUM(F36:F41) | G35: =SUM(G36:G41) | H35: =SUM(H36:H41) | I35: =SUM(I36:I41) | ... K35: =SUM(K36:K41) | L35: =K35/K$51 | M35: =SUM(M36:M41)
A36: 1.01.01 Venda de Mercadoria Fabricadas | B36: =SUMIFS('Lançamentos'!$L$2:$L$5010,'Lançamentos'!$A$2:$A$5010,"Frete de venda",'Lançamentos'!$B$2:$B$5010,$A36,'Lançamentos'!$C$2:$C$5010,B$4) | C36: =SUMIFS('Lançamentos'!$L$2:$L$5010,'Lançamentos'!$A$2:$A$5010,"Frete de venda",'Lançamentos'!$B$2:$B$5010,$A36,'Lançamentos'!$C$2:$C$5010,C$4) | D36: =SUMIFS('Lançamentos'!$L$2:$L$5010,'Lançamentos'!$A$2:$A$5010,"Frete de venda",'Lançamentos'!$B$2:$B$5010,$A36,'Lançamentos'!$C$2:$C$5010,D$4) | E36: =SUMIFS('Lançamentos'!$L$2:$L$5010,'Lançamentos'!$A$2:$A$5010,"Frete de venda",'Lançamentos'!$B$2:$B$5010,$A36,'Lançamentos'!$C$2:$C$5010,E$4) | F36: =SUMIFS('Lançamentos'!$L$2:$L$5010,'Lançamentos'!$A$2:$A$5010,"Frete de venda",'Lançamentos'!$B$2:$B$5010,$A36,'Lançamentos'!$C$2:$C$5010,F$4) | G36: =SUMIFS('Lançamentos'!$L$2:$L$5010,'Lançamentos'!$A$2:$A$5010,"Frete de venda",'Lançamentos'!$B$2:$B$5010,$A36,'Lançamentos'!$C$2:$C$5010,G$4) | H36: =SUMIFS('Lançamentos'!$L$2:$L$5010,'Lançamentos'!$A$2:$A$5010,"Frete de venda",'Lançamentos'!$B$2:$B$5010,$A36,'Lançamentos'!$C$2:$C$5010,H$4) | I36: =SUMIFS('Lançamentos'!$L$2:$L$5010,'Lançamentos'!$A$2:$A$5010,"Frete de venda",'Lançamentos'!$B$2:$B$5010,$A36,'Lançamentos'!$C$2:$C$5010,I$4) | J36: =SUMIFS('Lançamentos'!$L$2:$L$5010,'Lançamentos'!$A$2:$A$5010,"Frete de venda",'Lançamentos'!$B$2:$B$5010,$A36,'Lançamentos'!$C$2:$C$5010,J$4) | K36: =SUM(B36:J36) | L36: =K36/K$51 | M36: =SUMIFS('Lançamentos'!$L$2:$L$5010,'Lançamentos'!$A$2:$A$5010,"Frete de venda",'Lançamentos'!$B$2:$B$5010,$A36,'Lançamentos'!$C$2:$C$5010,"Antes de 2026")
A37: 2.01.01 Frete Galpão Produto Acabado | B37: =SUMIFS('Lançamentos'!$L$2:$L$5010,'Lançamentos'!$A$2:$A$5010,"Frete de venda",'Lançamentos'!$B$2:$B$5010,$A37,'Lançamentos'!$C$2:$C$5010,B$4) | C37: =SUMIFS('Lançamentos'!$L$2:$L$5010,'Lançamentos'!$A$2:$A$5010,"Frete de venda",'Lançamentos'!$B$2:$B$5010,$A37,'Lançamentos'!$C$2:$C$5010,C$4) | D37: =SUMIFS('Lançamentos'!$L$2:$L$5010,'Lançamentos'!$A$2:$A$5010,"Frete de venda",'Lançamentos'!$B$2:$B$5010,$A37,'Lançamentos'!$C$2:$C$5010,D$4) | E37: =SUMIFS('Lançamentos'!$L$2:$L$5010,'Lançamentos'!$A$2:$A$5010,"Frete de venda",'Lançamentos'!$B$2:$B$5010,$A37,'Lançamentos'!$C$2:$C$5010,E$4) | F37: =SUMIFS('Lançamentos'!$L$2:$L$5010,'Lançamentos'!$A$2:$A$5010,"Frete de venda",'Lançamentos'!$B$2:$B$5010,$A37,'Lançamentos'!$C$2:$C$5010,F$4) | G37: =SUMIFS('Lançamentos'!$L$2:$L$5010,'Lançamentos'!$A$2:$A$5010,"Frete de venda",'Lançamentos'!$B$2:$B$5010,$A37,'Lançamentos'!$C$2:$C$5010,G$4) | H37: =SUMIFS('Lançamentos'!$L$2:$L$5010,'Lançamentos'!$A$2:$A$5010,"Frete de venda",'Lançamentos'!$B$2:$B$5010,$A37,'Lançamentos'!$C$2:$C$5010,H$4) | I37: =SUMIFS('Lançamentos'!$L$2:$L$5010,'Lançamentos'!$A$2:$A$5010,"Frete de venda",'Lançamentos'!$B$2:$B$5010,$A37,'Lançamentos'!$C$2:$C$5010,I$4) | J37: =SUMIFS('Lançamentos'!$L$2:$L$5010,'Lançamentos'!$A$2:$A$5010,"Frete de venda",'Lançamentos'!$B$2:$B$5010,$A37,'Lançamentos'!$C$2:$C$5010,J$4) | K37: =SUM(B37:J37) | L37: =K37/K$51 | M37: =SUMIFS('Lançamentos'!$L$2:$L$5010,'Lançamentos'!$A$2:$A$5010,"Frete de venda",'Lançamentos'!$B$2:$B$5010,$A37,'Lançamentos'!$C$2:$C$5010,"Antes de 2026")
A38: 2.01.02 Frete sobre Vendas | B38: =SUMIFS('Lançamentos'!$L$2:$L$5010,'Lançamentos'!$A$2:$A$5010,"Frete de venda",'Lançamentos'!$B$2:$B$5010,$A38,'Lançamentos'!$C$2:$C$5010,B$4) | C38: =SUMIFS('Lançamentos'!$L$2:$L$5010,'Lançamentos'!$A$2:$A$5010,"Frete de venda",'Lançamentos'!$B$2:$B$5010,$A38,'Lançamentos'!$C$2:$C$5010,C$4) | D38: =SUMIFS('Lançamentos'!$L$2:$L$5010,'Lançamentos'!$A$2:$A$5010,"Frete de venda",'Lançamentos'!$B$2:$B$5010,$A38,'Lançamentos'!$C$2:$C$5010,D$4) | E38: =SUMIFS('Lançamentos'!$L$2:$L$5010,'Lançamentos'!$A$2:$A$5010,"Frete de venda",'Lançamentos'!$B$2:$B$5010,$A38,'Lançamentos'!$C$2:$C$5010,E$4) | F38: =SUMIFS('Lançamentos'!$L$2:$L$5010,'Lançamentos'!$A$2:$A$5010,"Frete de venda",'Lançamentos'!$B$2:$B$5010,$A38,'Lançamentos'!$C$2:$C$5010,F$4) | G38: =SUMIFS('Lançamentos'!$L$2:$L$5010,'Lançamentos'!$A$2:$A$5010,"Frete de venda",'Lançamentos'!$B$2:$B$5010,$A38,'Lançamentos'!$C$2:$C$5010,G$4) | H38: =SUMIFS('Lançamentos'!$L$2:$L$5010,'Lançamentos'!$A$2:$A$5010,"Frete de venda",'Lançamentos'!$B$2:$B$5010,$A38,'Lançamentos'!$C$2:$C$5010,H$4) | I38: =SUMIFS('Lançamentos'!$L$2:$L$5010,'Lançamentos'!$A$2:$A$5010,"Frete de venda",'Lançamentos'!$B$2:$B$5010,$A38,'Lançamentos'!$C$2:$C$5010,I$4) | J38: =SUMIFS('Lançamentos'!$L$2:$L$5010,'Lançamentos'!$A$2:$A$5010,"Frete de venda",'Lançamentos'!$B$2:$B$5010,$A38,'Lançamentos'!$C$2:$C$5010,J$4) | K38: =SUM(B38:J38) | L38: =K38/K$51 | M38: =SUMIFS('Lançamentos'!$L$2:$L$5010,'Lançamentos'!$A$2:$A$5010,"Frete de venda",'Lançamentos'!$B$2:$B$5010,$A38,'Lançamentos'!$C$2:$C$5010,"Antes de 2026")
A39: 2.01.84 Remessa de Mercadoria | B39: =SUMIFS('Lançamentos'!$L$2:$L$5010,'Lançamentos'!$A$2:$A$5010,"Frete de venda",'Lançamentos'!$B$2:$B$5010,$A39,'Lançamentos'!$C$2:$C$5010,B$4) | C39: =SUMIFS('Lançamentos'!$L$2:$L$5010,'Lançamentos'!$A$2:$A$5010,"Frete de venda",'Lançamentos'!$B$2:$B$5010,$A39,'Lançamentos'!$C$2:$C$5010,C$4) | D39: =SUMIFS('Lançamentos'!$L$2:$L$5010,'Lançamentos'!$A$2:$A$5010,"Frete de venda",'Lançamentos'!$B$2:$B$5010,$A39,'Lançamentos'!$C$2:$C$5010,D$4) | E39: =SUMIFS('Lançamentos'!$L$2:$L$5010,'Lançamentos'!$A$2:$A$5010,"Frete de venda",'Lançamentos'!$B$2:$B$5010,$A39,'Lançamentos'!$C$2:$C$5010,E$4) | F39: =SUMIFS('Lançamentos'!$L$2:$L$5010,'Lançamentos'!$A$2:$A$5010,"Frete de venda",'Lançamentos'!$B$2:$B$5010,$A39,'Lançamentos'!$C$2:$C$5010,F$4) | G39: =SUMIFS('Lançamentos'!$L$2:$L$5010,'Lançamentos'!$A$2:$A$5010,"Frete de venda",'Lançamentos'!$B$2:$B$5010,$A39,'Lançamentos'!$C$2:$C$5010,G$4) | H39: =SUMIFS('Lançamentos'!$L$2:$L$5010,'Lançamentos'!$A$2:$A$5010,"Frete de venda",'Lançamentos'!$B$2:$B$5010,$A39,'Lançamentos'!$C$2:$C$5010,H$4) | I39: =SUMIFS('Lançamentos'!$L$2:$L$5010,'Lançamentos'!$A$2:$A$5010,"Frete de venda",'Lançamentos'!$B$2:$B$5010,$A39,'Lançamentos'!$C$2:$C$5010,I$4) | J39: =SUMIFS('Lançamentos'!$L$2:$L$5010,'Lançamentos'!$A$2:$A$5010,"Frete de venda",'Lançamentos'!$B$2:$B$5010,$A39,'Lançamentos'!$C$2:$C$5010,J$4) | K39: =SUM(B39:J39) | L39: =K39/K$51 | M39: =SUMIFS('Lançamentos'!$L$2:$L$5010,'Lançamentos'!$A$2:$A$5010,"Frete de venda",'Lançamentos'!$B$2:$B$5010,$A39,'Lançamentos'!$C$2:$C$5010,"Antes de 2026")
