Workbook

Sheet Por fornecedor
A1: Detalhe por fornecedor / transportadora – custo líquido 2026 (R$)
A2: Ordenado pelo total do destino. Mês = emissão. Coluna % = participação no destino.
A4: Destino | B4: Fornecedor / Transportadora | C4: 46023 | D4: 46054 | E4: 46082 | F4: 46113 | G4: 46143 | H4: 46174 | I4: 46204 | J4: 46235 | K4: 46266 | L4: Total 2026 | M4: % do destino
A5: Insumos e papel | B5: CMPC Iguacu Embalagens Ltda | C5: =SUMIFS(Base!$I$2:$I$4786,Base!$B$2:$B$4786,$A5,Base!$D$2:$D$4786,$B5,Base!$A$2:$A$4786,C$4) | D5: =SUMIFS(Base!$I$2:$I$4786,Base!$B$2:$B$4786,$A5,Base!$D$2:$D$4786,$B5,Base!$A$2:$A$4786,D$4) | E5: =SUMIFS(Base!$I$2:$I$4786,Base!$B$2:$B$4786,$A5,Base!$D$2:$D$4786,$B5,Base!$A$2:$A$4786,E$4) | F5: =SUMIFS(Base!$I$2:$I$4786,Base!$B$2:$B$4786,$A5,Base!$D$2:$D$4786,$B5,Base!$A$2:$A$4786,F$4) | G5: =SUMIFS(Base!$I$2:$I$4786,Base!$B$2:$B$4786,$A5,Base!$D$2:$D$4786,$B5,Base!$A$2:$A$4786,G$4) | H5: =SUMIFS(Base!$I$2:$I$4786,Base!$B$2:$B$4786,$A5,Base!$D$2:$D$4786,$B5,Base!$A$2:$A$4786,H$4) | I5: =SUMIFS(Base!$I$2:$I$4786,Base!$B$2:$B$4786,$A5,Base!$D$2:$D$4786,$B5,Base!$A$2:$A$4786,I$4) | J5: =SUMIFS(Base!$I$2:$I$4786,Base!$B$2:$B$4786,$A5,Base!$D$2:$D$4786,$B5,Base!$A$2:$A$4786,J$4) | K5: =SUMIFS(Base!$I$2:$I$4786,Base!$B$2:$B$4786,$A5,Base!$D$2:$D$4786,$B5,Base!$A$2:$A$4786,K$4) | L5: =SUM(C5:K5) | M5: =IFERROR(L5/L$41,"")
A6: Insumos e papel | B6: NOVA CONPEL COMPANHIA NORDESTINA DE PAPEL LTDA | C6: =SUMIFS(Base!$I$2:$I$4786,Base!$B$2:$B$4786,$A6,Base!$D$2:$D$4786,$B6,Base!$A$2:$A$4786,C$4) | D6: =SUMIFS(Base!$I$2:$I$4786,Base!$B$2:$B$4786,$A6,Base!$D$2:$D$4786,$B6,Base!$A$2:$A$4786,D$4) | E6: =SUMIFS(Base!$I$2:$I$4786,Base!$B$2:$B$4786,$A6,Base!$D$2:$D$4786,$B6,Base!$A$2:$A$4786,E$4) | F6: =SUMIFS(Base!$I$2:$I$4786,Base!$B$2:$B$4786,$A6,Base!$D$2:$D$4786,$B6,Base!$A$2:$A$4786,F$4) | G6: =SUMIFS(Base!$I$2:$I$4786,Base!$B$2:$B$4786,$A6,Base!$D$2:$D$4786,$B6,Base!$A$2:$A$4786,G$4) | H6: =SUMIFS(Base!$I$2:$I$4786,Base!$B$2:$B$4786,$A6,Base!$D$2:$D$4786,$B6,Base!$A$2:$A$4786,H$4) | I6: =SUMIFS(Base!$I$2:$I$4786,Base!$B$2:$B$4786,$A6,Base!$D$2:$D$4786,$B6,Base!$A$2:$A$4786,I$4) | J6: =SUMIFS(Base!$I$2:$I$4786,Base!$B$2:$B$4786,$A6,Base!$D$2:$D$4786,$B6,Base!$A$2:$A$4786,J$4) | K6: =SUMIFS(Base!$I$2:$I$4786,Base!$B$2:$B$4786,$A6,Base!$D$2:$D$4786,$B6,Base!$A$2:$A$4786,K$4) | L6: =SUM(C6:K6) | M6: =IFERROR(L6/L$41,"")
A7: Insumos e papel | B7: COCELPA CIA DE CEL. E PAPEL DO PARANA SA | C7: =SUMIFS(Base!$I$2:$I$4786,Base!$B$2:$B$4786,$A7,Base!$D$2:$D$4786,$B7,Base!$A$2:$A$4786,C$4) | D7: =SUMIFS(Base!$I$2:$I$4786,Base!$B$2:$B$4786,$A7,Base!$D$2:$D$4786,$B7,Base!$A$2:$A$4786,D$4) | E7: =SUMIFS(Base!$I$2:$I$4786,Base!$B$2:$B$4786,$A7,Base!$D$2:$D$4786,$B7,Base!$A$2:$A$4786,E$4) | F7: =SUMIFS(Base!$I$2:$I$4786,Base!$B$2:$B$4786,$A7,Base!$D$2:$D$4786,$B7,Base!$A$2:$A$4786,F$4) | G7: =SUMIFS(Base!$I$2:$I$4786,Base!$B$2:$B$4786,$A7,Base!$D$2:$D$4786,$B7,Base!$A$2:$A$4786,G$4) | H7: =SUMIFS(Base!$I$2:$I$4786,Base!$B$2:$B$4786,$A7,Base!$D$2:$D$4786,$B7,Base!$A$2:$A$4786,H$4) | I7: =SUMIFS(Base!$I$2:$I$4786,Base!$B$2:$B$4786,$A7,Base!$D$2:$D$4786,$B7,Base!$A$2:$A$4786,I$4) | J7: =SUMIFS(Base!$I$2:$I$4786,Base!$B$2:$B$4786,$A7,Base!$D$2:$D$4786,$B7,Base!$A$2:$A$4786,J$4) | K7: =SUMIFS(Base!$I$2:$I$4786,Base!$B$2:$B$4786,$A7,Base!$D$2:$D$4786,$B7,Base!$A$2:$A$4786,K$4) | L7: =SUM(C7:K7) | M7: =IFERROR(L7/L$41,"")
A8: Insumos e papel | B8: COLAMID | C8: =SUMIFS(Base!$I$2:$I$4786,Base!$B$2:$B$4786,$A8,Base!$D$2:$D$4786,$B8,Base!$A$2:$A$4786,C$4) | D8: =SUMIFS(Base!$I$2:$I$4786,Base!$B$2:$B$4786,$A8,Base!$D$2:$D$4786,$B8,Base!$A$2:$A$4786,D$4) | E8: =SUMIFS(Base!$I$2:$I$4786,Base!$B$2:$B$4786,$A8,Base!$D$2:$D$4786,$B8,Base!$A$2:$A$4786,E$4) | F8: =SUMIFS(Base!$I$2:$I$4786,Base!$B$2:$B$4786,$A8,Base!$D$2:$D$4786,$B8,Base!$A$2:$A$4786,F$4) | G8: =SUMIFS(Base!$I$2:$I$4786,Base!$B$2:$B$4786,$A8,Base!$D$2:$D$4786,$B8,Base!$A$2:$A$4786,G$4) | H8: =SUMIFS(Base!$I$2:$I$4786,Base!$B$2:$B$4786,$A8,Base!$D$2:$D$4786,$B8,Base!$A$2:$A$4786,H$4) | I8: =SUMIFS(Base!$I$2:$I$4786,Base!$B$2:$B$4786,$A8,Base!$D$2:$D$4786,$B8,Base!$A$2:$A$4786,I$4) | J8: =SUMIFS(Base!$I$2:$I$4786,Base!$B$2:$B$4786,$A8,Base!$D$2:$D$4786,$B8,Base!$A$2:$A$4786,J$4) | K8: =SUMIFS(Base!$I$2:$I$4786,Base!$B$2:$B$4786,$A8,Base!$D$2:$D$4786,$B8,Base!$A$2:$A$4786,K$4) | L8: =SUM(C8:K8) | M8: =IFERROR(L8/L$41,"")
A9: Insumos e papel | B9: SANTA MARIA CIA DE PAPEL E CELULOSE | C9: =SUMIFS(Base!$I$2:$I$4786,Base!$B$2:$B$4786,$A9,Base!$D$2:$D$4786,$B9,Base!$A$2:$A$4786,C$4) | D9: =SUMIFS(Base!$I$2:$I$4786,Base!$B$2:$B$4786,$A9,Base!$D$2:$D$4786,$B9,Base!$A$2:$A$4786,D$4) | E9: =SUMIFS(Base!$I$2:$I$4786,Base!$B$2:$B$4786,$A9,Base!$D$2:$D$4786,$B9,Base!$A$2:$A$4786,E$4) | F9: =SUMIFS(Base!$I$2:$I$4786,Base!$B$2:$B$4786,$A9,Base!$D$2:$D$4786,$B9,Base!$A$2:$A$4786,F$4) | G9: =SUMIFS(Base!$I$2:$I$4786,Base!$B$2:$B$4786,$A9,Base!$D$2:$D$4786,$B9,Base!$A$2:$A$4786,G$4) | H9: =SUMIFS(Base!$I$2:$I$4786,Base!$B$2:$B$4786,$A9,Base!$D$2:$D$4786,$B9,Base!$A$2:$A$4786,H$4) | I9: =SUMIFS(Base!$I$2:$I$4786,Base!$B$2:$B$4786,$A9,Base!$D$2:$D$4786,$B9,Base!$A$2:$A$4786,I$4) | J9: =SUMIFS(Base!$I$2:$I$4786,Base!$B$2:$B$4786,$A9,Base!$D$2:$D$4786,$B9,Base!$A$2:$A$4786,J$4) | K9: =SUMIFS(Base!$I$2:$I$4786,Base!$B$2:$B$4786,$A9,Base!$D$2:$D$4786,$B9,Base!$A$2:$A$4786,K$4) | L9: =SUM(C9:K9) | M9: =IFERROR(L9/L$41,"")
A10: Insumos e papel | B10: ALSTEK SOLUCOES EM EMBALAGENS LTDA | C10: =SUMIFS(Base!$I$2:$I$4786,Base!$B$2:$B$4786,$A10,Base!$D$2:$D$4786,$B10,Base!$A$2:$A$4786,C$4) | D10: =SUMIFS(Base!$I$2:$I$4786,Base!$B$2:$B$4786,$A10,Base!$D$2:$D$4786,$B10,Base!$A$2:$A$4786,D$4) | E10: =SUMIFS(Base!$I$2:$I$4786,Base!$B$2:$B$4786,$A10,Base!$D$2:$D$4786,$B10,Base!$A$2:$A$4786,E$4) | F10: =SUMIFS(Base!$I$2:$I$4786,Base!$B$2:$B$4786,$A10,Base!$D$2:$D$4786,$B10,Base!$A$2:$A$4786,F$4) | G10: =SUMIFS(Base!$I$2:$I$4786,Base!$B$2:$B$4786,$A10,Base!$D$2:$D$4786,$B10,Base!$A$2:$A$4786,G$4) | H10: =SUMIFS(Base!$I$2:$I$4786,Base!$B$2:$B$4786,$A10,Base!$D$2:$D$4786,$B10,Base!$A$2:$A$4786,H$4) | I10: =SUMIFS(Base!$I$2:$I$4786,Base!$B$2:$B$4786,$A10,Base!$D$2:$D$4786,$B10,Base!$A$2:$A$4786,I$4) | J10: =SUMIFS(Base!$I$2:$I$4786,Base!$B$2:$B$4786,$A10,Base!$D$2:$D$4786,$B10,Base!$A$2:$A$4786,J$4) | K10: =SUMIFS(Base!$I$2:$I$4786,Base!$B$2:$B$4786,$A10,Base!$D$2:$D$4786,$B10,Base!$A$2:$A$4786,K$4) | L10: =SUM(C10:K10) | M10: =IFERROR(L10/L$41,"")
A11: Insumos e papel | B11: REQUIM PRODUTOS QUIMICOS LTDA | C11: =SUMIFS(Base!$I$2:$I$4786,Base!$B$2:$B$4786,$A11,Base!$D$2:$D$4786,$B11,Base!$A$2:$A$4786,C$4) | D11: =SUMIFS(Base!$I$2:$I$4786,Base!$B$2:$B$4786,$A11,Base!$D$2:$D$4786,$B11,Base!$A$2:$A$4786,D$4) | E11: =SUMIFS(Base!$I$2:$I$4786,Base!$B$2:$B$4786,$A11,Base!$D$2:$D$4786,$B11,Base!$A$2:$A$4786,E$4) | F11: =SUMIFS(Base!$I$2:$I$4786,Base!$B$2:$B$4786,$A11,Base!$D$2:$D$4786,$B11,Base!$A$2:$A$4786,F$4) | G11: =SUMIFS(Base!$I$2:$I$4786,Base!$B$2:$B$4786,$A11,Base!$D$2:$D$4786,$B11,Base!$A$2:$A$4786,G$4) | H11: =SUMIFS(Base!$I$2:$I$4786,Base!$B$2:$B$4786,$A11,Base!$D$2:$D$4786,$B11,Base!$A$2:$A$4786,H$4) | I11: =SUMIFS(Base!$I$2:$I$4786,Base!$B$2:$B$4786,$A11,Base!$D$2:$D$4786,$B11,Base!$A$2:$A$4786,I$4) | J11: =SUMIFS(Base!$I$2:$I$4786,Base!$B$2:$B$4786,$A11,Base!$D$2:$D$4786,$B11,Base!$A$2:$A$4786,J$4) | K11: =SUMIFS(Base!$I$2:$I$4786,Base!$B$2:$B$4786,$A11,Base!$D$2:$D$4786,$B11,Base!$A$2:$A$4786,K$4) | L11: =SUM(C11:K11) | M11: =IFERROR(L11/L$41,"")
A12: Insumos e papel | B12: IRANI PAPEL E EMBALAGEM S.A. | C12: =SUMIFS(Base!$I$2:$I$4786,Base!$B$2:$B$4786,$A12,Base!$D$2:$D$4786,$B12,Base!$A$2:$A$4786,C$4) | D12: =SUMIFS(Base!$I$2:$I$4786,Base!$B$2:$B$4786,$A12,Base!$D$2:$D$4786,$B12,Base!$A$2:$A$4786,D$4) | E12: =SUMIFS(Base!$I$2:$I$4786,Base!$B$2:$B$4786,$A12,Base!$D$2:$D$4786,$B12,Base!$A$2:$A$4786,E$4) | F12: =SUMIFS(Base!$I$2:$I$4786,Base!$B$2:$B$4786,$A12,Base!$D$2:$D$4786,$B12,Base!$A$2:$A$4786,F$4) | G12: =SUMIFS(Base!$I$2:$I$4786,Base!$B$2:$B$4786,$A12,Base!$D$2:$D$4786,$B12,Base!$A$2:$A$4786,G$4) | H12: =SUMIFS(Base!$I$2:$I$4786,Base!$B$2:$B$4786,$A12,Base!$D$2:$D$4786,$B12,Base!$A$2:$A$4786,H$4) | I12: =SUMIFS(Base!$I$2:$I$4786,Base!$B$2:$B$4786,$A12,Base!$D$2:$D$4786,$B12,Base!$A$2:$A$4786,I$4) | J12: =SUMIFS(Base!$I$2:$I$4786,Base!$B$2:$B$4786,$A12,Base!$D$2:$D$4786,$B12,Base!$A$2:$A$4786,J$4) | K12: =SUMIFS(Base!$I$2:$I$4786,Base!$B$2:$B$4786,$A12,Base!$D$2:$D$4786,$B12,Base!$A$2:$A$4786,K$4) | L12: =SUM(C12:K12) | M12: =IFERROR(L12/L$41,"")
A13: Insumos e papel | B13: FITTYCOR - INDUSTRIA E COMERCIO DE TINTAS ESPECIAIS LTDA | C13: =SUMIFS(Base!$I$2:$I$4786,Base!$B$2:$B$4786,$A13,Base!$D$2:$D$4786,$B13,Base!$A$2:$A$4786,C$4) | D13: =SUMIFS(Base!$I$2:$I$4786,Base!$B$2:$B$4786,$A13,Base!$D$2:$D$4786,$B13,Base!$A$2:$A$4786,D$4) | E13: =SUMIFS(Base!$I$2:$I$4786,Base!$B$2:$B$4786,$A13,Base!$D$2:$D$4786,$B13,Base!$A$2:$A$4786,E$4) | F13: =SUMIFS(Base!$I$2:$I$4786,Base!$B$2:$B$4786,$A13,Base!$D$2:$D$4786,$B13,Base!$A$2:$A$4786,F$4) | G13: =SUMIFS(Base!$I$2:$I$4786,Base!$B$2:$B$4786,$A13,Base!$D$2:$D$4786,$B13,Base!$A$2:$A$4786,G$4) | H13: =SUMIFS(Base!$I$2:$I$4786,Base!$B$2:$B$4786,$A13,Base!$D$2:$D$4786,$B13,Base!$A$2:$A$4786,H$4) | I13: =SUMIFS(Base!$I$2:$I$4786,Base!$B$2:$B$4786,$A13,Base!$D$2:$D$4786,$B13,Base!$A$2:$A$4786,I$4) | J13: =SUMIFS(Base!$I$2:$I$4786,Base!$B$2:$B$4786,$A13,Base!$D$2:$D$4786,$B13,Base!$A$2:$A$4786,J$4) | K13: =SUMIFS(Base!$I$2:$I$4786,Base!$B$2:$B$4786,$A13,Base!$D$2:$D$4786,$B13,Base!$A$2:$A$4786,K$4) | L13: =SUM(C13:K13) | M13: =IFERROR(L13/L$41,"")
A14: Insumos e papel | B14: BR EMBALAGENS INDUSTRIA E COMERCIO LTDA | C14: =SUMIFS(Base!$I$2:$I$4786,Base!$B$2:$B$4786,$A14,Base!$D$2:$D$4786,$B14,Base!$A$2:$A$4786,C$4) | D14: =SUMIFS(Base!$I$2:$I$4786,Base!$B$2:$B$4786,$A14,Base!$D$2:$D$4786,$B14,Base!$A$2:$A$4786,D$4) | E14: =SUMIFS(Base!$I$2:$I$4786,Base!$B$2:$B$4786,$A14,Base!$D$2:$D$4786,$B14,Base!$A$2:$A$4786,E$4) | F14: =SUMIFS(Base!$I$2:$I$4786,Base!$B$2:$B$4786,$A14,Base!$D$2:$D$4786,$B14,Base!$A$2:$A$4786,F$4) | G14: =SUMIFS(Base!$I$2:$I$4786,Base!$B$2:$B$4786,$A14,Base!$D$2:$D$4786,$B14,Base!$A$2:$A$4786,G$4) | H14: =SUMIFS(Base!$I$2:$I$4786,Base!$B$2:$B$4786,$A14,Base!$D$2:$D$4786,$B14,Base!$A$2:$A$4786,H$4) | I14: =SUMIFS(Base!$I$2:$I$4786,Base!$B$2:$B$4786,$A14,Base!$D$2:$D$4786,$B14,Base!$A$2:$A$4786,I$4) | J14: =SUMIFS(Base!$I$2:$I$4786,Base!$B$2:$B$4786,$A14,Base!$D$2:$D$4786,$B14,Base!$A$2:$A$4786,J$4) | K14: =SUMIFS(Base!$I$2:$I$4786,Base!$B$2:$B$4786,$A14,Base!$D$2:$D$4786,$B14,Base!$A$2:$A$4786,K$4) | L14: =SUM(C14:K14) | M14: =IFERROR(L14/L$41,"")
A15: Insumos e papel | B15: GDM INDUSTRIA E COMERCIO DE PLASTICOS LTDA. | C15: =SUMIFS(Base!$I$2:$I$4786,Base!$B$2:$B$4786,$A15,Base!$D$2:$D$4786,$B15,Base!$A$2:$A$4786,C$4) | D15: =SUMIFS(Base!$I$2:$I$4786,Base!$B$2:$B$4786,$A15,Base!$D$2:$D$4786,$B15,Base!$A$2:$A$4786,D$4) | E15: =SUMIFS(Base!$I$2:$I$4786,Base!$B$2:$B$4786,$A15,Base!$D$2:$D$4786,$B15,Base!$A$2:$A$4786,E$4) | F15: =SUMIFS(Base!$I$2:$I$4786,Base!$B$2:$B$4786,$A15,Base!$D$2:$D$4786,$B15,Base!$A$2:$A$4786,F$4) | G15: =SUMIFS(Base!$I$2:$I$4786,Base!$B$2:$B$4786,$A15,Base!$D$2:$D$4786,$B15,Base!$A$2:$A$4786,G$4) | H15: =SUMIFS(Base!$I$2:$I$4786,Base!$B$2:$B$4786,$A15,Base!$D$2:$D$4786,$B15,Base!$A$2:$A$4786,H$4) | I15: =SUMIFS(Base!$I$2:$I$4786,Base!$B$2:$B$4786,$A15,Base!$D$2:$D$4786,$B15,Base!$A$2:$A$4786,I$4) | J15: =SUMIFS(Base!$I$2:$I$4786,Base!$B$2:$B$4786,$A15,Base!$D$2:$D$4786,$B15,Base!$A$2:$A$4786,J$4) | K15: =SUMIFS(Base!$I$2:$I$4786,Base!$B$2:$B$4786,$A15,Base!$D$2:$D$4786,$B15,Base!$A$2:$A$4786,K$4) | L15: =SUM(C15:K15) | M15: =IFERROR(L15/L$41,"")
A16: Insumos e papel | B16: FLEXOPEL LTDA | C16: =SUMIFS(Base!$I$2:$I$4786,Base!$B$2:$B$4786,$A16,Base!$D$2:$D$4786,$B16,Base!$A$2:$A$4786,C$4) | D16: =SUMIFS(Base!$I$2:$I$4786,Base!$B$2:$B$4786,$A16,Base!$D$2:$D$4786,$B16,Base!$A$2:$A$4786,D$4) | E16: =SUMIFS(Base!$I$2:$I$4786,Base!$B$2:$B$4786,$A16,Base!$D$2:$D$4786,$B16,Base!$A$2:$A$4786,E$4) | F16: =SUMIFS(Base!$I$2:$I$4786,Base!$B$2:$B$4786,$A16,Base!$D$2:$D$4786,$B16,Base!$A$2:$A$4786,F$4) | G16: =SUMIFS(Base!$I$2:$I$4786,Base!$B$2:$B$4786,$A16,Base!$D$2:$D$4786,$B16,Base!$A$2:$A$4786,G$4) | H16: =SUMIFS(Base!$I$2:$I$4786,Base!$B$2:$B$4786,$A16,Base!$D$2:$D$4786,$B16,Base!$A$2:$A$4786,H$4) | I16: =SUMIFS(Base!$I$2:$I$4786,Base!$B$2:$B$4786,$A16,Base!$D$2:$D$4786,$B16,Base!$A$2:$A$4786,I$4) | J16: =SUMIFS(Base!$I$2:$I$4786,Base!$B$2:$B$4786,$A16,Base!$D$2:$D$4786,$B16,Base!$A$2:$A$4786,J$4) | K16: =SUMIFS(Base!$I$2:$I$4786,Base!$B$2:$B$4786,$A16,Base!$D$2:$D$4786,$B16,Base!$A$2:$A$4786,K$4) | L16: =SUM(C16:K16) | M16: =IFERROR(L16/L$41,"")
... A40: Insumos e papel | B40: INFORPOINT SERVICOS E COMERCIO EM TECNOLOGIA LTDA | C40: =SUMIFS(Base!$I$2:$I$4786,Base!$B$2:$B$4786,$A40,Base!$D$2:$D$4786,$B40,Base!$A$2:$A$4786,C$4) | D40: =SUMIFS(Base!$I$2:$I$4786,Base!$B$2:$B$4786,$A40,Base!$D$2:$D$4786,$B40,Base!$A$2:$A$4786,D$4) | E40: =SUMIFS(Base!$I$2:$I$4786,Base!$B$2:$B$4786,$A40,Base!$D$2:$D$4786,$B40,Base!$A$2:$A$4786,E$4) | F40: =SUMIFS(Base!$I$2:$I$4786,Base!$B$2:$B$4786,$A40,Base!$D$2:$D$4786,$B40,Base!$A$2:$A$4786,F$4) | G40: =SUMIFS(Base!$I$2:$I$4786,Base!$B$2:$B$4786,$A40,Base!$D$2:$D$4786,$B40,Base!$A$2:$A$4786,G$4) | H40: =SUMIFS(Base!$I$2:$I$4786,Base!$B$2:$B$4786,$A40,Base!$D$2:$D$4786,$B40,Base!$A$2:$A$4786,H$4) | I40: =SUMIFS(Base!$I$2:$I$4786,Base!$B$2:$B$4786,$A40,Base!$D$2:$D$4786,$B40,Base!$A$2:$A$4786,I$4) | J40: =SUMIFS(Base!$I$2:$I$4786,Base!$B$2:$B$4786,$A40,Base!$D$2:$D$4786,$B40,Base!$A$2:$A$4786,J$4) | K40: =SUMIFS(Base!$I$2:$I$4786,Base!$B$2:$B$4786,$A40,Base!$D$2:$D$4786,$B40,Base!$A$2:$A$4786,K$4) | L40: =SUM(C40:K40) | M40: =IFERROR(L40/L$41,"")
A41: Insumos e papel | B41: TOTAL Insumos e papel | C41: =SUM(C5:C40) | D41: =SUM(D5:D40) | E41: =SUM(E5:E40) | F41: =SUM(F5:F40) | G41: =SUM(G5:G40) | H41: =SUM(H5:H40) | I41: =SUM(I5:I40) | J41: =SUM(J5:J40) | ... L41: =SUM(L5:L40)
A43: Uso e consumo | B43: FURNAX COMERCIAL E IMPORTADORA EIRELI | C43: =SUMIFS(Base!$I$2:$I$4786,Base!$B$2:$B$4786,$A43,Base!$D$2:$D$4786,$B43,Base!$A$2:$A$4786,C$4) | D43: =SUMIFS(Base!$I$2:$I$4786,Base!$B$2:$B$4786,$A43,Base!$D$2:$D$4786,$B43,Base!$A$2:$A$4786,D$4) | E43: =SUMIFS(Base!$I$2:$I$4786,Base!$B$2:$B$4786,$A43,Base!$D$2:$D$4786,$B43,Base!$A$2:$A$4786,E$4) | F43: =SUMIFS(Base!$I$2:$I$4786,Base!$B$2:$B$4786,$A43,Base!$D$2:$D$4786,$B43,Base!$A$2:$A$4786,F$4) | G43: =SUMIFS(Base!$I$2:$I$4786,Base!$B$2:$B$4786,$A43,Base!$D$2:$D$4786,$B43,Base!$A$2:$A$4786,G$4) | H43: =SUMIFS(Base!$I$2:$I$4786,Base!$B$2:$B$4786,$A43,Base!$D$2:$D$4786,$B43,Base!$A$2:$A$4786,H$4) | I43: =SUMIFS(Base!$I$2:$I$4786,Base!$B$2:$B$4786,$A43,Base!$D$2:$D$4786,$B43,Base!$A$2:$A$4786,I$4) | J43: =SUMIFS(Base!$I$2:$I$4786,Base!$B$2:$B$4786,$A43,Base!$D$2:$D$4786,$B43,Base!$A$2:$A$4786,J$4) | K43: =SUMIFS(Base!$I$2:$I$4786,Base!$B$2:$B$4786,$A43,Base!$D$2:$D$4786,$B43,Base!$A$2:$A$4786,K$4) | L43: =SUM(C43:K43) | M43: =IFERROR(L43/L$123,"")
A44: Uso e consumo | B44: Limptech Paper Comercio Ltda | C44: =SUMIFS(Base!$I$2:$I$4786,Base!$B$2:$B$4786,$A44,Base!$D$2:$D$4786,$B44,Base!$A$2:$A$4786,C$4) | D44: =SUMIFS(Base!$I$2:$I$4786,Base!$B$2:$B$4786,$A44,Base!$D$2:$D$4786,$B44,Base!$A$2:$A$4786,D$4) | E44: =SUMIFS(Base!$I$2:$I$4786,Base!$B$2:$B$4786,$A44,Base!$D$2:$D$4786,$B44,Base!$A$2:$A$4786,E$4) | F44: =SUMIFS(Base!$I$2:$I$4786,Base!$B$2:$B$4786,$A44,Base!$D$2:$D$4786,$B44,Base!$A$2:$A$4786,F$4) | G44: =SUMIFS(Base!$I$2:$I$4786,Base!$B$2:$B$4786,$A44,Base!$D$2:$D$4786,$B44,Base!$A$2:$A$4786,G$4) | H44: =SUMIFS(Base!$I$2:$I$4786,Base!$B$2:$B$4786,$A44,Base!$D$2:$D$4786,$B44,Base!$A$2:$A$4786,H$4) | I44: =SUMIFS(Base!$I$2:$I$4786,Base!$B$2:$B$4786,$A44,Base!$D$2:$D$4786,$B44,Base!$A$2:$A$4786,I$4) | J44: =SUMIFS(Base!$I$2:$I$4786,Base!$B$2:$B$4786,$A44,Base!$D$2:$D$4786,$B44,Base!$A$2:$A$4786,J$4) | K44: =SUMIFS(Base!$I$2:$I$4786,Base!$B$2:$B$4786,$A44,Base!$D$2:$D$4786,$B44,Base!$A$2:$A$4786,K$4) | L44: =SUM(C44:K44) | M44: =IFERROR(L44/L$123,"")
A45: Uso e consumo | B45: R M FARDAMENTOS LTDA | C45: =SUMIFS(Base!$I$2:$I$4786,Base!$B$2:$B$4786,$A45,Base!$D$2:$D$4786,$B45,Base!$A$2:$A$4786,C$4) | D45: =SUMIFS(Base!$I$2:$I$4786,Base!$B$2:$B$4786,$A45,Base!$D$2:$D$4786,$B45,Base!$A$2:$A$4786,D$4) | E45: =SUMIFS(Base!$I$2:$I$4786,Base!$B$2:$B$4786,$A45,Base!$D$2:$D$4786,$B45,Base!$A$2:$A$4786,E$4) | F45: =SUMIFS(Base!$I$2:$I$4786,Base!$B$2:$B$4786,$A45,Base!$D$2:$D$4786,$B45,Base!$A$2:$A$4786,F$4) | G45: =SUMIFS(Base!$I$2:$I$4786,Base!$B$2:$B$4786,$A45,Base!$D$2:$D$4786,$B45,Base!$A$2:$A$4786,G$4) | H45: =SUMIFS(Base!$I$2:$I$4786,Base!$B$2:$B$4786,$A45,Base!$D$2:$D$4786,$B45,Base!$A$2:$A$4786,H$4) | I45: =SUMIFS(Base!$I$2:$I$4786,Base!$B$2:$B$4786,$A45,Base!$D$2:$D$4786,$B45,Base!$A$2:$A$4786,I$4) | J45: =SUMIFS(Base!$I$2:$I$4786,Base!$B$2:$B$4786,$A45,Base!$D$2:$D$4786,$B45,Base!$A$2:$A$4786,J$4) | K45: =SUMIFS(Base!$I$2:$I$4786,Base!$B$2:$B$4786,$A45,Base!$D$2:$D$4786,$B45,Base!$A$2:$A$4786,K$4) | L45: =SUM(C45:K45) | M45: =IFERROR(L45/L$123,"")
A46: Uso e consumo | B46: PERNAMBUCO DISTRIBUIDORA ATAC EPIS, INS IND e MRO LTDA | C46: =SUMIFS(Base!$I$2:$I$4786,Base!$B$2:$B$4786,$A46,Base!$D$2:$D$4786,$B46,Base!$A$2:$A$4786,C$4) | D46: =SUMIFS(Base!$I$2:$I$4786,Base!$B$2:$B$4786,$A46,Base!$D$2:$D$4786,$B46,Base!$A$2:$A$4786,D$4) | E46: =SUMIFS(Base!$I$2:$I$4786,Base!$B$2:$B$4786,$A46,Base!$D$2:$D$4786,$B46,Base!$A$2:$A$4786,E$4) | F46: =SUMIFS(Base!$I$2:$I$4786,Base!$B$2:$B$4786,$A46,Base!$D$2:$D$4786,$B46,Base!$A$2:$A$4786,F$4) | G46: =SUMIFS(Base!$I$2:$I$4786,Base!$B$2:$B$4786,$A46,Base!$D$2:$D$4786,$B46,Base!$A$2:$A$4786,G$4) | H46: =SUMIFS(Base!$I$2:$I$4786,Base!$B$2:$B$4786,$A46,Base!$D$2:$D$4786,$B46,Base!$A$2:$A$4786,H$4) | I46: =SUMIFS(Base!$I$2:$I$4786,Base!$B$2:$B$4786,$A46,Base!$D$2:$D$4786,$B46,Base!$A$2:$A$4786,I$4) | J46: =SUMIFS(Base!$I$2:$I$4786,Base!$B$2:$B$4786,$A46,Base!$D$2:$D$4786,$B46,Base!$A$2:$A$4786,J$4) | K46: =SUMIFS(Base!$I$2:$I$4786,Base!$B$2:$B$4786,$A46,Base!$D$2:$D$4786,$B46,Base!$A$2:$A$4786,K$4) | L46: =SUM(C46:K46) | M46: =IFERROR(L46/L$123,"")
A47: Uso e consumo | B47: ELETROPOLO ELETRICIDADE LTDA | C47: =SUMIFS(Base!$I$2:$I$4786,Base!$B$2:$B$4786,$A47,Base!$D$2:$D$4786,$B47,Base!$A$2:$A$4786,C$4) | D47: =SUMIFS(Base!$I$2:$I$4786,Base!$B$2:$B$4786,$A47,Base!$D$2:$D$4786,$B47,Base!$A$2:$A$4786,D$4) | E47: =SUMIFS(Base!$I$2:$I$4786,Base!$B$2:$B$4786,$A47,Base!$D$2:$D$4786,$B47,Base!$A$2:$A$4786,E$4) | F47: =SUMIFS(Base!$I$2:$I$4786,Base!$B$2:$B$4786,$A47,Base!$D$2:$D$4786,$B47,Base!$A$2:$A$4786,F$4) | G47: =SUMIFS(Base!$I$2:$I$4786,Base!$B$2:$B$4786,$A47,Base!$D$2:$D$4786,$B47,Base!$A$2:$A$4786,G$4) | H47: =SUMIFS(Base!$I$2:$I$4786,Base!$B$2:$B$4786,$A47,Base!$D$2:$D$4786,$B47,Base!$A$2:$A$4786,H$4) | I47: =SUMIFS(Base!$I$2:$I$4786,Base!$B$2:$B$4786,$A47,Base!$D$2:$D$4786,$B47,Base!$A$2:$A$4786,I$4) | J47: =SUMIFS(Base!$I$2:$I$4786,Base!$B$2:$B$4786,$A47,Base!$D$2:$D$4786,$B47,Base!$A$2:$A$4786,J$4) | K47: =SUMIFS(Base!$I$2:$I$4786,Base!$B$2:$B$4786,$A47,Base!$D$2:$D$4786,$B47,Base!$A$2:$A$4786,K$4) | L47: =SUM(C47:K47) | M47: =IFERROR(L47/L$123,"")
A48: Uso e consumo | B48: FERGE COMERCIO DE PRODUTOS INDUSTRIAIS LTDA | C48: =SUMIFS(Base!$I$2:$I$4786,Base!$B$2:$B$4786,$A48,Base!$D$2:$D$4786,$B48,Base!$A$2:$A$4786,C$4) | D48: =SUMIFS(Base!$I$2:$I$4786,Base!$B$2:$B$4786,$A48,Base!$D$2:$D$4786,$B48,Base!$A$2:$A$4786,D$4) | E48: =SUMIFS(Base!$I$2:$I$4786,Base!$B$2:$B$4786,$A48,Base!$D$2:$D$4786,$B48,Base!$A$2:$A$4786,E$4) | F48: =SUMIFS(Base!$I$2:$I$4786,Base!$B$2:$B$4786,$A48,Base!$D$2:$D$4786,$B48,Base!$A$2:$A$4786,F$4) | G48: =SUMIFS(Base!$I$2:$I$4786,Base!$B$2:$B$4786,$A48,Base!$D$2:$D$4786,$B48,Base!$A$2:$A$4786,G$4) | H48: =SUMIFS(Base!$I$2:$I$4786,Base!$B$2:$B$4786,$A48,Base!$D$2:$D$4786,$B48,Base!$A$2:$A$4786,H$4) | I48: =SUMIFS(Base!$I$2:$I$4786,Base!$B$2:$B$4786,$A48,Base!$D$2:$D$4786,$B48,Base!$A$2:$A$4786,I$4) | J48: =SUMIFS(Base!$I$2:$I$4786,Base!$B$2:$B$4786,$A48,Base!$D$2:$D$4786,$B48,Base!$A$2:$A$4786,J$4) | K48: =SUMIFS(Base!$I$2:$I$4786,Base!$B$2:$B$4786,$A48,Base!$D$2:$D$4786,$B48,Base!$A$2:$A$4786,K$4) | L48: =SUM(C48:K48) | M48: =IFERROR(L48/L$123,"")
A49: Uso e consumo | B49: GF COMERCIO DE PRODUTOS INDUSTRIAIS LTDA | C49: =SUMIFS(Base!$I$2:$I$4786,Base!$B$2:$B$4786,$A49,Base!$D$2:$D$4786,$B49,Base!$A$2:$A$4786,C$4) | D49: =SUMIFS(Base!$I$2:$I$4786,Base!$B$2:$B$4786,$A49,Base!$D$2:$D$4786,$B49,Base!$A$2:$A$4786,D$4) | E49: =SUMIFS(Base!$I$2:$I$4786,Base!$B$2:$B$4786,$A49,Base!$D$2:$D$4786,$B49,Base!$A$2:$A$4786,E$4) | F49: =SUMIFS(Base!$I$2:$I$4786,Base!$B$2:$B$4786,$A49,Base!$D$2:$D$4786,$B49,Base!$A$2:$A$4786,F$4) | G49: =SUMIFS(Base!$I$2:$I$4786,Base!$B$2:$B$4786,$A49,Base!$D$2:$D$4786,$B49,Base!$A$2:$A$4786,G$4) | H49: =SUMIFS(Base!$I$2:$I$4786,Base!$B$2:$B$4786,$A49,Base!$D$2:$D$4786,$B49,Base!$A$2:$A$4786,H$4) | I49: =SUMIFS(Base!$I$2:$I$4786,Base!$B$2:$B$4786,$A49,Base!$D$2:$D$4786,$B49,Base!$A$2:$A$4786,I$4) | J49: =SUMIFS(Base!$I$2:$I$4786,Base!$B$2:$B$4786,$A49,Base!$D$2:$D$4786,$B49,Base!$A$2:$A$4786,J$4) | K49: =SUMIFS(Base!$I$2:$I$4786,Base!$B$2:$B$4786,$A49,Base!$D$2:$D$4786,$B49,Base!$A$2:$A$4786,K$4) | L49: =SUM(C49:K49) | M49: =IFERROR(L49/L$123,"")
A50: Uso e consumo | B50: ATACADAO ECONOMICO - COMERCIO DE MATERIAL DE CONSTRUCAO LTDA | C50: =SUMIFS(Base!$I$2:$I$4786,Base!$B$2:$B$4786,$A50,Base!$D$2:$D$4786,$B50,Base!$A$2:$A$4786,C$4) | D50: =SUMIFS(Base!$I$2:$I$4786,Base!$B$2:$B$4786,$A50,Base!$D$2:$D$4786,$B50,Base!$A$2:$A$4786,D$4) | E50: =SUMIFS(Base!$I$2:$I$4786,Base!$B$2:$B$4786,$A50,Base!$D$2:$D$4786,$B50,Base!$A$2:$A$4786,E$4) | F50: =SUMIFS(Base!$I$2:$I$4786,Base!$B$2:$B$4786,$A50,Base!$D$2:$D$4786,$B50,Base!$A$2:$A$4786,F$4) | G50: =SUMIFS(Base!$I$2:$I$4786,Base!$B$2:$B$4786,$A50,Base!$D$2:$D$4786,$B50,Base!$A$2:$A$4786,G$4) | H50: =SUMIFS(Base!$I$2:$I$4786,Base!$B$2:$B$4786,$A50,Base!$D$2:$D$4786,$B50,Base!$A$2:$A$4786,H$4) | I50: =SUMIFS(Base!$I$2:$I$4786,Base!$B$2:$B$4786,$A50,Base!$D$2:$D$4786,$B50,Base!$A$2:$A$4786,I$4) | J50: =SUMIFS(Base!$I$2:$I$4786,Base!$B$2:$B$4786,$A50,Base!$D$2:$D$4786,$B50,Base!$A$2:$A$4786,J$4) | K50: =SUMIFS(Base!$I$2:$I$4786,Base!$B$2:$B$4786,$A50,Base!$D$2:$D$4786,$B50,Base!$A$2:$A$4786,K$4) | L50: =SUM(C50:K50) | M50: =IFERROR(L50/L$123,"")
A51: Uso e consumo | B51: TECHPRINT FACAS INDUSTRIAIS | C51: =SUMIFS(Base!$I$2:$I$4786,Base!$B$2:$B$4786,$A51,Base!$D$2:$D$4786,$B51,Base!$A$2:$A$4786,C$4) | D51: =SUMIFS(Base!$I$2:$I$4786,Base!$B$2:$B$4786,$A51,Base!$D$2:$D$4786,$B51,Base!$A$2:$A$4786,D$4) | E51: =SUMIFS(Base!$I$2:$I$4786,Base!$B$2:$B$4786,$A51,Base!$D$2:$D$4786,$B51,Base!$A$2:$A$4786,E$4) | F51: =SUMIFS(Base!$I$2:$I$4786,Base!$B$2:$B$4786,$A51,Base!$D$2:$D$4786,$B51,Base!$A$2:$A$4786,F$4) | G51: =SUMIFS(Base!$I$2:$I$4786,Base!$B$2:$B$4786,$A51,Base!$D$2:$D$4786,$B51,Base!$A$2:$A$4786,G$4) | H51: =SUMIFS(Base!$I$2:$I$4786,Base!$B$2:$B$4786,$A51,Base!$D$2:$D$4786,$B51,Base!$A$2:$A$4786,H$4) | I51: =SUMIFS(Base!$I$2:$I$4786,Base!$B$2:$B$4786,$A51,Base!$D$2:$D$4786,$B51,Base!$A$2:$A$4786,I$4) | J51: =SUMIFS(Base!$I$2:$I$4786,Base!$B$2:$B$4786,$A51,Base!$D$2:$D$4786,$B51,Base!$A$2:$A$4786,J$4) | K51: =SUMIFS(Base!$I$2:$I$4786,Base!$B$2:$B$4786,$A51,Base!$D$2:$D$4786,$B51,Base!$A$2:$A$4786,K$4) | L51: =SUM(C51:K51) | M51: =IFERROR(L51/L$123,"")
A52: Uso e consumo | B52: MARILENE CARVALHO LUCENA DE BRITO - ME | C52: =SUMIFS(Base!$I$2:$I$4786,Base!$B$2:$B$4786,$A52,Base!$D$2:$D$4786,$B52,Base!$A$2:$A$4786,C$4) | D52: =SUMIFS(Base!$I$2:$I$4786,Base!$B$2:$B$4786,$A52,Base!$D$2:$D$4786,$B52,Base!$A$2:$A$4786,D$4) | E52: =SUMIFS(Base!$I$2:$I$4786,Base!$B$2:$B$4786,$A52,Base!$D$2:$D$4786,$B52,Base!$A$2:$A$4786,E$4) | F52: =SUMIFS(Base!$I$2:$I$4786,Base!$B$2:$B$4786,$A52,Base!$D$2:$D$4786,$B52,Base!$A$2:$A$4786,F$4) | G52: =SUMIFS(Base!$I$2:$I$4786,Base!$B$2:$B$4786,$A52,Base!$D$2:$D$4786,$B52,Base!$A$2:$A$4786,G$4) | H52: =SUMIFS(Base!$I$2:$I$4786,Base!$B$2:$B$4786,$A52,Base!$D$2:$D$4786,$B52,Base!$A$2:$A$4786,H$4) | I52: =SUMIFS(Base!$I$2:$I$4786,Base!$B$2:$B$4786,$A52,Base!$D$2:$D$4786,$B52,Base!$A$2:$A$4786,I$4) | J52: =SUMIFS(Base!$I$2:$I$4786,Base!$B$2:$B$4786,$A52,Base!$D$2:$D$4786,$B52,Base!$A$2:$A$4786,J$4) | K52: =SUMIFS(Base!$I$2:$I$4786,Base!$B$2:$B$4786,$A52,Base!$D$2:$D$4786,$B52,Base!$A$2:$A$4786,K$4) | L52: =SUM(C52:K52) | M52: =IFERROR(L52/L$123,"")
A53: Uso e consumo | B53: EDNA DE ARAUJO PACHECO LTDA | C53: =SUMIFS(Base!$I$2:$I$4786,Base!$B$2:$B$4786,$A53,Base!$D$2:$D$4786,$B53,Base!$A$2:$A$4786,C$4) | D53: =SUMIFS(Base!$I$2:$I$4786,Base!$B$2:$B$4786,$A53,Base!$D$2:$D$4786,$B53,Base!$A$2:$A$4786,D$4) | E53: =SUMIFS(Base!$I$2:$I$4786,Base!$B$2:$B$4786,$A53,Base!$D$2:$D$4786,$B53,Base!$A$2:$A$4786,E$4) | F53: =SUMIFS(Base!$I$2:$I$4786,Base!$B$2:$B$4786,$A53,Base!$D$2:$D$4786,$B53,Base!$A$2:$A$4786,F$4) | G53: =SUMIFS(Base!$I$2:$I$4786,Base!$B$2:$B$4786,$A53,Base!$D$2:$D$4786,$B53,Base!$A$2:$A$4786,G$4) | H53: =SUMIFS(Base!$I$2:$I$4786,Base!$B$2:$B$4786,$A53,Base!$D$2:$D$4786,$B53,Base!$A$2:$A$4786,H$4) | I53: =SUMIFS(Base!$I$2:$I$4786,Base!$B$2:$B$4786,$A53,Base!$D$2:$D$4786,$B53,Base!$A$2:$A$4786,I$4) | J53: =SUMIFS(Base!$I$2:$I$4786,Base!$B$2:$B$4786,$A53,Base!$D$2:$D$4786,$B53,Base!$A$2:$A$4786,J$4) | K53: =SUMIFS(Base!$I$2:$I$4786,Base!$B$2:$B$4786,$A53,Base!$D$2:$D$4786,$B53,Base!$A$2:$A$4786,K$4) | L53: =SUM(C53:K53) | M53: =IFERROR(L53/L$123,"")
A54: Uso e consumo | B54: GDM INDUSTRIA E COMERCIO DE PLASTICOS LTDA. | C54: =SUMIFS(Base!$I$2:$I$4786,Base!$B$2:$B$4786,$A54,Base!$D$2:$D$4786,$B54,Base!$A$2:$A$4786,C$4) | D54: =SUMIFS(Base!$I$2:$I$4786,Base!$B$2:$B$4786,$A54,Base!$D$2:$D$4786,$B54,Base!$A$2:$A$4786,D$4) | E54: =SUMIFS(Base!$I$2:$I$4786,Base!$B$2:$B$4786,$A54,Base!$D$2:$D$4786,$B54,Base!$A$2:$A$4786,E$4) | F54: =SUMIFS(Base!$I$2:$I$4786,Base!$B$2:$B$4786,$A54,Base!$D$2:$D$4786,$B54,Base!$A$2:$A$4786,F$4) | G54: =SUMIFS(Base!$I$2:$I$4786,Base!$B$2:$B$4786,$A54,Base!$D$2:$D$4786,$B54,Base!$A$2:$A$4786,G$4) | H54: =SUMIFS(Base!$I$2:$I$4786,Base!$B$2:$B$4786,$A54,Base!$D$2:$D$4786,$B54,Base!$A$2:$A$4786,H$4) | I54: =SUMIFS(Base!$I$2:$I$4786,Base!$B$2:$B$4786,$A54,Base!$D$2:$D$4786,$B54,Base!$A$2:$A$4786,I$4) | J54: =SUMIFS(Base!$I$2:$I$4786,Base!$B$2:$B$4786,$A54,Base!$D$2:$D$4786,$B54,Base!$A$2:$A$4786,J$4) | K54: =SUMIFS(Base!$I$2:$I$4786,Base!$B$2:$B$4786,$A54,Base!$D$2:$D$4786,$B54,Base!$A$2:$A$4786,K$4) | L54: =SUM(C54:K54) | M54: =IFERROR(L54/L$123,"")
... A122: Uso e consumo | B122: BRICOZE CELL ELETRONICOS LTDA | C122: =SUMIFS(Base!$I$2:$I$4786,Base!$B$2:$B$4786,$A122,Base!$D$2:$D$4786,$B122,Base!$A$2:$A$4786,C$4) | D122: =SUMIFS(Base!$I$2:$I$4786,Base!$B$2:$B$4786,$A122,Base!$D$2:$D$4786,$B122,Base!$A$2:$A$4786,D$4) | E122: =SUMIFS(Base!$I$2:$I$4786,Base!$B$2:$B$4786,$A122,Base!$D$2:$D$4786,$B122,Base!$A$2:$A$4786,E$4) | F122: =SUMIFS(Base!$I$2:$I$4786,Base!$B$2:$B$4786,$A122,Base!$D$2:$D$4786,$B122,Base!$A$2:$A$4786,F$4) | G122: =SUMIFS(Base!$I$2:$I$4786,Base!$B$2:$B$4786,$A122,Base!$D$2:$D$4786,$B122,Base!$A$2:$A$4786,G$4) | H122: =SUMIFS(Base!$I$2:$I$4786,Base!$B$2:$B$4786,$A122,Base!$D$2:$D$4786,$B122,Base!$A$2:$A$4786,H$4) | I122: =SUMIFS(Base!$I$2:$I$4786,Base!$B$2:$B$4786,$A122,Base!$D$2:$D$4786,$B122,Base!$A$2:$A$4786,I$4) | J122: =SUMIFS(Base!$I$2:$I$4786,Base!$B$2:$B$4786,$A122,Base!$D$2:$D$4786,$B122,Base!$A$2:$A$4786,J$4) | K122: =SUMIFS(Base!$I$2:$I$4786,Base!$B$2:$B$4786,$A122,Base!$D$2:$D$4786,$B122,Base!$A$2:$A$4786,K$4) | L122: =SUM(C122:K122) | M122: =IFERROR(L122/L$123,"")
A123: Uso e consumo | B123: TOTAL Uso e consumo | C123: =SUM(C43:C122) | D123: =SUM(D43:D122) | E123: =SUM(E43:E122) | F123: =SUM(F43:F122) | G123: =SUM(G43:G122) | H123: =SUM(H43:H122) | I123: =SUM(I43:I122) | J123: =SUM(J43:J122) | ... L123: =SUM(L43:L122)
A125: Frete de compra | B125: ALIANCA NAVEGACAO E LOGISTICA LTDA | C125: =SUMIFS(Base!$I$2:$I$4786,Base!$B$2:$B$4786,$A125,Base!$D$2:$D$4786,$B125,Base!$A$2:$A$4786,C$4) | D125: =SUMIFS(Base!$I$2:$I$4786,Base!$B$2:$B$4786,$A125,Base!$D$2:$D$4786,$B125,Base!$A$2:$A$4786,D$4) | E125: =SUMIFS(Base!$I$2:$I$4786,Base!$B$2:$B$4786,$A125,Base!$D$2:$D$4786,$B125,Base!$A$2:$A$4786,E$4) | F125: =SUMIFS(Base!$I$2:$I$4786,Base!$B$2:$B$4786,$A125,Base!$D$2:$D$4786,$B125,Base!$A$2:$A$4786,F$4) | G125: =SUMIFS(Base!$I$2:$I$4786,Base!$B$2:$B$4786,$A125,Base!$D$2:$D$4786,$B125,Base!$A$2:$A$4786,G$4) | H125: =SUMIFS(Base!$I$2:$I$4786,Base!$B$2:$B$4786,$A125,Base!$D$2:$D$4786,$B125,Base!$A$2:$A$4786,H$4) | I125: =SUMIFS(Base!$I$2:$I$4786,Base!$B$2:$B$4786,$A125,Base!$D$2:$D$4786,$B125,Base!$A$2:$A$4786,I$4) | J125: =SUMIFS(Base!$I$2:$I$4786,Base!$B$2:$B$4786,$A125,Base!$D$2:$D$4786,$B125,Base!$A$2:$A$4786,J$4) | K125: =SUMIFS(Base!$I$2:$I$4786,Base!$B$2:$B$4786,$A125,Base!$D$2:$D$4786,$B125,Base!$A$2:$A$4786,K$4) | L125: =SUM(C125:K125) | M125: =IFERROR(L125/L$129,"")
A126: Frete de compra | B126: TRANSPORTES DE MAQUINAS PLANETA AZUL LTDA | C126: =SUMIFS(Base!$I$2:$I$4786,Base!$B$2:$B$4786,$A126,Base!$D$2:$D$4786,$B126,Base!$A$2:$A$4786,C$4) | D126: =SUMIFS(Base!$I$2:$I$4786,Base!$B$2:$B$4786,$A126,Base!$D$2:$D$4786,$B126,Base!$A$2:$A$4786,D$4) | E126: =SUMIFS(Base!$I$2:$I$4786,Base!$B$2:$B$4786,$A126,Base!$D$2:$D$4786,$B126,Base!$A$2:$A$4786,E$4) | F126: =SUMIFS(Base!$I$2:$I$4786,Base!$B$2:$B$4786,$A126,Base!$D$2:$D$4786,$B126,Base!$A$2:$A$4786,F$4) | G126: =SUMIFS(Base!$I$2:$I$4786,Base!$B$2:$B$4786,$A126,Base!$D$2:$D$4786,$B126,Base!$A$2:$A$4786,G$4) | H126: =SUMIFS(Base!$I$2:$I$4786,Base!$B$2:$B$4786,$A126,Base!$D$2:$D$4786,$B126,Base!$A$2:$A$4786,H$4) | I126: =SUMIFS(Base!$I$2:$I$4786,Base!$B$2:$B$4786,$A126,Base!$D$2:$D$4786,$B126,Base!$A$2:$A$4786,I$4) | J126: =SUMIFS(Base!$I$2:$I$4786,Base!$B$2:$B$4786,$A126,Base!$D$2:$D$4786,$B126,Base!$A$2:$A$4786,J$4) | K126: =SUMIFS(Base!$I$2:$I$4786,Base!$B$2:$B$4786,$A126,Base!$D$2:$D$4786,$B126,Base!$A$2:$A$4786,K$4) | L126: =SUM(C126:K126) | M126: =IFERROR(L126/L$129,"")
A127: Frete de compra | B127: ALIANCA NAVEGACAO E LOGISTICA LTDA. | C127: =SUMIFS(Base!$I$2:$I$4786,Base!$B$2:$B$4786,$A127,Base!$D$2:$D$4786,$B127,Base!$A$2:$A$4786,C$4) | D127: =SUMIFS(Base!$I$2:$I$4786,Base!$B$2:$B$4786,$A127,Base!$D$2:$D$4786,$B127,Base!$A$2:$A$4786,D$4) | E127: =SUMIFS(Base!$I$2:$I$4786,Base!$B$2:$B$4786,$A127,Base!$D$2:$D$4786,$B127,Base!$A$2:$A$4786,E$4) | F127: =SUMIFS(Base!$I$2:$I$4786,Base!$B$2:$B$4786,$A127,Base!$D$2:$D$4786,$B127,Base!$A$2:$A$4786,F$4) | G127: =SUMIFS(Base!$I$2:$I$4786,Base!$B$2:$B$4786,$A127,Base!$D$2:$D$4786,$B127,Base!$A$2:$A$4786,G$4) | H127: =SUMIFS(Base!$I$2:$I$4786,Base!$B$2:$B$4786,$A127,Base!$D$2:$D$4786,$B127,Base!$A$2:$A$4786,H$4) | I127: =SUMIFS(Base!$I$2:$I$4786,Base!$B$2:$B$4786,$A127,Base!$D$2:$D$4786,$B127,Base!$A$2:$A$4786,I$4) | J127: =SUMIFS(Base!$I$2:$I$4786,Base!$B$2:$B$4786,$A127,Base!$D$2:$D$4786,$B127,Base!$A$2:$A$4786,J$4) | K127: =SUMIFS(Base!$I$2:$I$4786,Base!$B$2:$B$4786,$A127,Base!$D$2:$D$4786,$B127,Base!$A$2:$A$4786,K$4) | L127: =SUM(C127:K127) | M127: =IFERROR(L127/L$129,"")
A128: Frete de compra | B128: GOL LINHAS AEREAS S.A. | C128: =SUMIFS(Base!$I$2:$I$4786,Base!$B$2:$B$4786,$A128,Base!$D$2:$D$4786,$B128,Base!$A$2:$A$4786,C$4) | D128: =SUMIFS(Base!$I$2:$I$4786,Base!$B$2:$B$4786,$A128,Base!$D$2:$D$4786,$B128,Base!$A$2:$A$4786,D$4) | E128: =SUMIFS(Base!$I$2:$I$4786,Base!$B$2:$B$4786,$A128,Base!$D$2:$D$4786,$B128,Base!$A$2:$A$4786,E$4) | F128: =SUMIFS(Base!$I$2:$I$4786,Base!$B$2:$B$4786,$A128,Base!$D$2:$D$4786,$B128,Base!$A$2:$A$4786,F$4) | G128: =SUMIFS(Base!$I$2:$I$4786,Base!$B$2:$B$4786,$A128,Base!$D$2:$D$4786,$B128,Base!$A$2:$A$4786,G$4) | H128: =SUMIFS(Base!$I$2:$I$4786,Base!$B$2:$B$4786,$A128,Base!$D$2:$D$4786,$B128,Base!$A$2:$A$4786,H$4) | I128: =SUMIFS(Base!$I$2:$I$4786,Base!$B$2:$B$4786,$A128,Base!$D$2:$D$4786,$B128,Base!$A$2:$A$4786,I$4) | J128: =SUMIFS(Base!$I$2:$I$4786,Base!$B$2:$B$4786,$A128,Base!$D$2:$D$4786,$B128,Base!$A$2:$A$4786,J$4) | K128: =SUMIFS(Base!$I$2:$I$4786,Base!$B$2:$B$4786,$A128,Base!$D$2:$D$4786,$B128,Base!$A$2:$A$4786,K$4) | L128: =SUM(C128:K128) | M128: =IFERROR(L128/L$129,"")
A129: Frete de compra | B129: TOTAL Frete de compra | C129: =SUM(C125:C128) | D129: =SUM(D125:D128) | E129: =SUM(E125:E128) | F129: =SUM(F125:F128) | G129: =SUM(G125:G128) | H129: =SUM(H125:H128) | I129: =SUM(I125:I128) | J129: =SUM(J125:J128) | ... L129: =SUM(L125:L128)
A131: Frete de venda | B131: DURA MAIS TRANSPORTES LTDA | C131: =SUMIFS(Base!$I$2:$I$4786,Base!$B$2:$B$4786,$A131,Base!$D$2:$D$4786,$B131,Base!$A$2:$A$4786,C$4) | D131: =SUMIFS(Base!$I$2:$I$4786,Base!$B$2:$B$4786,$A131,Base!$D$2:$D$4786,$B131,Base!$A$2:$A$4786,D$4) | E131: =SUMIFS(Base!$I$2:$I$4786,Base!$B$2:$B$4786,$A131,Base!$D$2:$D$4786,$B131,Base!$A$2:$A$4786,E$4) | F131: =SUMIFS(Base!$I$2:$I$4786,Base!$B$2:$B$4786,$A131,Base!$D$2:$D$4786,$B131,Base!$A$2:$A$4786,F$4) | G131: =SUMIFS(Base!$I$2:$I$4786,Base!$B$2:$B$4786,$A131,Base!$D$2:$D$4786,$B131,Base!$A$2:$A$4786,G$4) | H131: =SUMIFS(Base!$I$2:$I$4786,Base!$B$2:$B$4786,$A131,Base!$D$2:$D$4786,$B131,Base!$A$2:$A$4786,H$4) | I131: =SUMIFS(Base!$I$2:$I$4786,Base!$B$2:$B$4786,$A131,Base!$D$2:$D$4786,$B131,Base!$A$2:$A$4786,I$4) | J131: =SUMIFS(Base!$I$2:$I$4786,Base!$B$2:$B$4786,$A131,Base!$D$2:$D$4786,$B131,Base!$A$2:$A$4786,J$4) | K131: =SUMIFS(Base!$I$2:$I$4786,Base!$B$2:$B$4786,$A131,Base!$D$2:$D$4786,$B131,Base!$A$2:$A$4786,K$4) | L131: =SUM(C131:K131) | M131: =IFERROR(L131/L$156,"")
A132: Frete de venda | B132: R&R TRANSPORTE E LOGISTICA | C132: =SUMIFS(Base!$I$2:$I$4786,Base!$B$2:$B$4786,$A132,Base!$D$2:$D$4786,$B132,Base!$A$2:$A$4786,C$4) | D132: =SUMIFS(Base!$I$2:$I$4786,Base!$B$2:$B$4786,$A132,Base!$D$2:$D$4786,$B132,Base!$A$2:$A$4786,D$4) | E132: =SUMIFS(Base!$I$2:$I$4786,Base!$B$2:$B$4786,$A132,Base!$D$2:$D$4786,$B132,Base!$A$2:$A$4786,E$4) | F132: =SUMIFS(Base!$I$2:$I$4786,Base!$B$2:$B$4786,$A132,Base!$D$2:$D$4786,$B132,Base!$A$2:$A$4786,F$4) | G132: =SUMIFS(Base!$I$2:$I$4786,Base!$B$2:$B$4786,$A132,Base!$D$2:$D$4786,$B132,Base!$A$2:$A$4786,G$4) | H132: =SUMIFS(Base!$I$2:$I$4786,Base!$B$2:$B$4786,$A132,Base!$D$2:$D$4786,$B132,Base!$A$2:$A$4786,H$4) | I132: =SUMIFS(Base!$I$2:$I$4786,Base!$B$2:$B$4786,$A132,Base!$D$2:$D$4786,$B132,Base!$A$2:$A$4786,I$4) | J132: =SUMIFS(Base!$I$2:$I$4786,Base!$B$2:$B$4786,$A132,Base!$D$2:$D$4786,$B132,Base!$A$2:$A$4786,J$4) | K132: =SUMIFS(Base!$I$2:$I$4786,Base!$B$2:$B$4786,$A132,Base!$D$2:$D$4786,$B132,Base!$A$2:$A$4786,K$4) | L132: =SUM(C132:K132) | M132: =IFERROR(L132/L$156,"")
A133: Frete de venda | B133: UNIAO MULTIMODAL OTM LTDA | C133: =SUMIFS(Base!$I$2:$I$4786,Base!$B$2:$B$4786,$A133,Base!$D$2:$D$4786,$B133,Base!$A$2:$A$4786,C$4) | D133: =SUMIFS(Base!$I$2:$I$4786,Base!$B$2:$B$4786,$A133,Base!$D$2:$D$4786,$B133,Base!$A$2:$A$4786,D$4) | E133: =SUMIFS(Base!$I$2:$I$4786,Base!$B$2:$B$4786,$A133,Base!$D$2:$D$4786,$B133,Base!$A$2:$A$4786,E$4) | F133: =SUMIFS(Base!$I$2:$I$4786,Base!$B$2:$B$4786,$A133,Base!$D$2:$D$4786,$B133,Base!$A$2:$A$4786,F$4) | G133: =SUMIFS(Base!$I$2:$I$4786,Base!$B$2:$B$4786,$A133,Base!$D$2:$D$4786,$B133,Base!$A$2:$A$4786,G$4) | H133: =SUMIFS(Base!$I$2:$I$4786,Base!$B$2:$B$4786,$A133,Base!$D$2:$D$4786,$B133,Base!$A$2:$A$4786,H$4) | I133: =SUMIFS(Base!$I$2:$I$4786,Base!$B$2:$B$4786,$A133,Base!$D$2:$D$4786,$B133,Base!$A$2:$A$4786,I$4) | J133: =SUMIFS(Base!$I$2:$I$4786,Base!$B$2:$B$4786,$A133,Base!$D$2:$D$4786,$B133,Base!$A$2:$A$4786,J$4) | K133: =SUMIFS(Base!$I$2:$I$4786,Base!$B$2:$B$4786,$A133,Base!$D$2:$D$4786,$B133,Base!$A$2:$A$4786,K$4) | L133: =SUM(C133:K133) | M133: =IFERROR(L133/L$156,"")
A134: Frete de venda | B134: RAPIDO XAPURI TRANSPORTES E LOGISTICA LTDA | C134: =SUMIFS(Base!$I$2:$I$4786,Base!$B$2:$B$4786,$A134,Base!$D$2:$D$4786,$B134,Base!$A$2:$A$4786,C$4) | D134: =SUMIFS(Base!$I$2:$I$4786,Base!$B$2:$B$4786,$A134,Base!$D$2:$D$4786,$B134,Base!$A$2:$A$4786,D$4) | E134: =SUMIFS(Base!$I$2:$I$4786,Base!$B$2:$B$4786,$A134,Base!$D$2:$D$4786,$B134,Base!$A$2:$A$4786,E$4) | F134: =SUMIFS(Base!$I$2:$I$4786,Base!$B$2:$B$4786,$A134,Base!$D$2:$D$4786,$B134,Base!$A$2:$A$4786,F$4) | G134: =SUMIFS(Base!$I$2:$I$4786,Base!$B$2:$B$4786,$A134,Base!$D$2:$D$4786,$B134,Base!$A$2:$A$4786,G$4) | H134: =SUMIFS(Base!$I$2:$I$4786,Base!$B$2:$B$4786,$A134,Base!$D$2:$D$4786,$B134,Base!$A$2:$A$4786,H$4) | I134: =SUMIFS(Base!$I$2:$I$4786,Base!$B$2:$B$4786,$A134,Base!$D$2:$D$4786,$B134,Base!$A$2:$A$4786,I$4) | J134: =SUMIFS(Base!$I$2:$I$4786,Base!$B$2:$B$4786,$A134,Base!$D$2:$D$4786,$B134,Base!$A$2:$A$4786,J$4) | K134: =SUMIFS(Base!$I$2:$I$4786,Base!$B$2:$B$4786,$A134,Base!$D$2:$D$4786,$B134,Base!$A$2:$A$4786,K$4) | L134: =SUM(C134:K134) | M134: =IFERROR(L134/L$156,"")
...

Sheet Base
A1: Mês (emissão) | B1: Destino | C1: Categoria | D1: Fornecedor / Transportadora | E1: CNPJ/CPF | F1: Número | G1: Valor bruto | H1: Crédito | I1: Custo líquido
A2: Antes de 2026 | B2: Frete de compra | C2: Frete de compra | D2: GOL LINHAS AEREAS S.A. | E2: 55.218.977/0001-71 | F2: 000058287 | G2: 100.64 | H2: 4.03 | I2: =G2-H2
A3: Antes de 2026 | B3: Frete de compra | C3: Frete de compra | D3: GOL LINHAS AEREAS S.A. | E3: 912.249.939-34 | F3: 000058286 | G3: 191.66 | H3: 7.67 | I3: =G3-H3
A4: Antes de 2026 | B4: Frete de compra | C4: Frete de compra | D4: GOL LINHAS AEREAS S.A. | E4: 056.964.428-38 | F4: 000059052 | G4: 70.99 | H4: 2.84 | I4: =G4-H4
A5: Antes de 2026 | B5: Frete de compra | C5: Frete de compra | D5: GOL LINHAS AEREAS S.A. | E5: 154.280.657-70 | F5: 000059047 | G5: 111.99 | H5: 4.48 | I5: =G5-H5
A6: Antes de 2026 | B6: Frete de compra | C6: Frete de compra | D6: GOL LINHAS AEREAS S.A. | E6: 179.410.325-20 | F6: 000058716 | G6: 162.04 | H6: 6.48 | I6: =G6-H6
A7: Antes de 2026 | B7: Frete de compra | C7: Frete de compra | D7: GOL LINHAS AEREAS S.A. | E7: 814.563.105-00 | F7: 000059446 | G7: 44.99 | H7: 1.8 | I7: =G7-H7
A8: Antes de 2026 | B8: Frete de compra | C8: Frete de compra | D8: GOL LINHAS AEREAS S.A. | E8: 29.304.139/0001-00 | F8: 000058282 | G8: 173.39 | H8: 6.94 | I8: =G8-H8
A9: Antes de 2026 | B9: Frete de compra | C9: Frete de compra | D9: GOL LINHAS AEREAS S.A. | E9: 29.304.139/0001-00 | F9: 000059051 | G9: 128.54 | H9: 5.14 | I9: =G9-H9
A10: Antes de 2026 | B10: Frete de compra | C10: Frete de compra | D10: GOL LINHAS AEREAS S.A. | E10: 751.618.772-00 | F10: 000059055 | G10: 132.4 | H10: 5.3 | I10: =G10-H10
A11: Antes de 2026 | B11: Frete de compra | C11: Frete de compra | D11: GOL LINHAS AEREAS S.A. | E11: 668.690.999-87 | F11: 000058724 | G11: 207.45 | H11: 8.3 | I11: =G11-H11
A12: Antes de 2026 | B12: Frete de compra | C12: Frete de compra | D12: GOL LINHAS AEREAS S.A. | E12: 001.868.381-90 | F12: 000059048 | G12: 136.99 | H12: 5.48 | I12: =G12-H12
A13: Antes de 2026 | B13: Frete de compra | C13: Frete de compra | D13: GOL LINHAS AEREAS S.A. | E13: 617.736.545-00 | F13: 000058713 | G13: 162.04 | H13: 6.48 | I13: =G13-H13
... A1998: Antes de 2026 | B1998: Insumos e papel | C1998: 2.01.99 Compra de Caixas | D1998: NOVA CONPEL COMPANHIA NORDESTINA DE PAPEL LTDA | E1998: 55.330.530/0001-90 | F1998: 000011554 | G1998: 3604.74 | H1998: 1329.05 | I1998: =G1998-H1998
A1999: 46023 | B1999: Frete de venda | C1999: Frete de venda (para clientes) | D1999: ADEMIR DA SILVA LTDA | E1999: 18.965.796/0001-82 | F1999: 000000318 | G1999: 300 | H1999: 0 | I1999: =G1999-H1999
A2000: 46023 | B2000: Frete de venda | C2000: Frete de venda (para clientes) | D2000: CRUZ DE MALTA TRANSPORTES LTDA | E2000: 28.628.646/0001-37 | F2000: 000083544 | G2000: 800 | H2000: 0 | I2000: =G2000-H2000
A2001: 46023 | B2001: Frete de venda | C2001: Frete de venda (para clientes) | D2001: ADEMIR DA SILVA LTDA | E2001: 24.626.452/0001-41 | F2001: 000000316 | G2001: 300 | H2001: 0 | I2001: =G2001-H2001
A2002: 46023 | B2002: Frete de venda | C2002: Frete de venda (para clientes) | D2002: ADEMIR DA SILVA LTDA | E2002: 45.762.979/0001-73 | F2002: 000000315 | G2002: 600 | H2002: 0 | I2002: =G2002-H2002
A2003: 46023 | B2003: Frete de venda | C2003: Frete de venda (para clientes) | D2003: ADEMIR DA SILVA LTDA | E2003: 07.428.119/0001-09 | F2003: 000000317 | G2003: 300 | H2003: 0 | I2003: =G2003-H2003
A2004: 46023 | B2004: Frete de venda | C2004: Frete de venda (para clientes) | D2004: CRUZ DE MALTA TRANSPORTES LTDA | E2004: 57.632.874/0001-89 | F2004: 000083545 | G2004: 500 | H2004: 0 | I2004: =G2004-H2004
A2005: 46023 | B2005: Frete de compra | C2005: Frete de compra | D2005: GOL LINHAS AEREAS S.A. | E2005: 011.660.716-50 | F2005: 000075476 | G2005: 1163.65 | H2005: 46.55 | I2005: =G2005-H2005
A2006: 46023 | B2006: Frete de venda | C2006: Frete de venda (para clientes) | D2006: CAZAN TRANSPORTES LTDA | E2006: 39.285.002/0001-00 | F2006: 000213565 | G2006: 8287 | H2006: 0 | I2006: =G2006-H2006
A2007: 46023 | B2007: Frete de compra | C2007: Frete de compra | D2007: ALIANCA NAVEGACAO E LOGISTICA LTDA | E2007: 11.308.600/0008-04 | F2007: 000188201 | G2007: 17208.34 | H2007: 1204.58 | I2007: =G2007-H2007
A2008: 46023 | B2008: Frete de compra | C2008: Frete de compra | D2008: ALIANCA NAVEGACAO E LOGISTICA LTDA | E2008: 11.308.600/0008-04 | F2008: 000188202 | G2008: 17211.95 | H2008: 1204.84 | I2008: =G2008-H2008
A2009: 46023 | B2009: Frete de compra | C2009: Frete de compra | D2009: ALIANCA NAVEGACAO E LOGISTICA LTDA | E2009: 11.308.600/0008-04 | F2009: 000188203 | G2009: 17204.9 | H2009: 1204.34 | I2009: =G2009-H2009
A2010: 46023 | B2010: Frete de compra | C2010: Frete de compra | D2010: ALIANCA NAVEGACAO E LOGISTICA LTDA | E2010: 11.308.600/0008-04 | F2010: 000188204 | G2010: 17205.39 | H2010: 1204.38 | I2010: =G2010-H2010
... A4782: 46266 | B4782: Uso e consumo | C4782: 2.04.91 Compra de Material de Limpeza | D4782: Limptech Paper Comercio Ltda | E4782: 58.715.917/0001-52 | F4782: 000001541 | G4782: 549 | H4782: 0 | I4782: =G4782-H4782
A4783: 46235 | B4783: Frete de venda | C4783: Frete de venda (para clientes) | D4783: 26.221.654 ROGERIO DA CUNHA FERREIRA | F4783: 000000056 | G4783: 18300 | H4783: 0 | I4783: =G4783-H4783
A4784: 46235 | B4784: Frete de venda | C4784: Frete de venda (para clientes) | D4784: MARCOS RIBEIRO DE MELO | F4784: 000000012 | G4784: 13800 | H4784: 0 | I4784: =G4784-H4784
A4785: 46235 | B4785: Frete de venda | C4785: Frete de venda (para clientes) | D4785: PEDRO HENRIQUE MODESTO DE QUEIROZ SILVEIRA | F4785: 000000070 | G4785: 650 | H4785: 0 | I4785: =G4785-H4785
A4786: 46235 | B4786: Frete de venda | C4786: Frete de venda (para clientes) | D4786: ADIL CARLOS DA SILVA | F4786: FATURA | G4786: 34500 | H4786: 0 | I4786: =G4786-H4786
